[2021-12-29 12:48:41,567] {taskinstance.py:1035} INFO - Dependencies all met for <TaskInstance: scraping_daft_cavan.remove_file scheduled__2021-12-28T09:10:00+00:00 [queued]>
[2021-12-29 12:48:44,648] {taskinstance.py:1035} INFO - Dependencies all met for <TaskInstance: scraping_daft_cavan.remove_file scheduled__2021-12-28T09:10:00+00:00 [queued]>
[2021-12-29 12:48:44,855] {taskinstance.py:1241} INFO - 
--------------------------------------------------------------------------------
[2021-12-29 12:48:44,926] {taskinstance.py:1242} INFO - Starting attempt 4 of 4
[2021-12-29 12:48:45,010] {taskinstance.py:1243} INFO - 
--------------------------------------------------------------------------------
[2021-12-29 12:48:48,753] {taskinstance.py:1262} INFO - Executing <Task(SparkSubmitOperator): remove_file> on 2021-12-28 09:10:00+00:00
[2021-12-29 12:48:51,063] {standard_task_runner.py:76} INFO - Running: ['***', 'tasks', 'run', 'scraping_daft_cavan', 'remove_file', 'scheduled__2021-12-28T09:10:00+00:00', '--job-id', '5384', '--raw', '--subdir', 'DAGS_FOLDER/scraping_daft_cavan.py', '--cfg-path', '/tmp/tmpxd9lbrip', '--error-file', '/tmp/tmpp13_wjwd']
[2021-12-29 12:48:51,261] {standard_task_runner.py:77} INFO - Job 5384: Subtask remove_file
[2021-12-29 12:48:49,562] {standard_task_runner.py:52} INFO - Started process 33734 to run task
[2021-12-29 12:48:56,108] {logging_mixin.py:109} INFO - Running <TaskInstance: scraping_daft_cavan.remove_file scheduled__2021-12-28T09:10:00+00:00 [running]> on host 6bdda4c19a85
[2021-12-29 12:49:08,281] {taskinstance.py:1429} INFO - Exporting the following env vars:
AIRFLOW_CTX_DAG_EMAIL=clement.liscoet@gmail.com
AIRFLOW_CTX_DAG_OWNER=clemoni
AIRFLOW_CTX_DAG_ID=scraping_daft_cavan
AIRFLOW_CTX_TASK_ID=remove_file
AIRFLOW_CTX_EXECUTION_DATE=2021-12-28T09:10:00+00:00
AIRFLOW_CTX_DAG_RUN_ID=scheduled__2021-12-28T09:10:00+00:00
[2021-12-29 12:49:09,365] {base.py:79} INFO - Using connection to: id: spark_default. Host: spark://spark:7077, Port: None, Schema: , Login: ***, Password: ***, extra: {}
[2021-12-29 12:49:09,595] {spark_submit.py:360} INFO - Spark-Submit cmd: spark-submit --master spark://spark:7077 --conf spark.master=spark://spark:7077 --name remove file --verbose /opt/***/jobs/remove_file.py cavan
[2021-12-29 13:01:30,744] {spark_submit.py:514} INFO - Using properties file: null
[2021-12-29 13:29:21,946] {base_job.py:230} ERROR - LocalTaskJob heartbeat got an exception
Traceback (most recent call last):
  File "/home/airflow/.local/lib/python3.6/site-packages/sqlalchemy/engine/base.py", line 2336, in _wrap_pool_connect
    return fn()
  File "/home/airflow/.local/lib/python3.6/site-packages/sqlalchemy/pool/base.py", line 364, in connect
    return _ConnectionFairy._checkout(self)
  File "/home/airflow/.local/lib/python3.6/site-packages/sqlalchemy/pool/base.py", line 778, in _checkout
    fairy = _ConnectionRecord.checkout(pool)
  File "/home/airflow/.local/lib/python3.6/site-packages/sqlalchemy/pool/base.py", line 495, in checkout
    rec = pool._do_get()
  File "/home/airflow/.local/lib/python3.6/site-packages/sqlalchemy/pool/impl.py", line 241, in _do_get
    return self._create_connection()
  File "/home/airflow/.local/lib/python3.6/site-packages/sqlalchemy/pool/base.py", line 309, in _create_connection
    return _ConnectionRecord(self)
  File "/home/airflow/.local/lib/python3.6/site-packages/sqlalchemy/pool/base.py", line 440, in __init__
    self.__connect(first_connect_check=True)
  File "/home/airflow/.local/lib/python3.6/site-packages/sqlalchemy/pool/base.py", line 661, in __connect
    pool.logger.debug("Error on connect(): %s", e)
  File "/home/airflow/.local/lib/python3.6/site-packages/sqlalchemy/util/langhelpers.py", line 70, in __exit__
    with_traceback=exc_tb,
  File "/home/airflow/.local/lib/python3.6/site-packages/sqlalchemy/util/compat.py", line 182, in raise_
    raise exception
  File "/home/airflow/.local/lib/python3.6/site-packages/sqlalchemy/pool/base.py", line 656, in __connect
    connection = pool._invoke_creator(self)
  File "/home/airflow/.local/lib/python3.6/site-packages/sqlalchemy/engine/strategies.py", line 114, in connect
    return dialect.connect(*cargs, **cparams)
  File "/home/airflow/.local/lib/python3.6/site-packages/sqlalchemy/engine/default.py", line 508, in connect
    return self.dbapi.connect(*cargs, **cparams)
  File "/home/airflow/.local/lib/python3.6/site-packages/psycopg2/__init__.py", line 122, in connect
    conn = _connect(dsn, connection_factory=connection_factory, **kwasync)
psycopg2.OperationalError: server closed the connection unexpectedly
	This probably means the server terminated abnormally
	before or while processing the request.


The above exception was the direct cause of the following exception:

Traceback (most recent call last):
  File "/home/airflow/.local/lib/python3.6/site-packages/airflow/jobs/base_job.py", line 226, in heartbeat
    self.heartbeat_callback(session=session)
  File "/home/airflow/.local/lib/python3.6/site-packages/airflow/utils/session.py", line 67, in wrapper
    return func(*args, **kwargs)
  File "/home/airflow/.local/lib/python3.6/site-packages/airflow/jobs/local_task_job.py", line 184, in heartbeat_callback
    self.task_instance.refresh_from_db()
  File "/home/airflow/.local/lib/python3.6/site-packages/airflow/utils/session.py", line 70, in wrapper
    return func(*args, session=session, **kwargs)
  File "/home/airflow/.local/lib/python3.6/site-packages/airflow/models/taskinstance.py", line 731, in refresh_from_db
    ti = qry.first()
  File "/home/airflow/.local/lib/python3.6/site-packages/sqlalchemy/orm/query.py", line 3429, in first
    ret = list(self[0:1])
  File "/home/airflow/.local/lib/python3.6/site-packages/sqlalchemy/orm/query.py", line 3203, in __getitem__
    return list(res)
  File "/home/airflow/.local/lib/python3.6/site-packages/sqlalchemy/orm/query.py", line 3535, in __iter__
    return self._execute_and_instances(context)
  File "/home/airflow/.local/lib/python3.6/site-packages/sqlalchemy/orm/query.py", line 3557, in _execute_and_instances
    querycontext, self._connection_from_session, close_with_result=True
  File "/home/airflow/.local/lib/python3.6/site-packages/sqlalchemy/orm/query.py", line 3572, in _get_bind_args
    mapper=self._bind_mapper(), clause=querycontext.statement, **kw
  File "/home/airflow/.local/lib/python3.6/site-packages/sqlalchemy/orm/query.py", line 3550, in _connection_from_session
    conn = self.session.connection(**kw)
  File "/home/airflow/.local/lib/python3.6/site-packages/sqlalchemy/orm/session.py", line 1145, in connection
    execution_options=execution_options,
  File "/home/airflow/.local/lib/python3.6/site-packages/sqlalchemy/orm/session.py", line 1151, in _connection_for_bind
    engine, execution_options
  File "/home/airflow/.local/lib/python3.6/site-packages/sqlalchemy/orm/session.py", line 433, in _connection_for_bind
    conn = bind._contextual_connect()
  File "/home/airflow/.local/lib/python3.6/site-packages/sqlalchemy/engine/base.py", line 2302, in _contextual_connect
    self._wrap_pool_connect(self.pool.connect, None),
  File "/home/airflow/.local/lib/python3.6/site-packages/sqlalchemy/engine/base.py", line 2340, in _wrap_pool_connect
    e, dialect, self
  File "/home/airflow/.local/lib/python3.6/site-packages/sqlalchemy/engine/base.py", line 1584, in _handle_dbapi_exception_noconnection
    sqlalchemy_exception, with_traceback=exc_info[2], from_=e
  File "/home/airflow/.local/lib/python3.6/site-packages/sqlalchemy/util/compat.py", line 182, in raise_
    raise exception
  File "/home/airflow/.local/lib/python3.6/site-packages/sqlalchemy/engine/base.py", line 2336, in _wrap_pool_connect
    return fn()
  File "/home/airflow/.local/lib/python3.6/site-packages/sqlalchemy/pool/base.py", line 364, in connect
    return _ConnectionFairy._checkout(self)
  File "/home/airflow/.local/lib/python3.6/site-packages/sqlalchemy/pool/base.py", line 778, in _checkout
    fairy = _ConnectionRecord.checkout(pool)
  File "/home/airflow/.local/lib/python3.6/site-packages/sqlalchemy/pool/base.py", line 495, in checkout
    rec = pool._do_get()
  File "/home/airflow/.local/lib/python3.6/site-packages/sqlalchemy/pool/impl.py", line 241, in _do_get
    return self._create_connection()
  File "/home/airflow/.local/lib/python3.6/site-packages/sqlalchemy/pool/base.py", line 309, in _create_connection
    return _ConnectionRecord(self)
  File "/home/airflow/.local/lib/python3.6/site-packages/sqlalchemy/pool/base.py", line 440, in __init__
    self.__connect(first_connect_check=True)
  File "/home/airflow/.local/lib/python3.6/site-packages/sqlalchemy/pool/base.py", line 661, in __connect
    pool.logger.debug("Error on connect(): %s", e)
  File "/home/airflow/.local/lib/python3.6/site-packages/sqlalchemy/util/langhelpers.py", line 70, in __exit__
    with_traceback=exc_tb,
  File "/home/airflow/.local/lib/python3.6/site-packages/sqlalchemy/util/compat.py", line 182, in raise_
    raise exception
  File "/home/airflow/.local/lib/python3.6/site-packages/sqlalchemy/pool/base.py", line 656, in __connect
    connection = pool._invoke_creator(self)
  File "/home/airflow/.local/lib/python3.6/site-packages/sqlalchemy/engine/strategies.py", line 114, in connect
    return dialect.connect(*cargs, **cparams)
  File "/home/airflow/.local/lib/python3.6/site-packages/sqlalchemy/engine/default.py", line 508, in connect
    return self.dbapi.connect(*cargs, **cparams)
  File "/home/airflow/.local/lib/python3.6/site-packages/psycopg2/__init__.py", line 122, in connect
    conn = _connect(dsn, connection_factory=connection_factory, **kwasync)
sqlalchemy.exc.OperationalError: (psycopg2.OperationalError) server closed the connection unexpectedly
	This probably means the server terminated abnormally
	before or while processing the request.

(Background on this error at: http://sqlalche.me/e/13/e3q8)
[2021-12-29 13:38:04,706] {local_task_job.py:142} ERROR - Heartbeat time limit exceeded!
[2021-12-29 13:44:03,986] {process_utils.py:100} INFO - Sending Signals.SIGTERM to GPID 33734
[2021-12-29 13:45:38,043] {taskinstance.py:1411} ERROR - Received SIGTERM. Terminating subprocesses.
[2021-12-29 13:46:10,279] {spark_submit.py:644} INFO - Sending kill signal to spark-submit
[2021-12-29 13:46:48,439] {process_utils.py:113} WARNING - process psutil.Process(pid=33775, name='java', status='zombie', started='12:49:10') did not respond to SIGTERM. Trying SIGKILL
[2021-12-29 13:53:51,833] {process_utils.py:113} WARNING - process psutil.Process(pid=33734, name='airflow task ru', status='running', started='12:48:48') did not respond to SIGTERM. Trying SIGKILL
[2021-12-29 13:54:19,573] {process_utils.py:66} INFO - Process psutil.Process(pid=33775, name='java', status='terminated', started='12:49:10') (33775) terminated with exit code None
[2021-12-29 13:54:47,733] {process_utils.py:66} INFO - Process psutil.Process(pid=33734, name='airflow task ru', status='terminated', exitcode=<Negsignal.SIGKILL: -9>, started='12:48:48') (33734) terminated with exit code Negsignal.SIGKILL
[2021-12-29 13:54:48,176] {standard_task_runner.py:135} ERROR - Job 5384 was killed before it finished (likely due to running out of memory)
