[2021-12-28 13:49:44,860] {taskinstance.py:1035} INFO - Dependencies all met for <TaskInstance: scraping_daft_meath.persist_data scheduled__2021-12-27T10:25:00+00:00 [queued]>
[2021-12-28 13:49:44,889] {taskinstance.py:1035} INFO - Dependencies all met for <TaskInstance: scraping_daft_meath.persist_data scheduled__2021-12-27T10:25:00+00:00 [queued]>
[2021-12-28 13:49:44,890] {taskinstance.py:1241} INFO - 
--------------------------------------------------------------------------------
[2021-12-28 13:49:44,892] {taskinstance.py:1242} INFO - Starting attempt 3 of 4
[2021-12-28 13:49:44,893] {taskinstance.py:1243} INFO - 
--------------------------------------------------------------------------------
[2021-12-28 13:49:44,929] {taskinstance.py:1262} INFO - Executing <Task(SparkSubmitOperator): persist_data> on 2021-12-27 10:25:00+00:00
[2021-12-28 13:49:44,948] {standard_task_runner.py:76} INFO - Running: ['***', 'tasks', 'run', 'scraping_daft_meath', 'persist_data', 'scheduled__2021-12-27T10:25:00+00:00', '--job-id', '5125', '--raw', '--subdir', 'DAGS_FOLDER/scraping_daft_meath.py', '--cfg-path', '/tmp/tmpajmx31x3', '--error-file', '/tmp/tmphq1ng2yj']
[2021-12-28 13:49:44,951] {standard_task_runner.py:77} INFO - Job 5125: Subtask persist_data
[2021-12-28 13:49:44,944] {standard_task_runner.py:52} INFO - Started process 57445 to run task
[2021-12-28 13:49:45,142] {logging_mixin.py:109} INFO - Running <TaskInstance: scraping_daft_meath.persist_data scheduled__2021-12-27T10:25:00+00:00 [running]> on host 0c125a5bba95
[2021-12-28 13:49:45,452] {taskinstance.py:1429} INFO - Exporting the following env vars:
AIRFLOW_CTX_DAG_EMAIL=clement.liscoet@gmail.com
AIRFLOW_CTX_DAG_OWNER=clemoni
AIRFLOW_CTX_DAG_ID=scraping_daft_meath
AIRFLOW_CTX_TASK_ID=persist_data
AIRFLOW_CTX_EXECUTION_DATE=2021-12-27T10:25:00+00:00
AIRFLOW_CTX_DAG_RUN_ID=scheduled__2021-12-27T10:25:00+00:00
[2021-12-28 13:49:45,509] {base.py:79} INFO - Using connection to: id: spark_default. Host: spark://spark:7077, Port: None, Schema: , Login: ***, Password: ***, extra: {}
[2021-12-28 13:49:45,514] {spark_submit.py:360} INFO - Spark-Submit cmd: spark-submit --master spark://spark:7077 --conf spark.master=spark://spark:7077 --name persist data --verbose /opt/***/jobs/persist_db.py meath
[2021-12-28 13:49:48,859] {spark_submit.py:514} INFO - Using properties file: null
[2021-12-28 13:49:49,060] {spark_submit.py:514} INFO - WARNING: An illegal reflective access operation has occurred
[2021-12-28 13:49:49,062] {spark_submit.py:514} INFO - WARNING: Illegal reflective access by org.apache.spark.unsafe.Platform (file:/home/***/.local/lib/python3.6/site-packages/pyspark/jars/spark-unsafe_2.12-3.2.0.jar) to constructor java.nio.DirectByteBuffer(long,int)
[2021-12-28 13:49:49,063] {spark_submit.py:514} INFO - WARNING: Please consider reporting this to the maintainers of org.apache.spark.unsafe.Platform
[2021-12-28 13:49:49,064] {spark_submit.py:514} INFO - WARNING: Use --illegal-access=warn to enable warnings of further illegal reflective access operations
[2021-12-28 13:49:49,064] {spark_submit.py:514} INFO - WARNING: All illegal access operations will be denied in a future release
[2021-12-28 13:49:49,160] {spark_submit.py:514} INFO - Parsed arguments:
[2021-12-28 13:49:49,161] {spark_submit.py:514} INFO - master                  spark://spark:7077
[2021-12-28 13:49:49,162] {spark_submit.py:514} INFO - deployMode              null
[2021-12-28 13:49:49,163] {spark_submit.py:514} INFO - executorMemory          null
[2021-12-28 13:49:49,164] {spark_submit.py:514} INFO - executorCores           null
[2021-12-28 13:49:49,165] {spark_submit.py:514} INFO - totalExecutorCores      null
[2021-12-28 13:49:49,166] {spark_submit.py:514} INFO - propertiesFile          null
[2021-12-28 13:49:49,168] {spark_submit.py:514} INFO - driverMemory            null
[2021-12-28 13:49:49,169] {spark_submit.py:514} INFO - driverCores             null
[2021-12-28 13:49:49,170] {spark_submit.py:514} INFO - driverExtraClassPath    null
[2021-12-28 13:49:49,171] {spark_submit.py:514} INFO - driverExtraLibraryPath  null
[2021-12-28 13:49:49,173] {spark_submit.py:514} INFO - driverExtraJavaOptions  null
[2021-12-28 13:49:49,174] {spark_submit.py:514} INFO - supervise               false
[2021-12-28 13:49:49,175] {spark_submit.py:514} INFO - queue                   null
[2021-12-28 13:49:49,175] {spark_submit.py:514} INFO - numExecutors            null
[2021-12-28 13:49:49,176] {spark_submit.py:514} INFO - files                   null
[2021-12-28 13:49:49,177] {spark_submit.py:514} INFO - pyFiles                 null
[2021-12-28 13:49:49,178] {spark_submit.py:514} INFO - archives                null
[2021-12-28 13:49:49,179] {spark_submit.py:514} INFO - mainClass               null
[2021-12-28 13:49:49,180] {spark_submit.py:514} INFO - primaryResource         file:/opt/***/jobs/persist_db.py
[2021-12-28 13:49:49,181] {spark_submit.py:514} INFO - name                    persist data
[2021-12-28 13:49:49,181] {spark_submit.py:514} INFO - childArgs               [meath]
[2021-12-28 13:49:49,182] {spark_submit.py:514} INFO - jars                    null
[2021-12-28 13:49:49,183] {spark_submit.py:514} INFO - packages                null
[2021-12-28 13:49:49,184] {spark_submit.py:514} INFO - packagesExclusions      null
[2021-12-28 13:49:49,185] {spark_submit.py:514} INFO - repositories            null
[2021-12-28 13:49:49,186] {spark_submit.py:514} INFO - verbose                 true
[2021-12-28 13:49:49,187] {spark_submit.py:514} INFO - 
[2021-12-28 13:49:49,187] {spark_submit.py:514} INFO - Spark properties used, including those specified through
[2021-12-28 13:49:49,188] {spark_submit.py:514} INFO - --conf and those from the properties file null:
[2021-12-28 13:49:49,189] {spark_submit.py:514} INFO - (spark.master,spark://spark:7077)
[2021-12-28 13:49:49,190] {spark_submit.py:514} INFO - 
[2021-12-28 13:49:49,191] {spark_submit.py:514} INFO - 
[2021-12-28 13:49:50,242] {spark_submit.py:514} INFO - Main class:
[2021-12-28 13:49:50,243] {spark_submit.py:514} INFO - org.apache.spark.deploy.PythonRunner
[2021-12-28 13:49:50,245] {spark_submit.py:514} INFO - Arguments:
[2021-12-28 13:49:50,246] {spark_submit.py:514} INFO - file:/opt/***/jobs/persist_db.py
[2021-12-28 13:49:50,247] {spark_submit.py:514} INFO - null
[2021-12-28 13:49:50,248] {spark_submit.py:514} INFO - meath
[2021-12-28 13:49:50,249] {spark_submit.py:514} INFO - --verbose
[2021-12-28 13:49:50,250] {spark_submit.py:514} INFO - Spark config:
[2021-12-28 13:49:50,251] {spark_submit.py:514} INFO - (spark.master,spark://spark:7077)
[2021-12-28 13:49:50,252] {spark_submit.py:514} INFO - (spark.app.name,persist data)
[2021-12-28 13:49:50,253] {spark_submit.py:514} INFO - (spark.submit.pyFiles,)
[2021-12-28 13:49:50,254] {spark_submit.py:514} INFO - (spark.submit.deployMode,client)
[2021-12-28 13:49:50,255] {spark_submit.py:514} INFO - Classpath elements:
[2021-12-28 13:49:50,256] {spark_submit.py:514} INFO - 
[2021-12-28 13:49:50,256] {spark_submit.py:514} INFO - 
[2021-12-28 13:49:50,257] {spark_submit.py:514} INFO - 
[2021-12-28 13:49:53,749] {spark_submit.py:514} INFO - Using Spark's default log4j profile: org/apache/spark/log4j-defaults.properties
[2021-12-28 13:49:53,773] {spark_submit.py:514} INFO - 21/12/28 13:49:53 INFO SparkContext: Running Spark version 3.2.0
[2021-12-28 13:49:54,152] {spark_submit.py:514} INFO - 21/12/28 13:49:54 WARN NativeCodeLoader: Unable to load native-hadoop library for your platform... using builtin-java classes where applicable
[2021-12-28 13:49:54,755] {spark_submit.py:514} INFO - 21/12/28 13:49:54 INFO ResourceUtils: ==============================================================
[2021-12-28 13:49:54,757] {spark_submit.py:514} INFO - 21/12/28 13:49:54 INFO ResourceUtils: No custom resources configured for spark.driver.
[2021-12-28 13:49:54,758] {spark_submit.py:514} INFO - 21/12/28 13:49:54 INFO ResourceUtils: ==============================================================
[2021-12-28 13:49:54,759] {spark_submit.py:514} INFO - 21/12/28 13:49:54 INFO SparkContext: Submitted application: Persist DB
[2021-12-28 13:49:54,837] {spark_submit.py:514} INFO - 21/12/28 13:49:54 INFO ResourceProfile: Default ResourceProfile created, executor resources: Map(cores -> name: cores, amount: 1, script: , vendor: , memory -> name: memory, amount: 1024, script: , vendor: , offHeap -> name: offHeap, amount: 0, script: , vendor: ), task resources: Map(cpus -> name: cpus, amount: 1.0)
[2021-12-28 13:49:54,890] {spark_submit.py:514} INFO - 21/12/28 13:49:54 INFO ResourceProfile: Limiting resource is cpu
[2021-12-28 13:49:54,909] {spark_submit.py:514} INFO - 21/12/28 13:49:54 INFO ResourceProfileManager: Added ResourceProfile id: 0
[2021-12-28 13:49:55,353] {spark_submit.py:514} INFO - 21/12/28 13:49:55 INFO SecurityManager: Changing view acls to: ***
[2021-12-28 13:49:55,356] {spark_submit.py:514} INFO - 21/12/28 13:49:55 INFO SecurityManager: Changing modify acls to: ***
[2021-12-28 13:49:55,358] {spark_submit.py:514} INFO - 21/12/28 13:49:55 INFO SecurityManager: Changing view acls groups to:
[2021-12-28 13:49:55,362] {spark_submit.py:514} INFO - 21/12/28 13:49:55 INFO SecurityManager: Changing modify acls groups to:
[2021-12-28 13:49:55,364] {spark_submit.py:514} INFO - 21/12/28 13:49:55 INFO SecurityManager: SecurityManager: authentication disabled; ui acls disabled; users  with view permissions: Set(***); groups with view permissions: Set(); users  with modify permissions: Set(***); groups with modify permissions: Set()
[2021-12-28 13:49:56,961] {spark_submit.py:514} INFO - 21/12/28 13:49:56 INFO Utils: Successfully started service 'sparkDriver' on port 34199.
[2021-12-28 13:49:57,171] {spark_submit.py:514} INFO - 21/12/28 13:49:57 INFO SparkEnv: Registering MapOutputTracker
[2021-12-28 13:49:57,497] {spark_submit.py:514} INFO - 21/12/28 13:49:57 INFO SparkEnv: Registering BlockManagerMaster
[2021-12-28 13:49:57,712] {spark_submit.py:514} INFO - 21/12/28 13:49:57 INFO BlockManagerMasterEndpoint: Using org.apache.spark.storage.DefaultTopologyMapper for getting topology information
[2021-12-28 13:49:57,716] {spark_submit.py:514} INFO - 21/12/28 13:49:57 INFO BlockManagerMasterEndpoint: BlockManagerMasterEndpoint up
[2021-12-28 13:49:57,749] {spark_submit.py:514} INFO - 21/12/28 13:49:57 INFO SparkEnv: Registering BlockManagerMasterHeartbeat
[2021-12-28 13:49:57,932] {spark_submit.py:514} INFO - 21/12/28 13:49:57 INFO DiskBlockManager: Created local directory at /tmp/blockmgr-7c2bec3e-4897-42ff-ab81-2dea3b1500eb
[2021-12-28 13:49:58,143] {spark_submit.py:514} INFO - 21/12/28 13:49:58 INFO MemoryStore: MemoryStore started with capacity 434.4 MiB
[2021-12-28 13:49:58,247] {spark_submit.py:514} INFO - 21/12/28 13:49:58 INFO SparkEnv: Registering OutputCommitCoordinator
[2021-12-28 13:49:59,311] {spark_submit.py:514} INFO - 21/12/28 13:49:59 WARN Utils: Service 'SparkUI' could not bind on port 4040. Attempting port 4041.
[2021-12-28 13:49:59,314] {spark_submit.py:514} INFO - 21/12/28 13:49:59 WARN Utils: Service 'SparkUI' could not bind on port 4041. Attempting port 4042.
[2021-12-28 13:49:59,316] {spark_submit.py:514} INFO - 21/12/28 13:49:59 WARN Utils: Service 'SparkUI' could not bind on port 4042. Attempting port 4043.
[2021-12-28 13:49:59,344] {spark_submit.py:514} INFO - 21/12/28 13:49:59 INFO Utils: Successfully started service 'SparkUI' on port 4043.
[2021-12-28 13:49:59,627] {spark_submit.py:514} INFO - 21/12/28 13:49:59 INFO SparkUI: Bound SparkUI to 0.0.0.0, and started at http://0c125a5bba95:4043
[2021-12-28 13:50:00,234] {spark_submit.py:514} INFO - 21/12/28 13:50:00 INFO StandaloneAppClient$ClientEndpoint: Connecting to master spark://spark:7077...
[2021-12-28 13:50:00,393] {spark_submit.py:514} INFO - 21/12/28 13:50:00 WARN StandaloneAppClient$ClientEndpoint: Failed to connect to master spark:7077
[2021-12-28 13:50:00,394] {spark_submit.py:514} INFO - org.apache.spark.SparkException: Exception thrown in awaitResult:
[2021-12-28 13:50:00,396] {spark_submit.py:514} INFO - at org.apache.spark.util.ThreadUtils$.awaitResult(ThreadUtils.scala:301)
[2021-12-28 13:50:00,397] {spark_submit.py:514} INFO - at org.apache.spark.rpc.RpcTimeout.awaitResult(RpcTimeout.scala:75)
[2021-12-28 13:50:00,399] {spark_submit.py:514} INFO - at org.apache.spark.rpc.RpcEnv.setupEndpointRefByURI(RpcEnv.scala:101)
[2021-12-28 13:50:00,400] {spark_submit.py:514} INFO - at org.apache.spark.rpc.RpcEnv.setupEndpointRef(RpcEnv.scala:109)
[2021-12-28 13:50:00,401] {spark_submit.py:514} INFO - at org.apache.spark.deploy.client.StandaloneAppClient$ClientEndpoint$$anon$1.run(StandaloneAppClient.scala:107)
[2021-12-28 13:50:00,403] {spark_submit.py:514} INFO - at java.base/java.util.concurrent.Executors$RunnableAdapter.call(Executors.java:515)
[2021-12-28 13:50:00,404] {spark_submit.py:514} INFO - at java.base/java.util.concurrent.FutureTask.run(FutureTask.java:264)
[2021-12-28 13:50:00,405] {spark_submit.py:514} INFO - at java.base/java.util.concurrent.ThreadPoolExecutor.runWorker(ThreadPoolExecutor.java:1128)
[2021-12-28 13:50:00,406] {spark_submit.py:514} INFO - at java.base/java.util.concurrent.ThreadPoolExecutor$Worker.run(ThreadPoolExecutor.java:628)
[2021-12-28 13:50:00,406] {spark_submit.py:514} INFO - at java.base/java.lang.Thread.run(Thread.java:829)
[2021-12-28 13:50:00,407] {spark_submit.py:514} INFO - Caused by: java.io.IOException: Failed to connect to spark:7077
[2021-12-28 13:50:00,408] {spark_submit.py:514} INFO - at org.apache.spark.network.client.TransportClientFactory.createClient(TransportClientFactory.java:288)
[2021-12-28 13:50:00,409] {spark_submit.py:514} INFO - at org.apache.spark.network.client.TransportClientFactory.createClient(TransportClientFactory.java:218)
[2021-12-28 13:50:00,410] {spark_submit.py:514} INFO - at org.apache.spark.network.client.TransportClientFactory.createClient(TransportClientFactory.java:230)
[2021-12-28 13:50:00,411] {spark_submit.py:514} INFO - at org.apache.spark.rpc.netty.NettyRpcEnv.createClient(NettyRpcEnv.scala:204)
[2021-12-28 13:50:00,412] {spark_submit.py:514} INFO - at org.apache.spark.rpc.netty.Outbox$$anon$1.call(Outbox.scala:202)
[2021-12-28 13:50:00,412] {spark_submit.py:514} INFO - at org.apache.spark.rpc.netty.Outbox$$anon$1.call(Outbox.scala:198)
[2021-12-28 13:50:00,413] {spark_submit.py:514} INFO - ... 4 more
[2021-12-28 13:50:00,414] {spark_submit.py:514} INFO - Caused by: java.net.UnknownHostException: spark
[2021-12-28 13:50:00,415] {spark_submit.py:514} INFO - at java.base/java.net.InetAddress$CachedAddresses.get(InetAddress.java:797)
[2021-12-28 13:50:00,417] {spark_submit.py:514} INFO - at java.base/java.net.InetAddress.getAllByName0(InetAddress.java:1509)
[2021-12-28 13:50:00,418] {spark_submit.py:514} INFO - at java.base/java.net.InetAddress.getAllByName(InetAddress.java:1368)
[2021-12-28 13:50:00,418] {spark_submit.py:514} INFO - at java.base/java.net.InetAddress.getAllByName(InetAddress.java:1302)
[2021-12-28 13:50:00,419] {spark_submit.py:514} INFO - at java.base/java.net.InetAddress.getByName(InetAddress.java:1252)
[2021-12-28 13:50:00,420] {spark_submit.py:514} INFO - at io.netty.util.internal.SocketUtils$8.run(SocketUtils.java:156)
[2021-12-28 13:50:00,421] {spark_submit.py:514} INFO - at io.netty.util.internal.SocketUtils$8.run(SocketUtils.java:153)
[2021-12-28 13:50:00,422] {spark_submit.py:514} INFO - at java.base/java.security.AccessController.doPrivileged(Native Method)
[2021-12-28 13:50:00,423] {spark_submit.py:514} INFO - at io.netty.util.internal.SocketUtils.addressByName(SocketUtils.java:153)
[2021-12-28 13:50:00,423] {spark_submit.py:514} INFO - at io.netty.resolver.DefaultNameResolver.doResolve(DefaultNameResolver.java:41)
[2021-12-28 13:50:00,424] {spark_submit.py:514} INFO - at io.netty.resolver.SimpleNameResolver.resolve(SimpleNameResolver.java:61)
[2021-12-28 13:50:00,425] {spark_submit.py:514} INFO - at io.netty.resolver.SimpleNameResolver.resolve(SimpleNameResolver.java:53)
[2021-12-28 13:50:00,426] {spark_submit.py:514} INFO - at io.netty.resolver.InetSocketAddressResolver.doResolve(InetSocketAddressResolver.java:55)
[2021-12-28 13:50:00,427] {spark_submit.py:514} INFO - at io.netty.resolver.InetSocketAddressResolver.doResolve(InetSocketAddressResolver.java:31)
[2021-12-28 13:50:00,428] {spark_submit.py:514} INFO - at io.netty.resolver.AbstractAddressResolver.resolve(AbstractAddressResolver.java:106)
[2021-12-28 13:50:00,429] {spark_submit.py:514} INFO - at io.netty.bootstrap.Bootstrap.doResolveAndConnect0(Bootstrap.java:206)
[2021-12-28 13:50:00,430] {spark_submit.py:514} INFO - at io.netty.bootstrap.Bootstrap.access$000(Bootstrap.java:46)
[2021-12-28 13:50:00,431] {spark_submit.py:514} INFO - at io.netty.bootstrap.Bootstrap$1.operationComplete(Bootstrap.java:180)
[2021-12-28 13:50:00,432] {spark_submit.py:514} INFO - at io.netty.bootstrap.Bootstrap$1.operationComplete(Bootstrap.java:166)
[2021-12-28 13:50:00,433] {spark_submit.py:514} INFO - at io.netty.util.concurrent.DefaultPromise.notifyListener0(DefaultPromise.java:578)
[2021-12-28 13:50:00,434] {spark_submit.py:514} INFO - at io.netty.util.concurrent.DefaultPromise.notifyListenersNow(DefaultPromise.java:552)
[2021-12-28 13:50:00,435] {spark_submit.py:514} INFO - at io.netty.util.concurrent.DefaultPromise.notifyListeners(DefaultPromise.java:491)
[2021-12-28 13:50:00,436] {spark_submit.py:514} INFO - at io.netty.util.concurrent.DefaultPromise.setValue0(DefaultPromise.java:616)
[2021-12-28 13:50:00,437] {spark_submit.py:514} INFO - at io.netty.util.concurrent.DefaultPromise.setSuccess0(DefaultPromise.java:605)
[2021-12-28 13:50:00,438] {spark_submit.py:514} INFO - at io.netty.util.concurrent.DefaultPromise.trySuccess(DefaultPromise.java:104)
[2021-12-28 13:50:00,439] {spark_submit.py:514} INFO - at io.netty.channel.DefaultChannelPromise.trySuccess(DefaultChannelPromise.java:84)
[2021-12-28 13:50:00,440] {spark_submit.py:514} INFO - at io.netty.channel.AbstractChannel$AbstractUnsafe.safeSetSuccess(AbstractChannel.java:1008)
[2021-12-28 13:50:00,441] {spark_submit.py:514} INFO - at io.netty.channel.AbstractChannel$AbstractUnsafe.register0(AbstractChannel.java:516)
[2021-12-28 13:50:00,442] {spark_submit.py:514} INFO - at io.netty.channel.AbstractChannel$AbstractUnsafe.access$200(AbstractChannel.java:429)
[2021-12-28 13:50:00,444] {spark_submit.py:514} INFO - at io.netty.channel.AbstractChannel$AbstractUnsafe$1.run(AbstractChannel.java:486)
[2021-12-28 13:50:00,445] {spark_submit.py:514} INFO - at io.netty.util.concurrent.AbstractEventExecutor.safeExecute(AbstractEventExecutor.java:164)
[2021-12-28 13:50:00,446] {spark_submit.py:514} INFO - at io.netty.util.concurrent.SingleThreadEventExecutor.runAllTasks(SingleThreadEventExecutor.java:469)
[2021-12-28 13:50:00,447] {spark_submit.py:514} INFO - at io.netty.channel.nio.NioEventLoop.run(NioEventLoop.java:500)
[2021-12-28 13:50:00,448] {spark_submit.py:514} INFO - at io.netty.util.concurrent.SingleThreadEventExecutor$4.run(SingleThreadEventExecutor.java:986)
[2021-12-28 13:50:00,449] {spark_submit.py:514} INFO - at io.netty.util.internal.ThreadExecutorMap$2.run(ThreadExecutorMap.java:74)
[2021-12-28 13:50:00,451] {spark_submit.py:514} INFO - at io.netty.util.concurrent.FastThreadLocalRunnable.run(FastThreadLocalRunnable.java:30)
[2021-12-28 13:50:00,452] {spark_submit.py:514} INFO - ... 1 more
[2021-12-28 13:50:20,192] {spark_submit.py:514} INFO - 21/12/28 13:50:20 INFO StandaloneAppClient$ClientEndpoint: Connecting to master spark://spark:7077...
[2021-12-28 13:50:20,210] {spark_submit.py:514} INFO - 21/12/28 13:50:20 WARN StandaloneAppClient$ClientEndpoint: Failed to connect to master spark:7077
[2021-12-28 13:50:20,211] {spark_submit.py:514} INFO - org.apache.spark.SparkException: Exception thrown in awaitResult:
[2021-12-28 13:50:20,212] {spark_submit.py:514} INFO - at org.apache.spark.util.ThreadUtils$.awaitResult(ThreadUtils.scala:301)
[2021-12-28 13:50:20,213] {spark_submit.py:514} INFO - at org.apache.spark.rpc.RpcTimeout.awaitResult(RpcTimeout.scala:75)
[2021-12-28 13:50:20,214] {spark_submit.py:514} INFO - at org.apache.spark.rpc.RpcEnv.setupEndpointRefByURI(RpcEnv.scala:101)
[2021-12-28 13:50:20,214] {spark_submit.py:514} INFO - at org.apache.spark.rpc.RpcEnv.setupEndpointRef(RpcEnv.scala:109)
[2021-12-28 13:50:20,215] {spark_submit.py:514} INFO - at org.apache.spark.deploy.client.StandaloneAppClient$ClientEndpoint$$anon$1.run(StandaloneAppClient.scala:107)
[2021-12-28 13:50:20,217] {spark_submit.py:514} INFO - at java.base/java.util.concurrent.Executors$RunnableAdapter.call(Executors.java:515)
[2021-12-28 13:50:20,218] {spark_submit.py:514} INFO - at java.base/java.util.concurrent.FutureTask.run(FutureTask.java:264)
[2021-12-28 13:50:20,218] {spark_submit.py:514} INFO - at java.base/java.util.concurrent.ThreadPoolExecutor.runWorker(ThreadPoolExecutor.java:1128)
[2021-12-28 13:50:20,219] {spark_submit.py:514} INFO - at java.base/java.util.concurrent.ThreadPoolExecutor$Worker.run(ThreadPoolExecutor.java:628)
[2021-12-28 13:50:20,220] {spark_submit.py:514} INFO - at java.base/java.lang.Thread.run(Thread.java:829)
[2021-12-28 13:50:20,221] {spark_submit.py:514} INFO - Caused by: java.io.IOException: Failed to connect to spark:7077
[2021-12-28 13:50:20,221] {spark_submit.py:514} INFO - at org.apache.spark.network.client.TransportClientFactory.createClient(TransportClientFactory.java:288)
[2021-12-28 13:50:20,222] {spark_submit.py:514} INFO - at org.apache.spark.network.client.TransportClientFactory.createClient(TransportClientFactory.java:218)
[2021-12-28 13:50:20,223] {spark_submit.py:514} INFO - at org.apache.spark.network.client.TransportClientFactory.createClient(TransportClientFactory.java:230)
[2021-12-28 13:50:20,224] {spark_submit.py:514} INFO - at org.apache.spark.rpc.netty.NettyRpcEnv.createClient(NettyRpcEnv.scala:204)
[2021-12-28 13:50:20,225] {spark_submit.py:514} INFO - at org.apache.spark.rpc.netty.Outbox$$anon$1.call(Outbox.scala:202)
[2021-12-28 13:50:20,225] {spark_submit.py:514} INFO - at org.apache.spark.rpc.netty.Outbox$$anon$1.call(Outbox.scala:198)
[2021-12-28 13:50:20,226] {spark_submit.py:514} INFO - ... 4 more
[2021-12-28 13:50:20,227] {spark_submit.py:514} INFO - Caused by: java.net.UnknownHostException: spark
[2021-12-28 13:50:20,228] {spark_submit.py:514} INFO - at java.base/java.net.InetAddress$CachedAddresses.get(InetAddress.java:797)
[2021-12-28 13:50:20,228] {spark_submit.py:514} INFO - at java.base/java.net.InetAddress.getAllByName0(InetAddress.java:1509)
[2021-12-28 13:50:20,229] {spark_submit.py:514} INFO - at java.base/java.net.InetAddress.getAllByName(InetAddress.java:1368)
[2021-12-28 13:50:20,229] {spark_submit.py:514} INFO - at java.base/java.net.InetAddress.getAllByName(InetAddress.java:1302)
[2021-12-28 13:50:20,230] {spark_submit.py:514} INFO - at java.base/java.net.InetAddress.getByName(InetAddress.java:1252)
[2021-12-28 13:50:20,231] {spark_submit.py:514} INFO - at io.netty.util.internal.SocketUtils$8.run(SocketUtils.java:156)
[2021-12-28 13:50:20,232] {spark_submit.py:514} INFO - at io.netty.util.internal.SocketUtils$8.run(SocketUtils.java:153)
[2021-12-28 13:50:20,232] {spark_submit.py:514} INFO - at java.base/java.security.AccessController.doPrivileged(Native Method)
[2021-12-28 13:50:20,233] {spark_submit.py:514} INFO - at io.netty.util.internal.SocketUtils.addressByName(SocketUtils.java:153)
[2021-12-28 13:50:20,234] {spark_submit.py:514} INFO - at io.netty.resolver.DefaultNameResolver.doResolve(DefaultNameResolver.java:41)
[2021-12-28 13:50:20,235] {spark_submit.py:514} INFO - at io.netty.resolver.SimpleNameResolver.resolve(SimpleNameResolver.java:61)
[2021-12-28 13:50:20,236] {spark_submit.py:514} INFO - at io.netty.resolver.SimpleNameResolver.resolve(SimpleNameResolver.java:53)
[2021-12-28 13:50:20,236] {spark_submit.py:514} INFO - at io.netty.resolver.InetSocketAddressResolver.doResolve(InetSocketAddressResolver.java:55)
[2021-12-28 13:50:20,237] {spark_submit.py:514} INFO - at io.netty.resolver.InetSocketAddressResolver.doResolve(InetSocketAddressResolver.java:31)
[2021-12-28 13:50:20,238] {spark_submit.py:514} INFO - at io.netty.resolver.AbstractAddressResolver.resolve(AbstractAddressResolver.java:106)
[2021-12-28 13:50:20,239] {spark_submit.py:514} INFO - at io.netty.bootstrap.Bootstrap.doResolveAndConnect0(Bootstrap.java:206)
[2021-12-28 13:50:20,240] {spark_submit.py:514} INFO - at io.netty.bootstrap.Bootstrap.access$000(Bootstrap.java:46)
[2021-12-28 13:50:20,241] {spark_submit.py:514} INFO - at io.netty.bootstrap.Bootstrap$1.operationComplete(Bootstrap.java:180)
[2021-12-28 13:50:20,243] {spark_submit.py:514} INFO - at io.netty.bootstrap.Bootstrap$1.operationComplete(Bootstrap.java:166)
[2021-12-28 13:50:20,244] {spark_submit.py:514} INFO - at io.netty.util.concurrent.DefaultPromise.notifyListener0(DefaultPromise.java:578)
[2021-12-28 13:50:20,245] {spark_submit.py:514} INFO - at io.netty.util.concurrent.DefaultPromise.notifyListenersNow(DefaultPromise.java:552)
[2021-12-28 13:50:20,248] {spark_submit.py:514} INFO - at io.netty.util.concurrent.DefaultPromise.notifyListeners(DefaultPromise.java:491)
[2021-12-28 13:50:20,250] {spark_submit.py:514} INFO - at io.netty.util.concurrent.DefaultPromise.setValue0(DefaultPromise.java:616)
[2021-12-28 13:50:20,251] {spark_submit.py:514} INFO - at io.netty.util.concurrent.DefaultPromise.setSuccess0(DefaultPromise.java:605)
[2021-12-28 13:50:20,252] {spark_submit.py:514} INFO - at io.netty.util.concurrent.DefaultPromise.trySuccess(DefaultPromise.java:104)
[2021-12-28 13:50:20,253] {spark_submit.py:514} INFO - at io.netty.channel.DefaultChannelPromise.trySuccess(DefaultChannelPromise.java:84)
[2021-12-28 13:50:20,254] {spark_submit.py:514} INFO - at io.netty.channel.AbstractChannel$AbstractUnsafe.safeSetSuccess(AbstractChannel.java:1008)
[2021-12-28 13:50:20,254] {spark_submit.py:514} INFO - at io.netty.channel.AbstractChannel$AbstractUnsafe.register0(AbstractChannel.java:516)
[2021-12-28 13:50:20,255] {spark_submit.py:514} INFO - at io.netty.channel.AbstractChannel$AbstractUnsafe.access$200(AbstractChannel.java:429)
[2021-12-28 13:50:20,257] {spark_submit.py:514} INFO - at io.netty.channel.AbstractChannel$AbstractUnsafe$1.run(AbstractChannel.java:486)
[2021-12-28 13:50:20,257] {spark_submit.py:514} INFO - at io.netty.util.concurrent.AbstractEventExecutor.safeExecute(AbstractEventExecutor.java:164)
[2021-12-28 13:50:20,259] {spark_submit.py:514} INFO - at io.netty.util.concurrent.SingleThreadEventExecutor.runAllTasks(SingleThreadEventExecutor.java:469)
[2021-12-28 13:50:20,260] {spark_submit.py:514} INFO - at io.netty.channel.nio.NioEventLoop.run(NioEventLoop.java:500)
[2021-12-28 13:50:20,261] {spark_submit.py:514} INFO - at io.netty.util.concurrent.SingleThreadEventExecutor$4.run(SingleThreadEventExecutor.java:986)
[2021-12-28 13:50:20,262] {spark_submit.py:514} INFO - at io.netty.util.internal.ThreadExecutorMap$2.run(ThreadExecutorMap.java:74)
[2021-12-28 13:50:20,262] {spark_submit.py:514} INFO - at io.netty.util.concurrent.FastThreadLocalRunnable.run(FastThreadLocalRunnable.java:30)
[2021-12-28 13:50:20,263] {spark_submit.py:514} INFO - ... 1 more
[2021-12-28 14:20:35,425] {spark_submit.py:514} INFO - 21/12/28 14:20:35 INFO StandaloneAppClient$ClientEndpoint: Connecting to master spark://spark:7077...
[2021-12-28 14:20:35,583] {local_task_job.py:142} ERROR - Heartbeat time limit exceeded!
[2021-12-28 14:20:35,703] {spark_submit.py:514} INFO - 21/12/28 14:20:35 WARN StandaloneAppClient$ClientEndpoint: Failed to connect to master spark:7077
[2021-12-28 14:20:35,712] {spark_submit.py:514} INFO - org.apache.spark.SparkException: Exception thrown in awaitResult:
[2021-12-28 14:20:35,723] {spark_submit.py:514} INFO - at org.apache.spark.util.ThreadUtils$.awaitResult(ThreadUtils.scala:301)
[2021-12-28 14:20:35,733] {spark_submit.py:514} INFO - at org.apache.spark.rpc.RpcTimeout.awaitResult(RpcTimeout.scala:75)
[2021-12-28 14:20:35,743] {spark_submit.py:514} INFO - at org.apache.spark.rpc.RpcEnv.setupEndpointRefByURI(RpcEnv.scala:101)
[2021-12-28 14:20:35,747] {spark_submit.py:514} INFO - at org.apache.spark.rpc.RpcEnv.setupEndpointRef(RpcEnv.scala:109)
[2021-12-28 14:20:35,763] {spark_submit.py:514} INFO - at org.apache.spark.deploy.client.StandaloneAppClient$ClientEndpoint$$anon$1.run(StandaloneAppClient.scala:107)
[2021-12-28 14:20:35,779] {spark_submit.py:514} INFO - at java.base/java.util.concurrent.Executors$RunnableAdapter.call(Executors.java:515)
[2021-12-28 14:20:35,775] {process_utils.py:100} INFO - Sending Signals.SIGTERM to GPID 57445
[2021-12-28 14:20:35,813] {spark_submit.py:514} INFO - at java.base/java.util.concurrent.FutureTask.run(FutureTask.java:264)
[2021-12-28 14:20:35,954] {logging_mixin.py:109} WARNING - --- Logging error ---
--- Logging error ---
--- Logging error ---
--- Logging error ---
--- Logging error ---
--- Logging error ---
--- Logging error ---
--- Logging error ---
--- Logging error ---
--- Logging error ---
--- Logging error ---
--- Logging error ---
--- Logging error ---
--- Logging error ---
--- Logging error ---
--- Logging error ---
--- Logging error ---
--- Logging error ---
--- Logging error ---
--- Logging error ---
--- Logging error ---
--- Logging error ---
--- Logging error ---
--- Logging error ---
--- Logging error ---
--- Logging error ---
--- Logging error ---
--- Logging error ---
--- Logging error ---
--- Logging error ---
--- Logging error ---
--- Logging error ---
--- Logging error ---
--- Logging error ---
--- Logging error ---
--- Logging error ---
--- Logging error ---
--- Logging error ---
--- Logging error ---
--- Logging error ---
--- Logging error ---
--- Logging error ---
--- Logging error ---
--- Logging error ---
--- Logging error ---
--- Logging error ---
--- Logging error ---
--- Logging error ---
--- Logging error ---
--- Logging error ---
--- Logging error ---
--- Logging error ---
--- Logging error ---
--- Logging error ---
--- Logging error ---
--- Logging error ---
--- Logging error ---
--- Logging error ---
--- Logging error ---
--- Logging error ---
--- Logging error ---
--- Logging error ---
--- Logging error ---
--- Logging error ---
--- Logging error ---
--- Logging error ---
--- Logging error ---
--- Logging error ---
--- Logging error ---
--- Logging error ---
[2021-12-28 14:20:36,006] {logging_mixin.py:109} WARNING - Traceback (most recent call last):
[2021-12-28 14:20:36,012] {logging_mixin.py:109} WARNING -   File "/usr/local/lib/python3.6/logging/__init__.py", line 998, in emit
    self.flush()
[2021-12-28 14:20:36,014] {logging_mixin.py:109} WARNING -   File "/usr/local/lib/python3.6/logging/__init__.py", line 978, in flush
    self.stream.flush()
[2021-12-28 14:20:36,023] {logging_mixin.py:109} WARNING - RuntimeError: reentrant call inside <_io.BufferedWriter name='/opt/***/logs/scraping_daft_meath/persist_data/2021-12-27T10:25:00+00:00/3.log'>
[2021-12-28 14:20:36,029] {logging_mixin.py:109} WARNING - 
During handling of the above exception, another exception occurred:
[2021-12-28 14:20:36,093] {logging_mixin.py:109} WARNING - Traceback (most recent call last):
[2021-12-28 14:20:36,122] {logging_mixin.py:109} WARNING -   File "/usr/local/lib/python3.6/logging/__init__.py", line 998, in emit
    self.flush()
[2021-12-28 14:20:36,130] {logging_mixin.py:109} WARNING -   File "/usr/local/lib/python3.6/logging/__init__.py", line 978, in flush
    self.stream.flush()
[2021-12-28 14:20:36,143] {logging_mixin.py:109} WARNING - RuntimeError: reentrant call inside <_io.BufferedWriter name='/opt/***/logs/scraping_daft_meath/persist_data/2021-12-27T10:25:00+00:00/3.log'>
[2021-12-28 14:20:36,160] {logging_mixin.py:109} WARNING - 
During handling of the above exception, another exception occurred:
[2021-12-28 14:20:36,166] {logging_mixin.py:109} WARNING - Traceback (most recent call last):
[2021-12-28 14:20:36,172] {logging_mixin.py:109} WARNING -   File "/usr/local/lib/python3.6/logging/__init__.py", line 998, in emit
    self.flush()
[2021-12-28 14:20:36,177] {logging_mixin.py:109} WARNING -   File "/usr/local/lib/python3.6/logging/__init__.py", line 978, in flush
    self.stream.flush()
[2021-12-28 14:20:36,187] {logging_mixin.py:109} WARNING - RuntimeError: reentrant call inside <_io.BufferedWriter name='/opt/***/logs/scraping_daft_meath/persist_data/2021-12-27T10:25:00+00:00/3.log'>
[2021-12-28 14:20:36,196] {process_utils.py:66} INFO - Process psutil.Process(pid=57684, status='terminated', started='13:49:50') (57684) terminated with exit code None
[2021-12-28 14:20:36,206] {logging_mixin.py:109} WARNING - 
During handling of the above exception, another exception occurred:
[2021-12-28 14:20:36,216] {logging_mixin.py:109} WARNING - Traceback (most recent call last):
[2021-12-28 14:20:36,228] {logging_mixin.py:109} WARNING -   File "/usr/local/lib/python3.6/logging/__init__.py", line 998, in emit
    self.flush()
[2021-12-28 14:20:36,230] {logging_mixin.py:109} WARNING -   File "/usr/local/lib/python3.6/logging/__init__.py", line 978, in flush
    self.stream.flush()
[2021-12-28 14:20:36,234] {logging_mixin.py:109} WARNING - RuntimeError: reentrant call inside <_io.BufferedWriter name='/opt/***/logs/scraping_daft_meath/persist_data/2021-12-27T10:25:00+00:00/3.log'>
[2021-12-28 14:20:36,245] {logging_mixin.py:109} WARNING - 
During handling of the above exception, another exception occurred:
[2021-12-28 14:20:36,252] {logging_mixin.py:109} WARNING - Traceback (most recent call last):
[2021-12-28 14:20:36,274] {logging_mixin.py:109} WARNING -   File "/usr/local/lib/python3.6/logging/__init__.py", line 998, in emit
    self.flush()
[2021-12-28 14:20:36,282] {logging_mixin.py:109} WARNING -   File "/usr/local/lib/python3.6/logging/__init__.py", line 978, in flush
    self.stream.flush()
[2021-12-28 14:20:36,294] {logging_mixin.py:109} WARNING - RuntimeError: reentrant call inside <_io.BufferedWriter name='/opt/***/logs/scraping_daft_meath/persist_data/2021-12-27T10:25:00+00:00/3.log'>
[2021-12-28 14:20:36,308] {logging_mixin.py:109} WARNING - 
During handling of the above exception, another exception occurred:
[2021-12-28 14:20:36,312] {logging_mixin.py:109} WARNING - Traceback (most recent call last):
[2021-12-28 14:20:36,320] {logging_mixin.py:109} WARNING -   File "/usr/local/lib/python3.6/logging/__init__.py", line 998, in emit
    self.flush()
[2021-12-28 14:20:36,329] {logging_mixin.py:109} WARNING -   File "/usr/local/lib/python3.6/logging/__init__.py", line 978, in flush
    self.stream.flush()
[2021-12-28 14:20:36,332] {logging_mixin.py:109} WARNING - RuntimeError: reentrant call inside <_io.BufferedWriter name='/opt/***/logs/scraping_daft_meath/persist_data/2021-12-27T10:25:00+00:00/3.log'>
[2021-12-28 14:20:36,369] {logging_mixin.py:109} WARNING - 
During handling of the above exception, another exception occurred:
[2021-12-28 14:20:36,372] {logging_mixin.py:109} WARNING - Traceback (most recent call last):
[2021-12-28 14:20:36,374] {logging_mixin.py:109} WARNING -   File "/usr/local/lib/python3.6/logging/__init__.py", line 998, in emit
    self.flush()
[2021-12-28 14:20:36,375] {logging_mixin.py:109} WARNING -   File "/usr/local/lib/python3.6/logging/__init__.py", line 978, in flush
    self.stream.flush()
[2021-12-28 14:20:36,380] {logging_mixin.py:109} WARNING - RuntimeError: reentrant call inside <_io.BufferedWriter name='/opt/***/logs/scraping_daft_meath/persist_data/2021-12-27T10:25:00+00:00/3.log'>
[2021-12-28 14:20:36,398] {logging_mixin.py:109} WARNING - 
During handling of the above exception, another exception occurred:
[2021-12-28 14:20:36,401] {logging_mixin.py:109} WARNING - Traceback (most recent call last):
[2021-12-28 14:20:36,448] {logging_mixin.py:109} WARNING -   File "/usr/local/lib/python3.6/logging/__init__.py", line 998, in emit
    self.flush()
[2021-12-28 14:20:36,614] {logging_mixin.py:109} WARNING -   File "/usr/local/lib/python3.6/logging/__init__.py", line 978, in flush
    self.stream.flush()
[2021-12-28 14:20:39,801] {logging_mixin.py:109} WARNING - RuntimeError: reentrant call inside <_io.BufferedWriter name='/opt/***/logs/scraping_daft_meath/persist_data/2021-12-27T10:25:00+00:00/3.log'>
[2021-12-28 14:20:41,109] {logging_mixin.py:109} WARNING - 
During handling of the above exception, another exception occurred:
[2021-12-28 14:20:46,511] {logging_mixin.py:109} WARNING - Traceback (most recent call last):
[2021-12-28 14:20:46,529] {logging_mixin.py:109} WARNING -   File "/usr/local/lib/python3.6/logging/__init__.py", line 998, in emit
    self.flush()
[2021-12-28 14:20:46,557] {logging_mixin.py:109} WARNING -   File "/usr/local/lib/python3.6/logging/__init__.py", line 978, in flush
    self.stream.flush()
[2021-12-28 14:20:46,583] {logging_mixin.py:109} WARNING - RuntimeError: reentrant call inside <_io.BufferedWriter name='/opt/***/logs/scraping_daft_meath/persist_data/2021-12-27T10:25:00+00:00/3.log'>
[2021-12-28 14:20:46,638] {logging_mixin.py:109} WARNING - 
During handling of the above exception, another exception occurred:
[2021-12-28 14:20:46,654] {logging_mixin.py:109} WARNING - Traceback (most recent call last):
[2021-12-28 14:20:46,869] {logging_mixin.py:109} WARNING -   File "/usr/local/lib/python3.6/logging/__init__.py", line 998, in emit
    self.flush()
[2021-12-28 14:20:46,882] {logging_mixin.py:109} WARNING -   File "/usr/local/lib/python3.6/logging/__init__.py", line 978, in flush
    self.stream.flush()
[2021-12-28 14:20:46,911] {logging_mixin.py:109} WARNING - RuntimeError: reentrant call inside <_io.BufferedWriter name='/opt/***/logs/scraping_daft_meath/persist_data/2021-12-27T10:25:00+00:00/3.log'>
[2021-12-28 14:20:46,931] {logging_mixin.py:109} WARNING - 
During handling of the above exception, another exception occurred:
[2021-12-28 14:20:46,964] {logging_mixin.py:109} WARNING - Traceback (most recent call last):
[2021-12-28 14:20:46,986] {logging_mixin.py:109} WARNING -   File "/usr/local/lib/python3.6/logging/__init__.py", line 998, in emit
    self.flush()
[2021-12-28 14:20:47,017] {logging_mixin.py:109} WARNING -   File "/usr/local/lib/python3.6/logging/__init__.py", line 978, in flush
    self.stream.flush()
[2021-12-28 14:20:47,055] {logging_mixin.py:109} WARNING - RuntimeError: reentrant call inside <_io.BufferedWriter name='/opt/***/logs/scraping_daft_meath/persist_data/2021-12-27T10:25:00+00:00/3.log'>
[2021-12-28 14:20:47,060] {logging_mixin.py:109} WARNING - 
During handling of the above exception, another exception occurred:
[2021-12-28 14:20:47,069] {logging_mixin.py:109} WARNING - Traceback (most recent call last):
[2021-12-28 14:20:47,098] {logging_mixin.py:109} WARNING -   File "/usr/local/lib/python3.6/logging/__init__.py", line 998, in emit
    self.flush()
[2021-12-28 14:20:47,164] {logging_mixin.py:109} WARNING -   File "/usr/local/lib/python3.6/logging/__init__.py", line 978, in flush
    self.stream.flush()
[2021-12-28 14:20:47,186] {logging_mixin.py:109} WARNING - RuntimeError: reentrant call inside <_io.BufferedWriter name='/opt/***/logs/scraping_daft_meath/persist_data/2021-12-27T10:25:00+00:00/3.log'>
[2021-12-28 14:20:47,210] {logging_mixin.py:109} WARNING - 
During handling of the above exception, another exception occurred:
[2021-12-28 14:20:47,241] {logging_mixin.py:109} WARNING - Traceback (most recent call last):
[2021-12-28 14:20:47,292] {logging_mixin.py:109} WARNING -   File "/usr/local/lib/python3.6/logging/__init__.py", line 998, in emit
    self.flush()
[2021-12-28 14:20:47,318] {logging_mixin.py:109} WARNING -   File "/usr/local/lib/python3.6/logging/__init__.py", line 978, in flush
    self.stream.flush()
[2021-12-28 14:20:47,339] {logging_mixin.py:109} WARNING - RuntimeError: reentrant call inside <_io.BufferedWriter name='/opt/***/logs/scraping_daft_meath/persist_data/2021-12-27T10:25:00+00:00/3.log'>
[2021-12-28 14:20:47,353] {logging_mixin.py:109} WARNING - 
During handling of the above exception, another exception occurred:
[2021-12-28 14:20:47,378] {logging_mixin.py:109} WARNING - Traceback (most recent call last):
[2021-12-28 14:20:47,395] {logging_mixin.py:109} WARNING -   File "/usr/local/lib/python3.6/logging/__init__.py", line 998, in emit
    self.flush()
[2021-12-28 14:20:47,430] {logging_mixin.py:109} WARNING -   File "/usr/local/lib/python3.6/logging/__init__.py", line 978, in flush
    self.stream.flush()
[2021-12-28 14:20:47,834] {logging_mixin.py:109} WARNING - RuntimeError: reentrant call inside <_io.BufferedWriter name='/opt/***/logs/scraping_daft_meath/persist_data/2021-12-27T10:25:00+00:00/3.log'>
[2021-12-28 14:20:47,886] {logging_mixin.py:109} WARNING - 
During handling of the above exception, another exception occurred:
[2021-12-28 14:20:47,913] {logging_mixin.py:109} WARNING - Traceback (most recent call last):
[2021-12-28 14:20:48,209] {logging_mixin.py:109} WARNING -   File "/usr/local/lib/python3.6/logging/__init__.py", line 998, in emit
    self.flush()
[2021-12-28 14:20:48,529] {logging_mixin.py:109} WARNING -   File "/usr/local/lib/python3.6/logging/__init__.py", line 978, in flush
    self.stream.flush()
[2021-12-28 14:20:48,792] {logging_mixin.py:109} WARNING - RuntimeError: reentrant call inside <_io.BufferedWriter name='/opt/***/logs/scraping_daft_meath/persist_data/2021-12-27T10:25:00+00:00/3.log'>
[2021-12-28 14:20:48,929] {logging_mixin.py:109} WARNING - 
During handling of the above exception, another exception occurred:
[2021-12-28 14:20:48,950] {logging_mixin.py:109} WARNING - Traceback (most recent call last):
[2021-12-28 14:20:49,081] {logging_mixin.py:109} WARNING -   File "/usr/local/lib/python3.6/logging/__init__.py", line 998, in emit
    self.flush()
[2021-12-28 14:20:49,116] {logging_mixin.py:109} WARNING -   File "/usr/local/lib/python3.6/logging/__init__.py", line 978, in flush
    self.stream.flush()
[2021-12-28 14:20:56,195] {logging_mixin.py:109} WARNING - RuntimeError: reentrant call inside <_io.BufferedWriter name='/opt/***/logs/scraping_daft_meath/persist_data/2021-12-27T10:25:00+00:00/3.log'>
[2021-12-28 14:20:56,891] {logging_mixin.py:109} WARNING - 
During handling of the above exception, another exception occurred:
[2021-12-28 14:20:57,302] {logging_mixin.py:109} WARNING - Traceback (most recent call last):
[2021-12-28 14:20:57,488] {logging_mixin.py:109} WARNING -   File "/usr/local/lib/python3.6/logging/__init__.py", line 998, in emit
    self.flush()
[2021-12-28 14:20:57,676] {logging_mixin.py:109} WARNING -   File "/usr/local/lib/python3.6/logging/__init__.py", line 978, in flush
    self.stream.flush()
[2021-12-28 14:20:59,139] {logging_mixin.py:109} WARNING - RuntimeError: reentrant call inside <_io.BufferedWriter name='/opt/***/logs/scraping_daft_meath/persist_data/2021-12-27T10:25:00+00:00/3.log'>
[2021-12-28 14:20:59,176] {logging_mixin.py:109} WARNING - 
During handling of the above exception, another exception occurred:
[2021-12-28 14:20:59,224] {logging_mixin.py:109} WARNING - Traceback (most recent call last):
[2021-12-28 14:20:59,248] {logging_mixin.py:109} WARNING -   File "/usr/local/lib/python3.6/logging/__init__.py", line 998, in emit
    self.flush()
[2021-12-28 14:20:59,269] {logging_mixin.py:109} WARNING -   File "/usr/local/lib/python3.6/logging/__init__.py", line 978, in flush
    self.stream.flush()
[2021-12-28 14:20:59,427] {logging_mixin.py:109} WARNING - RuntimeError: reentrant call inside <_io.BufferedWriter name='/opt/***/logs/scraping_daft_meath/persist_data/2021-12-27T10:25:00+00:00/3.log'>
[2021-12-28 14:20:59,560] {logging_mixin.py:109} WARNING - 
During handling of the above exception, another exception occurred:
[2021-12-28 14:20:59,670] {logging_mixin.py:109} WARNING - Traceback (most recent call last):
[2021-12-28 14:20:59,718] {logging_mixin.py:109} WARNING -   File "/usr/local/lib/python3.6/logging/__init__.py", line 998, in emit
    self.flush()
[2021-12-28 14:20:59,871] {logging_mixin.py:109} WARNING -   File "/usr/local/lib/python3.6/logging/__init__.py", line 978, in flush
    self.stream.flush()
[2021-12-28 14:20:59,982] {logging_mixin.py:109} WARNING - RuntimeError: reentrant call inside <_io.BufferedWriter name='/opt/***/logs/scraping_daft_meath/persist_data/2021-12-27T10:25:00+00:00/3.log'>
[2021-12-28 14:21:00,164] {logging_mixin.py:109} WARNING - 
During handling of the above exception, another exception occurred:
[2021-12-28 14:21:00,187] {logging_mixin.py:109} WARNING - Traceback (most recent call last):
[2021-12-28 14:21:00,204] {logging_mixin.py:109} WARNING -   File "/usr/local/lib/python3.6/logging/__init__.py", line 998, in emit
    self.flush()
[2021-12-28 14:21:00,212] {logging_mixin.py:109} WARNING -   File "/usr/local/lib/python3.6/logging/__init__.py", line 978, in flush
    self.stream.flush()
[2021-12-28 14:21:00,257] {logging_mixin.py:109} WARNING - RuntimeError: reentrant call inside <_io.BufferedWriter name='/opt/***/logs/scraping_daft_meath/persist_data/2021-12-27T10:25:00+00:00/3.log'>
[2021-12-28 14:21:00,377] {logging_mixin.py:109} WARNING - 
During handling of the above exception, another exception occurred:
[2021-12-28 14:21:00,583] {logging_mixin.py:109} WARNING - Traceback (most recent call last):
[2021-12-28 14:21:00,675] {logging_mixin.py:109} WARNING -   File "/usr/local/lib/python3.6/logging/__init__.py", line 998, in emit
    self.flush()
[2021-12-28 14:21:00,752] {logging_mixin.py:109} WARNING -   File "/usr/local/lib/python3.6/logging/__init__.py", line 978, in flush
    self.stream.flush()
[2021-12-28 14:21:00,772] {logging_mixin.py:109} WARNING - RuntimeError: reentrant call inside <_io.BufferedWriter name='/opt/***/logs/scraping_daft_meath/persist_data/2021-12-27T10:25:00+00:00/3.log'>
[2021-12-28 14:21:00,812] {logging_mixin.py:109} WARNING - 
During handling of the above exception, another exception occurred:
[2021-12-28 14:21:00,897] {logging_mixin.py:109} WARNING - Traceback (most recent call last):
[2021-12-28 14:21:00,941] {logging_mixin.py:109} WARNING -   File "/usr/local/lib/python3.6/logging/__init__.py", line 998, in emit
    self.flush()
[2021-12-28 14:21:01,106] {logging_mixin.py:109} WARNING -   File "/usr/local/lib/python3.6/logging/__init__.py", line 978, in flush
    self.stream.flush()
[2021-12-28 14:21:01,338] {logging_mixin.py:109} WARNING - RuntimeError: reentrant call inside <_io.BufferedWriter name='/opt/***/logs/scraping_daft_meath/persist_data/2021-12-27T10:25:00+00:00/3.log'>
[2021-12-28 14:21:01,462] {logging_mixin.py:109} WARNING - 
During handling of the above exception, another exception occurred:
[2021-12-28 14:21:01,508] {logging_mixin.py:109} WARNING - Traceback (most recent call last):
[2021-12-28 14:21:01,574] {logging_mixin.py:109} WARNING -   File "/usr/local/lib/python3.6/logging/__init__.py", line 998, in emit
    self.flush()
[2021-12-28 14:21:01,614] {logging_mixin.py:109} WARNING -   File "/usr/local/lib/python3.6/logging/__init__.py", line 978, in flush
    self.stream.flush()
[2021-12-28 14:21:01,630] {logging_mixin.py:109} WARNING - RuntimeError: reentrant call inside <_io.BufferedWriter name='/opt/***/logs/scraping_daft_meath/persist_data/2021-12-27T10:25:00+00:00/3.log'>
[2021-12-28 14:21:01,655] {logging_mixin.py:109} WARNING - 
During handling of the above exception, another exception occurred:
[2021-12-28 14:21:01,722] {logging_mixin.py:109} WARNING - Traceback (most recent call last):
[2021-12-28 14:21:01,765] {logging_mixin.py:109} WARNING -   File "/usr/local/lib/python3.6/logging/__init__.py", line 998, in emit
    self.flush()
[2021-12-28 14:21:01,775] {logging_mixin.py:109} WARNING -   File "/usr/local/lib/python3.6/logging/__init__.py", line 978, in flush
    self.stream.flush()
[2021-12-28 14:21:01,843] {logging_mixin.py:109} WARNING - RuntimeError: reentrant call inside <_io.BufferedWriter name='/opt/***/logs/scraping_daft_meath/persist_data/2021-12-27T10:25:00+00:00/3.log'>
[2021-12-28 14:21:02,061] {logging_mixin.py:109} WARNING - 
During handling of the above exception, another exception occurred:
[2021-12-28 14:21:02,136] {logging_mixin.py:109} WARNING - Traceback (most recent call last):
[2021-12-28 14:21:02,366] {logging_mixin.py:109} WARNING -   File "/usr/local/lib/python3.6/logging/__init__.py", line 998, in emit
    self.flush()
[2021-12-28 14:21:02,392] {logging_mixin.py:109} WARNING -   File "/usr/local/lib/python3.6/logging/__init__.py", line 978, in flush
    self.stream.flush()
[2021-12-28 14:21:02,443] {logging_mixin.py:109} WARNING - RuntimeError: reentrant call inside <_io.BufferedWriter name='/opt/***/logs/scraping_daft_meath/persist_data/2021-12-27T10:25:00+00:00/3.log'>
[2021-12-28 14:21:02,477] {logging_mixin.py:109} WARNING - 
During handling of the above exception, another exception occurred:
[2021-12-28 14:21:02,504] {logging_mixin.py:109} WARNING - Traceback (most recent call last):
[2021-12-28 14:21:02,532] {logging_mixin.py:109} WARNING -   File "/usr/local/lib/python3.6/logging/__init__.py", line 998, in emit
    self.flush()
[2021-12-28 14:21:02,564] {logging_mixin.py:109} WARNING -   File "/usr/local/lib/python3.6/logging/__init__.py", line 978, in flush
    self.stream.flush()
[2021-12-28 14:21:02,612] {logging_mixin.py:109} WARNING - RuntimeError: reentrant call inside <_io.BufferedWriter name='/opt/***/logs/scraping_daft_meath/persist_data/2021-12-27T10:25:00+00:00/3.log'>
[2021-12-28 14:21:02,771] {logging_mixin.py:109} WARNING - 
During handling of the above exception, another exception occurred:
[2021-12-28 14:21:02,915] {logging_mixin.py:109} WARNING - Traceback (most recent call last):
[2021-12-28 14:21:02,959] {logging_mixin.py:109} WARNING -   File "/usr/local/lib/python3.6/logging/__init__.py", line 998, in emit
    self.flush()
[2021-12-28 14:21:03,758] {logging_mixin.py:109} WARNING -   File "/usr/local/lib/python3.6/logging/__init__.py", line 978, in flush
    self.stream.flush()
[2021-12-28 14:21:04,259] {logging_mixin.py:109} WARNING - RuntimeError: reentrant call inside <_io.BufferedWriter name='/opt/***/logs/scraping_daft_meath/persist_data/2021-12-27T10:25:00+00:00/3.log'>
[2021-12-28 14:21:04,560] {logging_mixin.py:109} WARNING - 
During handling of the above exception, another exception occurred:
[2021-12-28 14:21:04,589] {logging_mixin.py:109} WARNING - Traceback (most recent call last):
[2021-12-28 14:21:05,280] {logging_mixin.py:109} WARNING -   File "/usr/local/lib/python3.6/logging/__init__.py", line 998, in emit
    self.flush()
[2021-12-28 14:21:05,311] {logging_mixin.py:109} WARNING -   File "/usr/local/lib/python3.6/logging/__init__.py", line 978, in flush
    self.stream.flush()
[2021-12-28 14:21:05,409] {logging_mixin.py:109} WARNING - RuntimeError: reentrant call inside <_io.BufferedWriter name='/opt/***/logs/scraping_daft_meath/persist_data/2021-12-27T10:25:00+00:00/3.log'>
[2021-12-28 14:21:05,577] {logging_mixin.py:109} WARNING - 
During handling of the above exception, another exception occurred:
[2021-12-28 14:21:05,838] {logging_mixin.py:109} WARNING - Traceback (most recent call last):
[2021-12-28 14:21:05,864] {logging_mixin.py:109} WARNING -   File "/usr/local/lib/python3.6/logging/__init__.py", line 998, in emit
    self.flush()
[2021-12-28 14:21:05,889] {logging_mixin.py:109} WARNING -   File "/usr/local/lib/python3.6/logging/__init__.py", line 978, in flush
    self.stream.flush()
[2021-12-28 14:21:05,904] {logging_mixin.py:109} WARNING - RuntimeError: reentrant call inside <_io.BufferedWriter name='/opt/***/logs/scraping_daft_meath/persist_data/2021-12-27T10:25:00+00:00/3.log'>
[2021-12-28 14:21:05,912] {logging_mixin.py:109} WARNING - 
During handling of the above exception, another exception occurred:
[2021-12-28 14:21:05,940] {logging_mixin.py:109} WARNING - Traceback (most recent call last):
[2021-12-28 14:21:06,034] {logging_mixin.py:109} WARNING -   File "/usr/local/lib/python3.6/logging/__init__.py", line 998, in emit
    self.flush()
[2021-12-28 14:21:06,054] {logging_mixin.py:109} WARNING -   File "/usr/local/lib/python3.6/logging/__init__.py", line 978, in flush
    self.stream.flush()
[2021-12-28 14:21:06,096] {logging_mixin.py:109} WARNING - RuntimeError: reentrant call inside <_io.BufferedWriter name='/opt/***/logs/scraping_daft_meath/persist_data/2021-12-27T10:25:00+00:00/3.log'>
[2021-12-28 14:21:06,103] {logging_mixin.py:109} WARNING - 
During handling of the above exception, another exception occurred:
[2021-12-28 14:21:06,121] {logging_mixin.py:109} WARNING - Traceback (most recent call last):
[2021-12-28 14:21:06,159] {logging_mixin.py:109} WARNING -   File "/usr/local/lib/python3.6/logging/__init__.py", line 998, in emit
    self.flush()
[2021-12-28 14:21:06,193] {logging_mixin.py:109} WARNING -   File "/usr/local/lib/python3.6/logging/__init__.py", line 978, in flush
    self.stream.flush()
[2021-12-28 14:21:06,209] {logging_mixin.py:109} WARNING - RuntimeError: reentrant call inside <_io.BufferedWriter name='/opt/***/logs/scraping_daft_meath/persist_data/2021-12-27T10:25:00+00:00/3.log'>
[2021-12-28 14:21:06,227] {logging_mixin.py:109} WARNING - 
During handling of the above exception, another exception occurred:
[2021-12-28 14:21:06,262] {logging_mixin.py:109} WARNING - Traceback (most recent call last):
[2021-12-28 14:21:06,539] {logging_mixin.py:109} WARNING -   File "/usr/local/lib/python3.6/logging/__init__.py", line 998, in emit
    self.flush()
[2021-12-28 14:21:06,554] {logging_mixin.py:109} WARNING -   File "/usr/local/lib/python3.6/logging/__init__.py", line 978, in flush
    self.stream.flush()
[2021-12-28 14:21:06,575] {logging_mixin.py:109} WARNING - RuntimeError: reentrant call inside <_io.BufferedWriter name='/opt/***/logs/scraping_daft_meath/persist_data/2021-12-27T10:25:00+00:00/3.log'>
[2021-12-28 14:21:06,590] {logging_mixin.py:109} WARNING - 
During handling of the above exception, another exception occurred:
[2021-12-28 14:21:06,606] {logging_mixin.py:109} WARNING - Traceback (most recent call last):
[2021-12-28 14:21:06,615] {logging_mixin.py:109} WARNING -   File "/usr/local/lib/python3.6/logging/__init__.py", line 998, in emit
    self.flush()
[2021-12-28 14:21:06,636] {logging_mixin.py:109} WARNING -   File "/usr/local/lib/python3.6/logging/__init__.py", line 978, in flush
    self.stream.flush()
[2021-12-28 14:21:06,656] {logging_mixin.py:109} WARNING - RuntimeError: reentrant call inside <_io.BufferedWriter name='/opt/***/logs/scraping_daft_meath/persist_data/2021-12-27T10:25:00+00:00/3.log'>
[2021-12-28 14:21:06,676] {logging_mixin.py:109} WARNING - 
During handling of the above exception, another exception occurred:
[2021-12-28 14:21:06,693] {logging_mixin.py:109} WARNING - Traceback (most recent call last):
[2021-12-28 14:21:06,704] {logging_mixin.py:109} WARNING -   File "/usr/local/lib/python3.6/logging/__init__.py", line 998, in emit
    self.flush()
[2021-12-28 14:21:06,713] {logging_mixin.py:109} WARNING -   File "/usr/local/lib/python3.6/logging/__init__.py", line 978, in flush
    self.stream.flush()
[2021-12-28 14:21:06,745] {logging_mixin.py:109} WARNING - RuntimeError: reentrant call inside <_io.BufferedWriter name='/opt/***/logs/scraping_daft_meath/persist_data/2021-12-27T10:25:00+00:00/3.log'>
[2021-12-28 14:21:06,763] {logging_mixin.py:109} WARNING - 
During handling of the above exception, another exception occurred:
[2021-12-28 14:21:06,787] {logging_mixin.py:109} WARNING - Traceback (most recent call last):
[2021-12-28 14:21:06,903] {logging_mixin.py:109} WARNING -   File "/usr/local/lib/python3.6/logging/__init__.py", line 998, in emit
    self.flush()
[2021-12-28 14:21:06,943] {logging_mixin.py:109} WARNING -   File "/usr/local/lib/python3.6/logging/__init__.py", line 978, in flush
    self.stream.flush()
[2021-12-28 14:21:06,956] {logging_mixin.py:109} WARNING - RuntimeError: reentrant call inside <_io.BufferedWriter name='/opt/***/logs/scraping_daft_meath/persist_data/2021-12-27T10:25:00+00:00/3.log'>
[2021-12-28 14:21:06,968] {logging_mixin.py:109} WARNING - 
During handling of the above exception, another exception occurred:
[2021-12-28 14:21:07,022] {logging_mixin.py:109} WARNING - Traceback (most recent call last):
[2021-12-28 14:21:07,040] {logging_mixin.py:109} WARNING -   File "/usr/local/lib/python3.6/logging/__init__.py", line 998, in emit
    self.flush()
[2021-12-28 14:21:07,083] {logging_mixin.py:109} WARNING -   File "/usr/local/lib/python3.6/logging/__init__.py", line 978, in flush
    self.stream.flush()
[2021-12-28 14:21:07,101] {logging_mixin.py:109} WARNING - RuntimeError: reentrant call inside <_io.BufferedWriter name='/opt/***/logs/scraping_daft_meath/persist_data/2021-12-27T10:25:00+00:00/3.log'>
[2021-12-28 14:21:07,196] {logging_mixin.py:109} WARNING - 
During handling of the above exception, another exception occurred:
[2021-12-28 14:21:07,203] {logging_mixin.py:109} WARNING - Traceback (most recent call last):
[2021-12-28 14:21:07,265] {logging_mixin.py:109} WARNING -   File "/usr/local/lib/python3.6/logging/__init__.py", line 998, in emit
    self.flush()
[2021-12-28 14:21:07,307] {logging_mixin.py:109} WARNING -   File "/usr/local/lib/python3.6/logging/__init__.py", line 978, in flush
    self.stream.flush()
[2021-12-28 14:21:07,345] {logging_mixin.py:109} WARNING - RuntimeError: reentrant call inside <_io.BufferedWriter name='/opt/***/logs/scraping_daft_meath/persist_data/2021-12-27T10:25:00+00:00/3.log'>
[2021-12-28 14:21:07,455] {logging_mixin.py:109} WARNING - 
During handling of the above exception, another exception occurred:
[2021-12-28 14:21:07,470] {logging_mixin.py:109} WARNING - Traceback (most recent call last):
[2021-12-28 14:21:07,569] {logging_mixin.py:109} WARNING -   File "/usr/local/lib/python3.6/logging/__init__.py", line 998, in emit
    self.flush()
[2021-12-28 14:21:07,623] {logging_mixin.py:109} WARNING -   File "/usr/local/lib/python3.6/logging/__init__.py", line 978, in flush
    self.stream.flush()
[2021-12-28 14:21:07,742] {logging_mixin.py:109} WARNING - RuntimeError: reentrant call inside <_io.BufferedWriter name='/opt/***/logs/scraping_daft_meath/persist_data/2021-12-27T10:25:00+00:00/3.log'>
[2021-12-28 14:21:07,782] {logging_mixin.py:109} WARNING - 
During handling of the above exception, another exception occurred:
[2021-12-28 14:21:07,881] {logging_mixin.py:109} WARNING - Traceback (most recent call last):
[2021-12-28 14:21:07,924] {logging_mixin.py:109} WARNING -   File "/usr/local/lib/python3.6/logging/__init__.py", line 998, in emit
    self.flush()
[2021-12-28 14:21:08,076] {logging_mixin.py:109} WARNING -   File "/usr/local/lib/python3.6/logging/__init__.py", line 978, in flush
    self.stream.flush()
[2021-12-28 14:21:08,133] {logging_mixin.py:109} WARNING - RuntimeError: reentrant call inside <_io.BufferedWriter name='/opt/***/logs/scraping_daft_meath/persist_data/2021-12-27T10:25:00+00:00/3.log'>
[2021-12-28 14:21:08,390] {logging_mixin.py:109} WARNING - 
During handling of the above exception, another exception occurred:
[2021-12-28 14:21:08,423] {logging_mixin.py:109} WARNING - Traceback (most recent call last):
[2021-12-28 14:21:08,505] {logging_mixin.py:109} WARNING -   File "/usr/local/lib/python3.6/logging/__init__.py", line 998, in emit
    self.flush()
[2021-12-28 14:21:08,570] {logging_mixin.py:109} WARNING -   File "/usr/local/lib/python3.6/logging/__init__.py", line 978, in flush
    self.stream.flush()
[2021-12-28 14:21:08,603] {logging_mixin.py:109} WARNING - RuntimeError: reentrant call inside <_io.BufferedWriter name='/opt/***/logs/scraping_daft_meath/persist_data/2021-12-27T10:25:00+00:00/3.log'>
[2021-12-28 14:21:08,678] {logging_mixin.py:109} WARNING - 
During handling of the above exception, another exception occurred:
[2021-12-28 14:21:08,694] {logging_mixin.py:109} WARNING - Traceback (most recent call last):
[2021-12-28 14:21:08,712] {logging_mixin.py:109} WARNING -   File "/usr/local/lib/python3.6/logging/__init__.py", line 998, in emit
    self.flush()
[2021-12-28 14:21:08,803] {logging_mixin.py:109} WARNING -   File "/usr/local/lib/python3.6/logging/__init__.py", line 978, in flush
    self.stream.flush()
[2021-12-28 14:21:08,824] {logging_mixin.py:109} WARNING - RuntimeError: reentrant call inside <_io.BufferedWriter name='/opt/***/logs/scraping_daft_meath/persist_data/2021-12-27T10:25:00+00:00/3.log'>
[2021-12-28 14:21:08,835] {logging_mixin.py:109} WARNING - 
During handling of the above exception, another exception occurred:
[2021-12-28 14:21:08,843] {logging_mixin.py:109} WARNING - Traceback (most recent call last):
[2021-12-28 14:21:08,849] {logging_mixin.py:109} WARNING -   File "/usr/local/lib/python3.6/logging/__init__.py", line 998, in emit
    self.flush()
[2021-12-28 14:21:08,861] {logging_mixin.py:109} WARNING -   File "/usr/local/lib/python3.6/logging/__init__.py", line 978, in flush
    self.stream.flush()
[2021-12-28 14:21:08,871] {logging_mixin.py:109} WARNING - RuntimeError: reentrant call inside <_io.BufferedWriter name='/opt/***/logs/scraping_daft_meath/persist_data/2021-12-27T10:25:00+00:00/3.log'>
[2021-12-28 14:21:08,890] {logging_mixin.py:109} WARNING - 
During handling of the above exception, another exception occurred:
[2021-12-28 14:21:08,906] {logging_mixin.py:109} WARNING - Traceback (most recent call last):
[2021-12-28 14:21:08,923] {logging_mixin.py:109} WARNING -   File "/usr/local/lib/python3.6/logging/__init__.py", line 998, in emit
    self.flush()
[2021-12-28 14:21:08,961] {logging_mixin.py:109} WARNING -   File "/usr/local/lib/python3.6/logging/__init__.py", line 978, in flush
    self.stream.flush()
[2021-12-28 14:21:08,982] {logging_mixin.py:109} WARNING - RuntimeError: reentrant call inside <_io.BufferedWriter name='/opt/***/logs/scraping_daft_meath/persist_data/2021-12-27T10:25:00+00:00/3.log'>
[2021-12-28 14:21:09,232] {logging_mixin.py:109} WARNING - 
During handling of the above exception, another exception occurred:
[2021-12-28 14:21:09,313] {logging_mixin.py:109} WARNING - Traceback (most recent call last):
[2021-12-28 14:21:09,444] {logging_mixin.py:109} WARNING -   File "/usr/local/lib/python3.6/logging/__init__.py", line 998, in emit
    self.flush()
[2021-12-28 14:21:09,518] {logging_mixin.py:109} WARNING -   File "/usr/local/lib/python3.6/logging/__init__.py", line 978, in flush
    self.stream.flush()
[2021-12-28 14:21:09,653] {logging_mixin.py:109} WARNING - RuntimeError: reentrant call inside <_io.BufferedWriter name='/opt/***/logs/scraping_daft_meath/persist_data/2021-12-27T10:25:00+00:00/3.log'>
[2021-12-28 14:21:09,700] {logging_mixin.py:109} WARNING - 
During handling of the above exception, another exception occurred:
[2021-12-28 14:21:10,152] {logging_mixin.py:109} WARNING - Traceback (most recent call last):
[2021-12-28 14:21:10,163] {logging_mixin.py:109} WARNING -   File "/usr/local/lib/python3.6/logging/__init__.py", line 998, in emit
    self.flush()
[2021-12-28 14:21:10,340] {logging_mixin.py:109} WARNING -   File "/usr/local/lib/python3.6/logging/__init__.py", line 978, in flush
    self.stream.flush()
[2021-12-28 14:21:10,413] {logging_mixin.py:109} WARNING - RuntimeError: reentrant call inside <_io.BufferedWriter name='/opt/***/logs/scraping_daft_meath/persist_data/2021-12-27T10:25:00+00:00/3.log'>
[2021-12-28 14:21:10,614] {logging_mixin.py:109} WARNING - 
During handling of the above exception, another exception occurred:
[2021-12-28 14:21:10,655] {logging_mixin.py:109} WARNING - Traceback (most recent call last):
[2021-12-28 14:21:10,731] {logging_mixin.py:109} WARNING -   File "/usr/local/lib/python3.6/logging/__init__.py", line 998, in emit
    self.flush()
[2021-12-28 14:21:10,774] {logging_mixin.py:109} WARNING -   File "/usr/local/lib/python3.6/logging/__init__.py", line 978, in flush
    self.stream.flush()
[2021-12-28 14:21:10,867] {logging_mixin.py:109} WARNING - RuntimeError: reentrant call inside <_io.BufferedWriter name='/opt/***/logs/scraping_daft_meath/persist_data/2021-12-27T10:25:00+00:00/3.log'>
[2021-12-28 14:21:10,885] {logging_mixin.py:109} WARNING - 
During handling of the above exception, another exception occurred:
[2021-12-28 14:21:10,902] {logging_mixin.py:109} WARNING - Traceback (most recent call last):
[2021-12-28 14:21:10,918] {logging_mixin.py:109} WARNING -   File "/usr/local/lib/python3.6/logging/__init__.py", line 998, in emit
    self.flush()
[2021-12-28 14:21:11,046] {logging_mixin.py:109} WARNING -   File "/usr/local/lib/python3.6/logging/__init__.py", line 978, in flush
    self.stream.flush()
[2021-12-28 14:21:11,128] {logging_mixin.py:109} WARNING - RuntimeError: reentrant call inside <_io.BufferedWriter name='/opt/***/logs/scraping_daft_meath/persist_data/2021-12-27T10:25:00+00:00/3.log'>
[2021-12-28 14:21:11,205] {logging_mixin.py:109} WARNING - 
During handling of the above exception, another exception occurred:
[2021-12-28 14:21:11,405] {logging_mixin.py:109} WARNING - Traceback (most recent call last):
[2021-12-28 14:21:11,509] {logging_mixin.py:109} WARNING -   File "/usr/local/lib/python3.6/logging/__init__.py", line 998, in emit
    self.flush()
[2021-12-28 14:21:11,521] {logging_mixin.py:109} WARNING -   File "/usr/local/lib/python3.6/logging/__init__.py", line 978, in flush
    self.stream.flush()
[2021-12-28 14:21:11,543] {logging_mixin.py:109} WARNING - RuntimeError: reentrant call inside <_io.BufferedWriter name='/opt/***/logs/scraping_daft_meath/persist_data/2021-12-27T10:25:00+00:00/3.log'>
[2021-12-28 14:21:11,754] {logging_mixin.py:109} WARNING - 
During handling of the above exception, another exception occurred:
[2021-12-28 14:21:11,788] {logging_mixin.py:109} WARNING - Traceback (most recent call last):
[2021-12-28 14:21:12,008] {logging_mixin.py:109} WARNING -   File "/usr/local/lib/python3.6/logging/__init__.py", line 998, in emit
    self.flush()
[2021-12-28 14:21:12,024] {logging_mixin.py:109} WARNING -   File "/usr/local/lib/python3.6/logging/__init__.py", line 978, in flush
    self.stream.flush()
[2021-12-28 14:21:12,045] {logging_mixin.py:109} WARNING - RuntimeError: reentrant call inside <_io.BufferedWriter name='/opt/***/logs/scraping_daft_meath/persist_data/2021-12-27T10:25:00+00:00/3.log'>
[2021-12-28 14:21:12,055] {logging_mixin.py:109} WARNING - 
During handling of the above exception, another exception occurred:
[2021-12-28 14:21:12,070] {logging_mixin.py:109} WARNING - Traceback (most recent call last):
[2021-12-28 14:21:12,078] {logging_mixin.py:109} WARNING -   File "/usr/local/lib/python3.6/logging/__init__.py", line 998, in emit
    self.flush()
[2021-12-28 14:21:12,174] {logging_mixin.py:109} WARNING -   File "/usr/local/lib/python3.6/logging/__init__.py", line 978, in flush
    self.stream.flush()
[2021-12-28 14:21:12,217] {logging_mixin.py:109} WARNING - RuntimeError: reentrant call inside <_io.BufferedWriter name='/opt/***/logs/scraping_daft_meath/persist_data/2021-12-27T10:25:00+00:00/3.log'>
[2021-12-28 14:21:12,242] {logging_mixin.py:109} WARNING - 
During handling of the above exception, another exception occurred:
[2021-12-28 14:21:12,259] {logging_mixin.py:109} WARNING - Traceback (most recent call last):
[2021-12-28 14:21:12,303] {logging_mixin.py:109} WARNING -   File "/usr/local/lib/python3.6/logging/__init__.py", line 998, in emit
    self.flush()
[2021-12-28 14:21:12,311] {logging_mixin.py:109} WARNING -   File "/usr/local/lib/python3.6/logging/__init__.py", line 978, in flush
    self.stream.flush()
[2021-12-28 14:21:12,317] {logging_mixin.py:109} WARNING - RuntimeError: reentrant call inside <_io.BufferedWriter name='/opt/***/logs/scraping_daft_meath/persist_data/2021-12-27T10:25:00+00:00/3.log'>
[2021-12-28 14:21:12,385] {logging_mixin.py:109} WARNING - 
During handling of the above exception, another exception occurred:
[2021-12-28 14:21:12,403] {logging_mixin.py:109} WARNING - Traceback (most recent call last):
[2021-12-28 14:21:12,478] {logging_mixin.py:109} WARNING -   File "/usr/local/lib/python3.6/logging/__init__.py", line 998, in emit
    self.flush()
[2021-12-28 14:21:12,564] {logging_mixin.py:109} WARNING -   File "/usr/local/lib/python3.6/logging/__init__.py", line 978, in flush
    self.stream.flush()
[2021-12-28 14:21:12,605] {logging_mixin.py:109} WARNING - RuntimeError: reentrant call inside <_io.BufferedWriter name='/opt/***/logs/scraping_daft_meath/persist_data/2021-12-27T10:25:00+00:00/3.log'>
[2021-12-28 14:21:12,751] {logging_mixin.py:109} WARNING - 
During handling of the above exception, another exception occurred:
[2021-12-28 14:21:12,858] {logging_mixin.py:109} WARNING - Traceback (most recent call last):
[2021-12-28 14:21:12,948] {logging_mixin.py:109} WARNING -   File "/usr/local/lib/python3.6/logging/__init__.py", line 998, in emit
    self.flush()
[2021-12-28 14:21:12,987] {logging_mixin.py:109} WARNING -   File "/usr/local/lib/python3.6/logging/__init__.py", line 978, in flush
    self.stream.flush()
[2021-12-28 14:21:12,998] {logging_mixin.py:109} WARNING - RuntimeError: reentrant call inside <_io.BufferedWriter name='/opt/***/logs/scraping_daft_meath/persist_data/2021-12-27T10:25:00+00:00/3.log'>
[2021-12-28 14:21:13,027] {logging_mixin.py:109} WARNING - 
During handling of the above exception, another exception occurred:
[2021-12-28 14:21:13,067] {logging_mixin.py:109} WARNING - Traceback (most recent call last):
[2021-12-28 14:21:13,102] {logging_mixin.py:109} WARNING -   File "/usr/local/lib/python3.6/logging/__init__.py", line 998, in emit
    self.flush()
[2021-12-28 14:21:13,166] {logging_mixin.py:109} WARNING -   File "/usr/local/lib/python3.6/logging/__init__.py", line 978, in flush
    self.stream.flush()
[2021-12-28 14:21:13,212] {logging_mixin.py:109} WARNING - RuntimeError: reentrant call inside <_io.BufferedWriter name='/opt/***/logs/scraping_daft_meath/persist_data/2021-12-27T10:25:00+00:00/3.log'>
[2021-12-28 14:21:13,224] {logging_mixin.py:109} WARNING - 
During handling of the above exception, another exception occurred:
[2021-12-28 14:21:13,240] {logging_mixin.py:109} WARNING - Traceback (most recent call last):
[2021-12-28 14:21:13,473] {logging_mixin.py:109} WARNING -   File "/usr/local/lib/python3.6/logging/__init__.py", line 998, in emit
    self.flush()
[2021-12-28 14:21:13,690] {logging_mixin.py:109} WARNING -   File "/usr/local/lib/python3.6/logging/__init__.py", line 978, in flush
    self.stream.flush()
[2021-12-28 14:21:13,700] {logging_mixin.py:109} WARNING - RuntimeError: reentrant call inside <_io.BufferedWriter name='/opt/***/logs/scraping_daft_meath/persist_data/2021-12-27T10:25:00+00:00/3.log'>
[2021-12-28 14:21:13,709] {logging_mixin.py:109} WARNING - 
During handling of the above exception, another exception occurred:
[2021-12-28 14:21:13,721] {logging_mixin.py:109} WARNING - Traceback (most recent call last):
[2021-12-28 14:21:13,729] {logging_mixin.py:109} WARNING -   File "/usr/local/lib/python3.6/logging/__init__.py", line 998, in emit
    self.flush()
[2021-12-28 14:21:13,739] {logging_mixin.py:109} WARNING -   File "/usr/local/lib/python3.6/logging/__init__.py", line 978, in flush
    self.stream.flush()
[2021-12-28 14:21:13,752] {logging_mixin.py:109} WARNING - RuntimeError: reentrant call inside <_io.BufferedWriter name='/opt/***/logs/scraping_daft_meath/persist_data/2021-12-27T10:25:00+00:00/3.log'>
[2021-12-28 14:21:13,769] {logging_mixin.py:109} WARNING - 
During handling of the above exception, another exception occurred:
[2021-12-28 14:21:13,784] {logging_mixin.py:109} WARNING - Traceback (most recent call last):
[2021-12-28 14:21:13,800] {logging_mixin.py:109} WARNING -   File "/usr/local/lib/python3.6/logging/__init__.py", line 998, in emit
    self.flush()
[2021-12-28 14:21:13,816] {logging_mixin.py:109} WARNING -   File "/usr/local/lib/python3.6/logging/__init__.py", line 978, in flush
    self.stream.flush()
[2021-12-28 14:21:13,828] {logging_mixin.py:109} WARNING - RuntimeError: reentrant call inside <_io.BufferedWriter name='/opt/***/logs/scraping_daft_meath/persist_data/2021-12-27T10:25:00+00:00/3.log'>
[2021-12-28 14:21:13,837] {logging_mixin.py:109} WARNING - 
During handling of the above exception, another exception occurred:
[2021-12-28 14:21:13,846] {logging_mixin.py:109} WARNING - Traceback (most recent call last):
[2021-12-28 14:21:13,896] {logging_mixin.py:109} WARNING -   File "/usr/local/lib/python3.6/logging/__init__.py", line 998, in emit
    self.flush()
[2021-12-28 14:21:13,930] {logging_mixin.py:109} WARNING -   File "/usr/local/lib/python3.6/logging/__init__.py", line 978, in flush
    self.stream.flush()
[2021-12-28 14:21:13,950] {logging_mixin.py:109} WARNING - RuntimeError: reentrant call inside <_io.BufferedWriter name='/opt/***/logs/scraping_daft_meath/persist_data/2021-12-27T10:25:00+00:00/3.log'>
[2021-12-28 14:21:13,962] {logging_mixin.py:109} WARNING - 
During handling of the above exception, another exception occurred:
[2021-12-28 14:21:13,971] {logging_mixin.py:109} WARNING - Traceback (most recent call last):
[2021-12-28 14:21:14,002] {logging_mixin.py:109} WARNING -   File "/usr/local/lib/python3.6/logging/__init__.py", line 998, in emit
    self.flush()
[2021-12-28 14:21:14,035] {logging_mixin.py:109} WARNING -   File "/usr/local/lib/python3.6/logging/__init__.py", line 978, in flush
    self.stream.flush()
[2021-12-28 14:21:14,089] {logging_mixin.py:109} WARNING - RuntimeError: reentrant call inside <_io.BufferedWriter name='/opt/***/logs/scraping_daft_meath/persist_data/2021-12-27T10:25:00+00:00/3.log'>
[2021-12-28 14:21:14,247] {logging_mixin.py:109} WARNING - 
During handling of the above exception, another exception occurred:
[2021-12-28 14:21:14,344] {logging_mixin.py:109} WARNING - Traceback (most recent call last):
[2021-12-28 14:21:14,456] {logging_mixin.py:109} WARNING -   File "/usr/local/lib/python3.6/logging/__init__.py", line 998, in emit
    self.flush()
[2021-12-28 14:21:14,503] {logging_mixin.py:109} WARNING -   File "/usr/local/lib/python3.6/logging/__init__.py", line 978, in flush
    self.stream.flush()
[2021-12-28 14:21:14,520] {logging_mixin.py:109} WARNING - RuntimeError: reentrant call inside <_io.BufferedWriter name='/opt/***/logs/scraping_daft_meath/persist_data/2021-12-27T10:25:00+00:00/3.log'>
[2021-12-28 14:21:14,557] {logging_mixin.py:109} WARNING - 
During handling of the above exception, another exception occurred:
[2021-12-28 14:21:14,579] {logging_mixin.py:109} WARNING - Traceback (most recent call last):
[2021-12-28 14:21:14,602] {logging_mixin.py:109} WARNING -   File "/usr/local/lib/python3.6/logging/__init__.py", line 998, in emit
    self.flush()
[2021-12-28 14:21:14,615] {logging_mixin.py:109} WARNING -   File "/usr/local/lib/python3.6/logging/__init__.py", line 978, in flush
    self.stream.flush()
[2021-12-28 14:21:14,624] {logging_mixin.py:109} WARNING - RuntimeError: reentrant call inside <_io.BufferedWriter name='/opt/***/logs/scraping_daft_meath/persist_data/2021-12-27T10:25:00+00:00/3.log'>
[2021-12-28 14:21:14,638] {logging_mixin.py:109} WARNING - 
During handling of the above exception, another exception occurred:
[2021-12-28 14:21:14,650] {logging_mixin.py:109} WARNING - Traceback (most recent call last):
[2021-12-28 14:21:14,657] {logging_mixin.py:109} WARNING -   File "/usr/local/lib/python3.6/logging/__init__.py", line 998, in emit
    self.flush()
[2021-12-28 14:21:14,672] {logging_mixin.py:109} WARNING -   File "/usr/local/lib/python3.6/logging/__init__.py", line 978, in flush
    self.stream.flush()
[2021-12-28 14:21:14,706] {logging_mixin.py:109} WARNING - RuntimeError: reentrant call inside <_io.BufferedWriter name='/opt/***/logs/scraping_daft_meath/persist_data/2021-12-27T10:25:00+00:00/3.log'>
[2021-12-28 14:21:14,735] {logging_mixin.py:109} WARNING - 
During handling of the above exception, another exception occurred:
[2021-12-28 14:21:14,741] {logging_mixin.py:109} WARNING - Traceback (most recent call last):
[2021-12-28 14:21:14,747] {logging_mixin.py:109} WARNING -   File "/usr/local/lib/python3.6/logging/__init__.py", line 998, in emit
    self.flush()
[2021-12-28 14:21:14,753] {logging_mixin.py:109} WARNING -   File "/usr/local/lib/python3.6/logging/__init__.py", line 978, in flush
    self.stream.flush()
[2021-12-28 14:21:14,760] {logging_mixin.py:109} WARNING - RuntimeError: reentrant call inside <_io.BufferedWriter name='/opt/***/logs/scraping_daft_meath/persist_data/2021-12-27T10:25:00+00:00/3.log'>
[2021-12-28 14:21:14,763] {logging_mixin.py:109} WARNING - 
During handling of the above exception, another exception occurred:
[2021-12-28 14:21:14,767] {logging_mixin.py:109} WARNING - Traceback (most recent call last):
[2021-12-28 14:21:14,786] {logging_mixin.py:109} WARNING -   File "/usr/local/lib/python3.6/logging/__init__.py", line 998, in emit
    self.flush()
[2021-12-28 14:21:14,793] {logging_mixin.py:109} WARNING -   File "/usr/local/lib/python3.6/logging/__init__.py", line 978, in flush
    self.stream.flush()
[2021-12-28 14:21:14,798] {logging_mixin.py:109} WARNING - RuntimeError: reentrant call inside <_io.BufferedWriter name='/opt/***/logs/scraping_daft_meath/persist_data/2021-12-27T10:25:00+00:00/3.log'>
[2021-12-28 14:21:14,805] {logging_mixin.py:109} WARNING - 
During handling of the above exception, another exception occurred:
[2021-12-28 14:21:14,815] {logging_mixin.py:109} WARNING - Traceback (most recent call last):
[2021-12-28 14:21:14,830] {logging_mixin.py:109} WARNING -   File "/usr/local/lib/python3.6/logging/__init__.py", line 998, in emit
    self.flush()
[2021-12-28 14:21:14,847] {logging_mixin.py:109} WARNING -   File "/usr/local/lib/python3.6/logging/__init__.py", line 978, in flush
    self.stream.flush()
[2021-12-28 14:21:14,863] {logging_mixin.py:109} WARNING - RuntimeError: reentrant call inside <_io.BufferedWriter name='/opt/***/logs/scraping_daft_meath/persist_data/2021-12-27T10:25:00+00:00/3.log'>
[2021-12-28 14:21:14,902] {logging_mixin.py:109} WARNING - 
During handling of the above exception, another exception occurred:
[2021-12-28 14:21:14,918] {logging_mixin.py:109} WARNING - Traceback (most recent call last):
[2021-12-28 14:21:14,933] {logging_mixin.py:109} WARNING -   File "/usr/local/lib/python3.6/logging/__init__.py", line 998, in emit
    self.flush()
[2021-12-28 14:21:14,944] {logging_mixin.py:109} WARNING -   File "/usr/local/lib/python3.6/logging/__init__.py", line 978, in flush
    self.stream.flush()
[2021-12-28 14:21:14,976] {logging_mixin.py:109} WARNING - RuntimeError: reentrant call inside <_io.BufferedWriter name='/opt/***/logs/scraping_daft_meath/persist_data/2021-12-27T10:25:00+00:00/3.log'>
[2021-12-28 14:21:14,993] {logging_mixin.py:109} WARNING - 
During handling of the above exception, another exception occurred:
[2021-12-28 14:21:15,015] {logging_mixin.py:109} WARNING - Traceback (most recent call last):
[2021-12-28 14:21:15,046] {logging_mixin.py:109} WARNING -   File "/usr/local/lib/python3.6/logging/__init__.py", line 998, in emit
    self.flush()
[2021-12-28 14:21:15,053] {logging_mixin.py:109} WARNING -   File "/usr/local/lib/python3.6/logging/__init__.py", line 978, in flush
    self.stream.flush()
[2021-12-28 14:21:15,066] {logging_mixin.py:109} WARNING - RuntimeError: reentrant call inside <_io.BufferedWriter name='/opt/***/logs/scraping_daft_meath/persist_data/2021-12-27T10:25:00+00:00/3.log'>
[2021-12-28 14:21:15,144] {logging_mixin.py:109} WARNING - 
During handling of the above exception, another exception occurred:
[2021-12-28 14:21:15,171] {logging_mixin.py:109} WARNING - Traceback (most recent call last):
[2021-12-28 14:21:15,192] {logging_mixin.py:109} WARNING -   File "/usr/local/lib/python3.6/logging/__init__.py", line 998, in emit
    self.flush()
[2021-12-28 14:21:15,232] {logging_mixin.py:109} WARNING -   File "/usr/local/lib/python3.6/logging/__init__.py", line 978, in flush
    self.stream.flush()
[2021-12-28 14:21:15,255] {logging_mixin.py:109} WARNING - RuntimeError: reentrant call inside <_io.BufferedWriter name='/opt/***/logs/scraping_daft_meath/persist_data/2021-12-27T10:25:00+00:00/3.log'>
[2021-12-28 14:21:15,279] {logging_mixin.py:109} WARNING - 
During handling of the above exception, another exception occurred:
[2021-12-28 14:21:15,292] {logging_mixin.py:109} WARNING - Traceback (most recent call last):
[2021-12-28 14:21:15,373] {logging_mixin.py:109} WARNING -   File "/usr/local/lib/python3.6/logging/__init__.py", line 998, in emit
    self.flush()
[2021-12-28 14:21:15,449] {logging_mixin.py:109} WARNING -   File "/usr/local/lib/python3.6/logging/__init__.py", line 978, in flush
    self.stream.flush()
[2021-12-28 14:21:15,522] {logging_mixin.py:109} WARNING - RuntimeError: reentrant call inside <_io.BufferedWriter name='/opt/***/logs/scraping_daft_meath/persist_data/2021-12-27T10:25:00+00:00/3.log'>
[2021-12-28 14:21:15,585] {logging_mixin.py:109} WARNING - 
During handling of the above exception, another exception occurred:
[2021-12-28 14:21:15,675] {logging_mixin.py:109} WARNING - Traceback (most recent call last):
[2021-12-28 14:21:16,131] {logging_mixin.py:109} WARNING -   File "/usr/local/lib/python3.6/logging/__init__.py", line 998, in emit
    self.flush()
[2021-12-28 14:21:16,177] {logging_mixin.py:109} WARNING -   File "/usr/local/lib/python3.6/logging/__init__.py", line 978, in flush
    self.stream.flush()
[2021-12-28 14:21:16,215] {logging_mixin.py:109} WARNING -   File "/home/***/.local/lib/python3.6/site-packages/***/models/taskinstance.py", line 1411, in signal_handler
    self.log.error("Received SIGTERM. Terminating subprocesses.")
[2021-12-28 14:21:16,253] {logging_mixin.py:109} WARNING -   File "/usr/local/lib/python3.6/logging/__init__.py", line 1337, in error
    self._log(ERROR, msg, args, **kwargs)
[2021-12-28 14:21:16,515] {logging_mixin.py:109} WARNING -   File "/usr/local/lib/python3.6/logging/__init__.py", line 1444, in _log
    self.handle(record)
[2021-12-28 14:21:16,535] {logging_mixin.py:109} WARNING -   File "/usr/local/lib/python3.6/logging/__init__.py", line 1454, in handle
    self.callHandlers(record)
[2021-12-28 14:21:16,576] {logging_mixin.py:109} WARNING -   File "/usr/local/lib/python3.6/logging/__init__.py", line 1516, in callHandlers
    hdlr.handle(record)
[2021-12-28 14:21:16,666] {logging_mixin.py:109} WARNING -   File "/usr/local/lib/python3.6/logging/__init__.py", line 865, in handle
    self.emit(record)
[2021-12-28 14:21:16,752] {logging_mixin.py:109} WARNING -   File "/home/***/.local/lib/python3.6/site-packages/***/utils/log/file_task_handler.py", line 66, in emit
    self.handler.emit(record)
[2021-12-28 14:21:16,784] {logging_mixin.py:109} WARNING -   File "/usr/local/lib/python3.6/logging/__init__.py", line 1072, in emit
    StreamHandler.emit(self, record)
[2021-12-28 14:21:16,831] {logging_mixin.py:109} WARNING -   File "/usr/local/lib/python3.6/logging/__init__.py", line 1000, in emit
    self.handleError(record)
[2021-12-28 14:21:16,897] {logging_mixin.py:109} WARNING -   File "/usr/local/lib/python3.6/logging/__init__.py", line 917, in handleError
    sys.stderr.write('--- Logging error ---\n')
[2021-12-28 14:21:16,961] {logging_mixin.py:109} WARNING -   File "/home/***/.local/lib/python3.6/site-packages/***/utils/log/logging_mixin.py", line 121, in write
    self._propagate_log(self._buffer.rstrip())
[2021-12-28 14:21:17,019] {logging_mixin.py:109} WARNING -   File "/home/***/.local/lib/python3.6/site-packages/***/utils/log/logging_mixin.py", line 109, in _propagate_log
    self.logger.log(self.level, remove_escape_codes(message))
[2021-12-28 14:21:17,049] {logging_mixin.py:109} WARNING -   File "/usr/local/lib/python3.6/logging/__init__.py", line 1374, in log
    self._log(level, msg, args, **kwargs)
[2021-12-28 14:21:17,068] {logging_mixin.py:109} WARNING -   File "/usr/local/lib/python3.6/logging/__init__.py", line 1444, in _log
    self.handle(record)
[2021-12-28 14:21:17,115] {logging_mixin.py:109} WARNING -   File "/usr/local/lib/python3.6/logging/__init__.py", line 1454, in handle
    self.callHandlers(record)
[2021-12-28 14:21:17,207] {logging_mixin.py:109} WARNING -   File "/usr/local/lib/python3.6/logging/__init__.py", line 1516, in callHandlers
    hdlr.handle(record)
[2021-12-28 14:21:17,217] {logging_mixin.py:109} WARNING -   File "/usr/local/lib/python3.6/logging/__init__.py", line 865, in handle
    self.emit(record)
[2021-12-28 14:21:17,230] {logging_mixin.py:109} WARNING -   File "/home/***/.local/lib/python3.6/site-packages/***/utils/log/file_task_handler.py", line 66, in emit
    self.handler.emit(record)
[2021-12-28 14:21:17,392] {logging_mixin.py:109} WARNING -   File "/usr/local/lib/python3.6/logging/__init__.py", line 1072, in emit
    StreamHandler.emit(self, record)
[2021-12-28 14:21:17,453] {logging_mixin.py:109} WARNING -   File "/usr/local/lib/python3.6/logging/__init__.py", line 1000, in emit
    self.handleError(record)
[2021-12-28 14:21:17,483] {logging_mixin.py:109} WARNING -   File "/usr/local/lib/python3.6/logging/__init__.py", line 917, in handleError
    sys.stderr.write('--- Logging error ---\n')
[2021-12-28 14:21:17,540] {logging_mixin.py:109} WARNING -   File "/home/***/.local/lib/python3.6/site-packages/***/utils/log/logging_mixin.py", line 121, in write
    self._propagate_log(self._buffer.rstrip())
[2021-12-28 14:21:17,597] {logging_mixin.py:109} WARNING -   File "/home/***/.local/lib/python3.6/site-packages/***/utils/log/logging_mixin.py", line 109, in _propagate_log
    self.logger.log(self.level, remove_escape_codes(message))
[2021-12-28 14:21:17,767] {logging_mixin.py:109} WARNING -   File "/usr/local/lib/python3.6/logging/__init__.py", line 1374, in log
    self._log(level, msg, args, **kwargs)
[2021-12-28 14:21:17,818] {logging_mixin.py:109} WARNING -   File "/usr/local/lib/python3.6/logging/__init__.py", line 1444, in _log
    self.handle(record)
[2021-12-28 14:21:17,883] {logging_mixin.py:109} WARNING -   File "/usr/local/lib/python3.6/logging/__init__.py", line 1454, in handle
    self.callHandlers(record)
[2021-12-28 14:21:17,901] {logging_mixin.py:109} WARNING -   File "/usr/local/lib/python3.6/logging/__init__.py", line 1516, in callHandlers
    hdlr.handle(record)
[2021-12-28 14:21:17,926] {logging_mixin.py:109} WARNING -   File "/usr/local/lib/python3.6/logging/__init__.py", line 865, in handle
    self.emit(record)
[2021-12-28 14:21:17,942] {logging_mixin.py:109} WARNING -   File "/home/***/.local/lib/python3.6/site-packages/***/utils/log/file_task_handler.py", line 66, in emit
    self.handler.emit(record)
[2021-12-28 14:21:17,964] {logging_mixin.py:109} WARNING -   File "/usr/local/lib/python3.6/logging/__init__.py", line 1072, in emit
    StreamHandler.emit(self, record)
[2021-12-28 14:21:17,986] {logging_mixin.py:109} WARNING -   File "/usr/local/lib/python3.6/logging/__init__.py", line 1000, in emit
    self.handleError(record)
[2021-12-28 14:21:18,011] {logging_mixin.py:109} WARNING -   File "/usr/local/lib/python3.6/logging/__init__.py", line 917, in handleError
    sys.stderr.write('--- Logging error ---\n')
[2021-12-28 14:21:18,089] {logging_mixin.py:109} WARNING -   File "/home/***/.local/lib/python3.6/site-packages/***/utils/log/logging_mixin.py", line 121, in write
    self._propagate_log(self._buffer.rstrip())
[2021-12-28 14:21:18,143] {logging_mixin.py:109} WARNING -   File "/home/***/.local/lib/python3.6/site-packages/***/utils/log/logging_mixin.py", line 109, in _propagate_log
    self.logger.log(self.level, remove_escape_codes(message))
[2021-12-28 14:21:18,173] {logging_mixin.py:109} WARNING -   File "/usr/local/lib/python3.6/logging/__init__.py", line 1374, in log
    self._log(level, msg, args, **kwargs)
[2021-12-28 14:21:18,243] {logging_mixin.py:109} WARNING -   File "/usr/local/lib/python3.6/logging/__init__.py", line 1444, in _log
    self.handle(record)
[2021-12-28 14:21:18,316] {logging_mixin.py:109} WARNING -   File "/usr/local/lib/python3.6/logging/__init__.py", line 1454, in handle
    self.callHandlers(record)
[2021-12-28 14:21:18,360] {logging_mixin.py:109} WARNING -   File "/usr/local/lib/python3.6/logging/__init__.py", line 1516, in callHandlers
    hdlr.handle(record)
[2021-12-28 14:21:18,384] {logging_mixin.py:109} WARNING -   File "/usr/local/lib/python3.6/logging/__init__.py", line 865, in handle
    self.emit(record)
[2021-12-28 14:21:18,420] {logging_mixin.py:109} WARNING -   File "/home/***/.local/lib/python3.6/site-packages/***/utils/log/file_task_handler.py", line 66, in emit
    self.handler.emit(record)
[2021-12-28 14:21:18,470] {logging_mixin.py:109} WARNING -   File "/usr/local/lib/python3.6/logging/__init__.py", line 1072, in emit
    StreamHandler.emit(self, record)
[2021-12-28 14:21:18,480] {logging_mixin.py:109} WARNING -   File "/usr/local/lib/python3.6/logging/__init__.py", line 1000, in emit
    self.handleError(record)
[2021-12-28 14:21:18,499] {logging_mixin.py:109} WARNING -   File "/usr/local/lib/python3.6/logging/__init__.py", line 917, in handleError
    sys.stderr.write('--- Logging error ---\n')
[2021-12-28 14:21:18,615] {logging_mixin.py:109} WARNING -   File "/home/***/.local/lib/python3.6/site-packages/***/utils/log/logging_mixin.py", line 121, in write
    self._propagate_log(self._buffer.rstrip())
[2021-12-28 14:21:18,632] {logging_mixin.py:109} WARNING -   File "/home/***/.local/lib/python3.6/site-packages/***/utils/log/logging_mixin.py", line 109, in _propagate_log
    self.logger.log(self.level, remove_escape_codes(message))
[2021-12-28 14:21:18,743] {logging_mixin.py:109} WARNING -   File "/usr/local/lib/python3.6/logging/__init__.py", line 1374, in log
    self._log(level, msg, args, **kwargs)
[2021-12-28 14:21:18,774] {logging_mixin.py:109} WARNING -   File "/usr/local/lib/python3.6/logging/__init__.py", line 1444, in _log
    self.handle(record)
[2021-12-28 14:21:18,867] {logging_mixin.py:109} WARNING -   File "/usr/local/lib/python3.6/logging/__init__.py", line 1454, in handle
    self.callHandlers(record)
[2021-12-28 14:21:18,881] {logging_mixin.py:109} WARNING -   File "/usr/local/lib/python3.6/logging/__init__.py", line 1516, in callHandlers
    hdlr.handle(record)
[2021-12-28 14:21:18,928] {logging_mixin.py:109} WARNING -   File "/usr/local/lib/python3.6/logging/__init__.py", line 865, in handle
    self.emit(record)
[2021-12-28 14:21:18,948] {logging_mixin.py:109} WARNING -   File "/home/***/.local/lib/python3.6/site-packages/***/utils/log/file_task_handler.py", line 66, in emit
    self.handler.emit(record)
[2021-12-28 14:21:19,031] {logging_mixin.py:109} WARNING -   File "/usr/local/lib/python3.6/logging/__init__.py", line 1072, in emit
    StreamHandler.emit(self, record)
[2021-12-28 14:21:19,045] {logging_mixin.py:109} WARNING -   File "/usr/local/lib/python3.6/logging/__init__.py", line 1000, in emit
    self.handleError(record)
[2021-12-28 14:21:19,059] {logging_mixin.py:109} WARNING -   File "/usr/local/lib/python3.6/logging/__init__.py", line 917, in handleError
    sys.stderr.write('--- Logging error ---\n')
[2021-12-28 14:21:19,094] {logging_mixin.py:109} WARNING -   File "/home/***/.local/lib/python3.6/site-packages/***/utils/log/logging_mixin.py", line 121, in write
    self._propagate_log(self._buffer.rstrip())
[2021-12-28 14:21:19,394] {logging_mixin.py:109} WARNING -   File "/home/***/.local/lib/python3.6/site-packages/***/utils/log/logging_mixin.py", line 109, in _propagate_log
    self.logger.log(self.level, remove_escape_codes(message))
[2021-12-28 14:21:19,479] {logging_mixin.py:109} WARNING -   File "/usr/local/lib/python3.6/logging/__init__.py", line 1374, in log
    self._log(level, msg, args, **kwargs)
[2021-12-28 14:21:19,815] {logging_mixin.py:109} WARNING -   File "/usr/local/lib/python3.6/logging/__init__.py", line 1444, in _log
    self.handle(record)
[2021-12-28 14:21:20,236] {logging_mixin.py:109} WARNING -   File "/usr/local/lib/python3.6/logging/__init__.py", line 1454, in handle
    self.callHandlers(record)
[2021-12-28 14:21:20,278] {logging_mixin.py:109} WARNING -   File "/usr/local/lib/python3.6/logging/__init__.py", line 1516, in callHandlers
    hdlr.handle(record)
[2021-12-28 14:21:20,295] {logging_mixin.py:109} WARNING -   File "/usr/local/lib/python3.6/logging/__init__.py", line 865, in handle
    self.emit(record)
[2021-12-28 14:21:20,406] {logging_mixin.py:109} WARNING -   File "/home/***/.local/lib/python3.6/site-packages/***/utils/log/file_task_handler.py", line 66, in emit
    self.handler.emit(record)
[2021-12-28 14:21:20,412] {logging_mixin.py:109} WARNING -   File "/usr/local/lib/python3.6/logging/__init__.py", line 1072, in emit
    StreamHandler.emit(self, record)
[2021-12-28 14:21:20,419] {logging_mixin.py:109} WARNING -   File "/usr/local/lib/python3.6/logging/__init__.py", line 1000, in emit
    self.handleError(record)
[2021-12-28 14:21:20,424] {logging_mixin.py:109} WARNING -   File "/usr/local/lib/python3.6/logging/__init__.py", line 917, in handleError
    sys.stderr.write('--- Logging error ---\n')
[2021-12-28 14:21:20,454] {logging_mixin.py:109} WARNING -   File "/home/***/.local/lib/python3.6/site-packages/***/utils/log/logging_mixin.py", line 121, in write
    self._propagate_log(self._buffer.rstrip())
[2021-12-28 14:21:20,464] {logging_mixin.py:109} WARNING -   File "/home/***/.local/lib/python3.6/site-packages/***/utils/log/logging_mixin.py", line 109, in _propagate_log
    self.logger.log(self.level, remove_escape_codes(message))
[2021-12-28 14:21:20,471] {logging_mixin.py:109} WARNING -   File "/usr/local/lib/python3.6/logging/__init__.py", line 1374, in log
    self._log(level, msg, args, **kwargs)
[2021-12-28 14:21:20,478] {logging_mixin.py:109} WARNING -   File "/usr/local/lib/python3.6/logging/__init__.py", line 1444, in _log
    self.handle(record)
[2021-12-28 14:21:20,487] {logging_mixin.py:109} WARNING -   File "/usr/local/lib/python3.6/logging/__init__.py", line 1454, in handle
    self.callHandlers(record)
[2021-12-28 14:21:20,511] {logging_mixin.py:109} WARNING -   File "/usr/local/lib/python3.6/logging/__init__.py", line 1516, in callHandlers
    hdlr.handle(record)
[2021-12-28 14:21:20,523] {logging_mixin.py:109} WARNING -   File "/usr/local/lib/python3.6/logging/__init__.py", line 865, in handle
    self.emit(record)
[2021-12-28 14:21:20,538] {logging_mixin.py:109} WARNING -   File "/home/***/.local/lib/python3.6/site-packages/***/utils/log/file_task_handler.py", line 66, in emit
    self.handler.emit(record)
[2021-12-28 14:21:20,549] {logging_mixin.py:109} WARNING -   File "/usr/local/lib/python3.6/logging/__init__.py", line 1072, in emit
    StreamHandler.emit(self, record)
[2021-12-28 14:21:20,595] {logging_mixin.py:109} WARNING -   File "/usr/local/lib/python3.6/logging/__init__.py", line 1000, in emit
    self.handleError(record)
[2021-12-28 14:21:20,612] {logging_mixin.py:109} WARNING -   File "/usr/local/lib/python3.6/logging/__init__.py", line 917, in handleError
    sys.stderr.write('--- Logging error ---\n')
[2021-12-28 14:21:20,622] {logging_mixin.py:109} WARNING -   File "/home/***/.local/lib/python3.6/site-packages/***/utils/log/logging_mixin.py", line 121, in write
    self._propagate_log(self._buffer.rstrip())
[2021-12-28 14:21:20,629] {logging_mixin.py:109} WARNING -   File "/home/***/.local/lib/python3.6/site-packages/***/utils/log/logging_mixin.py", line 109, in _propagate_log
    self.logger.log(self.level, remove_escape_codes(message))
[2021-12-28 14:21:20,647] {logging_mixin.py:109} WARNING -   File "/usr/local/lib/python3.6/logging/__init__.py", line 1374, in log
    self._log(level, msg, args, **kwargs)
[2021-12-28 14:21:20,656] {logging_mixin.py:109} WARNING -   File "/usr/local/lib/python3.6/logging/__init__.py", line 1444, in _log
    self.handle(record)
[2021-12-28 14:21:20,662] {logging_mixin.py:109} WARNING -   File "/usr/local/lib/python3.6/logging/__init__.py", line 1454, in handle
    self.callHandlers(record)
[2021-12-28 14:21:20,669] {logging_mixin.py:109} WARNING -   File "/usr/local/lib/python3.6/logging/__init__.py", line 1516, in callHandlers
    hdlr.handle(record)
[2021-12-28 14:21:20,711] {logging_mixin.py:109} WARNING -   File "/usr/local/lib/python3.6/logging/__init__.py", line 865, in handle
    self.emit(record)
[2021-12-28 14:21:20,739] {logging_mixin.py:109} WARNING -   File "/home/***/.local/lib/python3.6/site-packages/***/utils/log/file_task_handler.py", line 66, in emit
    self.handler.emit(record)
[2021-12-28 14:21:20,802] {logging_mixin.py:109} WARNING -   File "/usr/local/lib/python3.6/logging/__init__.py", line 1072, in emit
    StreamHandler.emit(self, record)
[2021-12-28 14:21:20,828] {logging_mixin.py:109} WARNING -   File "/usr/local/lib/python3.6/logging/__init__.py", line 1000, in emit
    self.handleError(record)
[2021-12-28 14:21:20,902] {logging_mixin.py:109} WARNING -   File "/usr/local/lib/python3.6/logging/__init__.py", line 917, in handleError
    sys.stderr.write('--- Logging error ---\n')
[2021-12-28 14:21:20,981] {logging_mixin.py:109} WARNING -   File "/home/***/.local/lib/python3.6/site-packages/***/utils/log/logging_mixin.py", line 121, in write
    self._propagate_log(self._buffer.rstrip())
[2021-12-28 14:21:21,268] {logging_mixin.py:109} WARNING -   File "/home/***/.local/lib/python3.6/site-packages/***/utils/log/logging_mixin.py", line 109, in _propagate_log
    self.logger.log(self.level, remove_escape_codes(message))
[2021-12-28 14:21:21,301] {logging_mixin.py:109} WARNING -   File "/usr/local/lib/python3.6/logging/__init__.py", line 1374, in log
    self._log(level, msg, args, **kwargs)
[2021-12-28 14:21:21,711] {logging_mixin.py:109} WARNING -   File "/usr/local/lib/python3.6/logging/__init__.py", line 1444, in _log
    self.handle(record)
[2021-12-28 14:21:21,729] {logging_mixin.py:109} WARNING -   File "/usr/local/lib/python3.6/logging/__init__.py", line 1454, in handle
    self.callHandlers(record)
[2021-12-28 14:21:21,748] {logging_mixin.py:109} WARNING -   File "/usr/local/lib/python3.6/logging/__init__.py", line 1516, in callHandlers
    hdlr.handle(record)
[2021-12-28 14:21:21,775] {logging_mixin.py:109} WARNING -   File "/usr/local/lib/python3.6/logging/__init__.py", line 865, in handle
    self.emit(record)
[2021-12-28 14:21:21,785] {logging_mixin.py:109} WARNING -   File "/home/***/.local/lib/python3.6/site-packages/***/utils/log/file_task_handler.py", line 66, in emit
    self.handler.emit(record)
[2021-12-28 14:21:21,865] {logging_mixin.py:109} WARNING -   File "/usr/local/lib/python3.6/logging/__init__.py", line 1072, in emit
    StreamHandler.emit(self, record)
[2021-12-28 14:21:21,887] {logging_mixin.py:109} WARNING -   File "/usr/local/lib/python3.6/logging/__init__.py", line 1000, in emit
    self.handleError(record)
[2021-12-28 14:21:22,052] {logging_mixin.py:109} WARNING -   File "/usr/local/lib/python3.6/logging/__init__.py", line 917, in handleError
    sys.stderr.write('--- Logging error ---\n')
[2021-12-28 14:21:22,162] {logging_mixin.py:109} WARNING -   File "/home/***/.local/lib/python3.6/site-packages/***/utils/log/logging_mixin.py", line 121, in write
    self._propagate_log(self._buffer.rstrip())
[2021-12-28 14:21:22,221] {logging_mixin.py:109} WARNING -   File "/home/***/.local/lib/python3.6/site-packages/***/utils/log/logging_mixin.py", line 109, in _propagate_log
    self.logger.log(self.level, remove_escape_codes(message))
[2021-12-28 14:21:22,231] {logging_mixin.py:109} WARNING -   File "/usr/local/lib/python3.6/logging/__init__.py", line 1374, in log
    self._log(level, msg, args, **kwargs)
[2021-12-28 14:21:22,288] {logging_mixin.py:109} WARNING -   File "/usr/local/lib/python3.6/logging/__init__.py", line 1444, in _log
    self.handle(record)
[2021-12-28 14:21:22,365] {logging_mixin.py:109} WARNING -   File "/usr/local/lib/python3.6/logging/__init__.py", line 1454, in handle
    self.callHandlers(record)
[2021-12-28 14:21:22,415] {logging_mixin.py:109} WARNING -   File "/usr/local/lib/python3.6/logging/__init__.py", line 1516, in callHandlers
    hdlr.handle(record)
[2021-12-28 14:21:22,453] {logging_mixin.py:109} WARNING -   File "/usr/local/lib/python3.6/logging/__init__.py", line 865, in handle
    self.emit(record)
[2021-12-28 14:21:22,462] {logging_mixin.py:109} WARNING -   File "/home/***/.local/lib/python3.6/site-packages/***/utils/log/file_task_handler.py", line 66, in emit
    self.handler.emit(record)
[2021-12-28 14:21:22,486] {logging_mixin.py:109} WARNING -   File "/usr/local/lib/python3.6/logging/__init__.py", line 1072, in emit
    StreamHandler.emit(self, record)
[2021-12-28 14:21:22,521] {logging_mixin.py:109} WARNING -   File "/usr/local/lib/python3.6/logging/__init__.py", line 1000, in emit
    self.handleError(record)
[2021-12-28 14:21:22,574] {logging_mixin.py:109} WARNING -   File "/usr/local/lib/python3.6/logging/__init__.py", line 917, in handleError
    sys.stderr.write('--- Logging error ---\n')
[2021-12-28 14:21:22,608] {logging_mixin.py:109} WARNING -   File "/home/***/.local/lib/python3.6/site-packages/***/utils/log/logging_mixin.py", line 121, in write
    self._propagate_log(self._buffer.rstrip())
[2021-12-28 14:21:22,653] {logging_mixin.py:109} WARNING -   File "/home/***/.local/lib/python3.6/site-packages/***/utils/log/logging_mixin.py", line 109, in _propagate_log
    self.logger.log(self.level, remove_escape_codes(message))
[2021-12-28 14:21:22,669] {logging_mixin.py:109} WARNING -   File "/usr/local/lib/python3.6/logging/__init__.py", line 1374, in log
    self._log(level, msg, args, **kwargs)
[2021-12-28 14:21:22,721] {logging_mixin.py:109} WARNING -   File "/usr/local/lib/python3.6/logging/__init__.py", line 1444, in _log
    self.handle(record)
[2021-12-28 14:21:22,789] {logging_mixin.py:109} WARNING -   File "/usr/local/lib/python3.6/logging/__init__.py", line 1454, in handle
    self.callHandlers(record)
[2021-12-28 14:21:22,811] {logging_mixin.py:109} WARNING -   File "/usr/local/lib/python3.6/logging/__init__.py", line 1516, in callHandlers
    hdlr.handle(record)
[2021-12-28 14:21:22,820] {logging_mixin.py:109} WARNING -   File "/usr/local/lib/python3.6/logging/__init__.py", line 865, in handle
    self.emit(record)
[2021-12-28 14:21:22,836] {logging_mixin.py:109} WARNING -   File "/home/***/.local/lib/python3.6/site-packages/***/utils/log/file_task_handler.py", line 66, in emit
    self.handler.emit(record)
[2021-12-28 14:21:22,851] {logging_mixin.py:109} WARNING -   File "/usr/local/lib/python3.6/logging/__init__.py", line 1072, in emit
    StreamHandler.emit(self, record)
[2021-12-28 14:21:22,885] {logging_mixin.py:109} WARNING -   File "/usr/local/lib/python3.6/logging/__init__.py", line 1000, in emit
    self.handleError(record)
[2021-12-28 14:21:22,897] {logging_mixin.py:109} WARNING -   File "/usr/local/lib/python3.6/logging/__init__.py", line 917, in handleError
    sys.stderr.write('--- Logging error ---\n')
[2021-12-28 14:21:22,909] {logging_mixin.py:109} WARNING -   File "/home/***/.local/lib/python3.6/site-packages/***/utils/log/logging_mixin.py", line 121, in write
    self._propagate_log(self._buffer.rstrip())
[2021-12-28 14:21:22,933] {logging_mixin.py:109} WARNING -   File "/home/***/.local/lib/python3.6/site-packages/***/utils/log/logging_mixin.py", line 109, in _propagate_log
    self.logger.log(self.level, remove_escape_codes(message))
[2021-12-28 14:21:22,946] {logging_mixin.py:109} WARNING -   File "/usr/local/lib/python3.6/logging/__init__.py", line 1374, in log
    self._log(level, msg, args, **kwargs)
[2021-12-28 14:21:22,986] {logging_mixin.py:109} WARNING -   File "/usr/local/lib/python3.6/logging/__init__.py", line 1444, in _log
    self.handle(record)
[2021-12-28 14:21:23,108] {logging_mixin.py:109} WARNING -   File "/usr/local/lib/python3.6/logging/__init__.py", line 1454, in handle
    self.callHandlers(record)
[2021-12-28 14:21:23,307] {logging_mixin.py:109} WARNING -   File "/usr/local/lib/python3.6/logging/__init__.py", line 1516, in callHandlers
    hdlr.handle(record)
[2021-12-28 14:21:23,386] {logging_mixin.py:109} WARNING -   File "/usr/local/lib/python3.6/logging/__init__.py", line 865, in handle
    self.emit(record)
[2021-12-28 14:21:23,460] {logging_mixin.py:109} WARNING -   File "/home/***/.local/lib/python3.6/site-packages/***/utils/log/file_task_handler.py", line 66, in emit
    self.handler.emit(record)
[2021-12-28 14:21:23,595] {logging_mixin.py:109} WARNING -   File "/usr/local/lib/python3.6/logging/__init__.py", line 1072, in emit
    StreamHandler.emit(self, record)
[2021-12-28 14:21:23,644] {logging_mixin.py:109} WARNING -   File "/usr/local/lib/python3.6/logging/__init__.py", line 1000, in emit
    self.handleError(record)
[2021-12-28 14:21:23,706] {logging_mixin.py:109} WARNING -   File "/usr/local/lib/python3.6/logging/__init__.py", line 917, in handleError
    sys.stderr.write('--- Logging error ---\n')
[2021-12-28 14:21:23,973] {logging_mixin.py:109} WARNING -   File "/home/***/.local/lib/python3.6/site-packages/***/utils/log/logging_mixin.py", line 121, in write
    self._propagate_log(self._buffer.rstrip())
[2021-12-28 14:21:23,996] {logging_mixin.py:109} WARNING -   File "/home/***/.local/lib/python3.6/site-packages/***/utils/log/logging_mixin.py", line 109, in _propagate_log
    self.logger.log(self.level, remove_escape_codes(message))
[2021-12-28 14:21:24,073] {logging_mixin.py:109} WARNING -   File "/usr/local/lib/python3.6/logging/__init__.py", line 1374, in log
    self._log(level, msg, args, **kwargs)
[2021-12-28 14:21:24,130] {logging_mixin.py:109} WARNING -   File "/usr/local/lib/python3.6/logging/__init__.py", line 1444, in _log
    self.handle(record)
[2021-12-28 14:21:24,209] {logging_mixin.py:109} WARNING -   File "/usr/local/lib/python3.6/logging/__init__.py", line 1454, in handle
    self.callHandlers(record)
[2021-12-28 14:21:24,392] {logging_mixin.py:109} WARNING -   File "/usr/local/lib/python3.6/logging/__init__.py", line 1516, in callHandlers
    hdlr.handle(record)
[2021-12-28 14:21:24,413] {logging_mixin.py:109} WARNING -   File "/usr/local/lib/python3.6/logging/__init__.py", line 865, in handle
    self.emit(record)
[2021-12-28 14:21:24,438] {logging_mixin.py:109} WARNING -   File "/home/***/.local/lib/python3.6/site-packages/***/utils/log/file_task_handler.py", line 66, in emit
    self.handler.emit(record)
[2021-12-28 14:21:24,462] {logging_mixin.py:109} WARNING -   File "/usr/local/lib/python3.6/logging/__init__.py", line 1072, in emit
    StreamHandler.emit(self, record)
[2021-12-28 14:21:24,471] {logging_mixin.py:109} WARNING -   File "/usr/local/lib/python3.6/logging/__init__.py", line 1000, in emit
    self.handleError(record)
[2021-12-28 14:21:24,485] {logging_mixin.py:109} WARNING -   File "/usr/local/lib/python3.6/logging/__init__.py", line 917, in handleError
    sys.stderr.write('--- Logging error ---\n')
[2021-12-28 14:21:24,495] {logging_mixin.py:109} WARNING -   File "/home/***/.local/lib/python3.6/site-packages/***/utils/log/logging_mixin.py", line 121, in write
    self._propagate_log(self._buffer.rstrip())
[2021-12-28 14:21:24,504] {logging_mixin.py:109} WARNING -   File "/home/***/.local/lib/python3.6/site-packages/***/utils/log/logging_mixin.py", line 109, in _propagate_log
    self.logger.log(self.level, remove_escape_codes(message))
[2021-12-28 14:21:24,513] {logging_mixin.py:109} WARNING -   File "/usr/local/lib/python3.6/logging/__init__.py", line 1374, in log
    self._log(level, msg, args, **kwargs)
[2021-12-28 14:21:24,525] {logging_mixin.py:109} WARNING -   File "/usr/local/lib/python3.6/logging/__init__.py", line 1444, in _log
    self.handle(record)
[2021-12-28 14:21:24,537] {logging_mixin.py:109} WARNING -   File "/usr/local/lib/python3.6/logging/__init__.py", line 1454, in handle
    self.callHandlers(record)
[2021-12-28 14:21:24,546] {logging_mixin.py:109} WARNING -   File "/usr/local/lib/python3.6/logging/__init__.py", line 1516, in callHandlers
    hdlr.handle(record)
[2021-12-28 14:21:24,555] {logging_mixin.py:109} WARNING -   File "/usr/local/lib/python3.6/logging/__init__.py", line 865, in handle
    self.emit(record)
[2021-12-28 14:21:24,569] {logging_mixin.py:109} WARNING -   File "/home/***/.local/lib/python3.6/site-packages/***/utils/log/file_task_handler.py", line 66, in emit
    self.handler.emit(record)
[2021-12-28 14:21:24,579] {logging_mixin.py:109} WARNING -   File "/usr/local/lib/python3.6/logging/__init__.py", line 1072, in emit
    StreamHandler.emit(self, record)
[2021-12-28 14:21:24,596] {logging_mixin.py:109} WARNING -   File "/usr/local/lib/python3.6/logging/__init__.py", line 1000, in emit
    self.handleError(record)
[2021-12-28 14:21:24,608] {logging_mixin.py:109} WARNING -   File "/usr/local/lib/python3.6/logging/__init__.py", line 917, in handleError
    sys.stderr.write('--- Logging error ---\n')
[2021-12-28 14:21:24,626] {logging_mixin.py:109} WARNING -   File "/home/***/.local/lib/python3.6/site-packages/***/utils/log/logging_mixin.py", line 121, in write
    self._propagate_log(self._buffer.rstrip())
[2021-12-28 14:21:24,632] {logging_mixin.py:109} WARNING -   File "/home/***/.local/lib/python3.6/site-packages/***/utils/log/logging_mixin.py", line 109, in _propagate_log
    self.logger.log(self.level, remove_escape_codes(message))
[2021-12-28 14:21:24,640] {logging_mixin.py:109} WARNING -   File "/usr/local/lib/python3.6/logging/__init__.py", line 1374, in log
    self._log(level, msg, args, **kwargs)
[2021-12-28 14:21:24,658] {logging_mixin.py:109} WARNING -   File "/usr/local/lib/python3.6/logging/__init__.py", line 1444, in _log
    self.handle(record)
[2021-12-28 14:21:24,666] {logging_mixin.py:109} WARNING -   File "/usr/local/lib/python3.6/logging/__init__.py", line 1454, in handle
    self.callHandlers(record)
[2021-12-28 14:21:24,682] {logging_mixin.py:109} WARNING -   File "/usr/local/lib/python3.6/logging/__init__.py", line 1516, in callHandlers
    hdlr.handle(record)
[2021-12-28 14:21:24,692] {logging_mixin.py:109} WARNING -   File "/usr/local/lib/python3.6/logging/__init__.py", line 865, in handle
    self.emit(record)
[2021-12-28 14:21:24,708] {logging_mixin.py:109} WARNING -   File "/home/***/.local/lib/python3.6/site-packages/***/utils/log/file_task_handler.py", line 66, in emit
    self.handler.emit(record)
[2021-12-28 14:21:24,762] {logging_mixin.py:109} WARNING -   File "/usr/local/lib/python3.6/logging/__init__.py", line 1072, in emit
    StreamHandler.emit(self, record)
[2021-12-28 14:21:24,807] {logging_mixin.py:109} WARNING -   File "/usr/local/lib/python3.6/logging/__init__.py", line 1000, in emit
    self.handleError(record)
[2021-12-28 14:21:24,851] {logging_mixin.py:109} WARNING -   File "/usr/local/lib/python3.6/logging/__init__.py", line 917, in handleError
    sys.stderr.write('--- Logging error ---\n')
[2021-12-28 14:21:24,940] {logging_mixin.py:109} WARNING -   File "/home/***/.local/lib/python3.6/site-packages/***/utils/log/logging_mixin.py", line 121, in write
    self._propagate_log(self._buffer.rstrip())
[2021-12-28 14:21:25,616] {logging_mixin.py:109} WARNING -   File "/home/***/.local/lib/python3.6/site-packages/***/utils/log/logging_mixin.py", line 109, in _propagate_log
    self.logger.log(self.level, remove_escape_codes(message))
[2021-12-28 14:21:25,629] {logging_mixin.py:109} WARNING -   File "/usr/local/lib/python3.6/logging/__init__.py", line 1374, in log
    self._log(level, msg, args, **kwargs)
[2021-12-28 14:21:25,636] {logging_mixin.py:109} WARNING -   File "/usr/local/lib/python3.6/logging/__init__.py", line 1444, in _log
    self.handle(record)
[2021-12-28 14:21:25,680] {logging_mixin.py:109} WARNING -   File "/usr/local/lib/python3.6/logging/__init__.py", line 1454, in handle
    self.callHandlers(record)
[2021-12-28 14:21:25,718] {logging_mixin.py:109} WARNING -   File "/usr/local/lib/python3.6/logging/__init__.py", line 1516, in callHandlers
    hdlr.handle(record)
[2021-12-28 14:21:25,727] {logging_mixin.py:109} WARNING -   File "/usr/local/lib/python3.6/logging/__init__.py", line 865, in handle
    self.emit(record)
[2021-12-28 14:21:27,709] {logging_mixin.py:109} WARNING -   File "/home/***/.local/lib/python3.6/site-packages/***/utils/log/file_task_handler.py", line 66, in emit
    self.handler.emit(record)
[2021-12-28 14:21:27,728] {logging_mixin.py:109} WARNING -   File "/usr/local/lib/python3.6/logging/__init__.py", line 1072, in emit
    StreamHandler.emit(self, record)
[2021-12-28 14:21:27,751] {logging_mixin.py:109} WARNING -   File "/usr/local/lib/python3.6/logging/__init__.py", line 1000, in emit
    self.handleError(record)
[2021-12-28 14:21:28,105] {logging_mixin.py:109} WARNING -   File "/usr/local/lib/python3.6/logging/__init__.py", line 917, in handleError
    sys.stderr.write('--- Logging error ---\n')
[2021-12-28 14:21:28,378] {logging_mixin.py:109} WARNING -   File "/home/***/.local/lib/python3.6/site-packages/***/utils/log/logging_mixin.py", line 121, in write
    self._propagate_log(self._buffer.rstrip())
[2021-12-28 14:21:28,535] {logging_mixin.py:109} WARNING -   File "/home/***/.local/lib/python3.6/site-packages/***/utils/log/logging_mixin.py", line 109, in _propagate_log
    self.logger.log(self.level, remove_escape_codes(message))
[2021-12-28 14:21:28,572] {logging_mixin.py:109} WARNING -   File "/usr/local/lib/python3.6/logging/__init__.py", line 1374, in log
    self._log(level, msg, args, **kwargs)
[2021-12-28 14:21:28,770] {logging_mixin.py:109} WARNING -   File "/usr/local/lib/python3.6/logging/__init__.py", line 1444, in _log
    self.handle(record)
[2021-12-28 14:21:28,787] {logging_mixin.py:109} WARNING -   File "/usr/local/lib/python3.6/logging/__init__.py", line 1454, in handle
    self.callHandlers(record)
[2021-12-28 14:21:28,827] {logging_mixin.py:109} WARNING -   File "/usr/local/lib/python3.6/logging/__init__.py", line 1516, in callHandlers
    hdlr.handle(record)
[2021-12-28 14:21:28,873] {logging_mixin.py:109} WARNING -   File "/usr/local/lib/python3.6/logging/__init__.py", line 865, in handle
    self.emit(record)
[2021-12-28 14:21:28,928] {logging_mixin.py:109} WARNING -   File "/home/***/.local/lib/python3.6/site-packages/***/utils/log/file_task_handler.py", line 66, in emit
    self.handler.emit(record)
[2021-12-28 14:21:28,960] {logging_mixin.py:109} WARNING -   File "/usr/local/lib/python3.6/logging/__init__.py", line 1072, in emit
    StreamHandler.emit(self, record)
[2021-12-28 14:21:28,993] {logging_mixin.py:109} WARNING -   File "/usr/local/lib/python3.6/logging/__init__.py", line 1000, in emit
    self.handleError(record)
[2021-12-28 14:21:29,154] {logging_mixin.py:109} WARNING -   File "/usr/local/lib/python3.6/logging/__init__.py", line 917, in handleError
    sys.stderr.write('--- Logging error ---\n')
[2021-12-28 14:21:29,186] {logging_mixin.py:109} WARNING -   File "/home/***/.local/lib/python3.6/site-packages/***/utils/log/logging_mixin.py", line 121, in write
    self._propagate_log(self._buffer.rstrip())
[2021-12-28 14:21:29,198] {logging_mixin.py:109} WARNING -   File "/home/***/.local/lib/python3.6/site-packages/***/utils/log/logging_mixin.py", line 109, in _propagate_log
    self.logger.log(self.level, remove_escape_codes(message))
[2021-12-28 14:21:29,207] {logging_mixin.py:109} WARNING -   File "/usr/local/lib/python3.6/logging/__init__.py", line 1374, in log
    self._log(level, msg, args, **kwargs)
[2021-12-28 14:21:29,214] {logging_mixin.py:109} WARNING -   File "/usr/local/lib/python3.6/logging/__init__.py", line 1444, in _log
    self.handle(record)
[2021-12-28 14:21:29,221] {logging_mixin.py:109} WARNING -   File "/usr/local/lib/python3.6/logging/__init__.py", line 1454, in handle
    self.callHandlers(record)
[2021-12-28 14:21:29,236] {logging_mixin.py:109} WARNING -   File "/usr/local/lib/python3.6/logging/__init__.py", line 1516, in callHandlers
    hdlr.handle(record)
[2021-12-28 14:21:29,248] {logging_mixin.py:109} WARNING -   File "/usr/local/lib/python3.6/logging/__init__.py", line 865, in handle
    self.emit(record)
[2021-12-28 14:21:29,258] {logging_mixin.py:109} WARNING -   File "/home/***/.local/lib/python3.6/site-packages/***/utils/log/file_task_handler.py", line 66, in emit
    self.handler.emit(record)
[2021-12-28 14:21:29,273] {logging_mixin.py:109} WARNING -   File "/usr/local/lib/python3.6/logging/__init__.py", line 1072, in emit
    StreamHandler.emit(self, record)
[2021-12-28 14:21:29,299] {logging_mixin.py:109} WARNING -   File "/usr/local/lib/python3.6/logging/__init__.py", line 1000, in emit
    self.handleError(record)
[2021-12-28 14:21:29,331] {logging_mixin.py:109} WARNING -   File "/usr/local/lib/python3.6/logging/__init__.py", line 917, in handleError
    sys.stderr.write('--- Logging error ---\n')
[2021-12-28 14:21:29,351] {logging_mixin.py:109} WARNING -   File "/home/***/.local/lib/python3.6/site-packages/***/utils/log/logging_mixin.py", line 121, in write
    self._propagate_log(self._buffer.rstrip())
[2021-12-28 14:21:29,384] {logging_mixin.py:109} WARNING -   File "/home/***/.local/lib/python3.6/site-packages/***/utils/log/logging_mixin.py", line 109, in _propagate_log
    self.logger.log(self.level, remove_escape_codes(message))
[2021-12-28 14:21:29,410] {logging_mixin.py:109} WARNING -   File "/usr/local/lib/python3.6/logging/__init__.py", line 1374, in log
    self._log(level, msg, args, **kwargs)
[2021-12-28 14:21:29,451] {logging_mixin.py:109} WARNING -   File "/usr/local/lib/python3.6/logging/__init__.py", line 1444, in _log
    self.handle(record)
[2021-12-28 14:21:29,565] {logging_mixin.py:109} WARNING -   File "/usr/local/lib/python3.6/logging/__init__.py", line 1454, in handle
    self.callHandlers(record)
[2021-12-28 14:21:29,582] {logging_mixin.py:109} WARNING -   File "/usr/local/lib/python3.6/logging/__init__.py", line 1516, in callHandlers
    hdlr.handle(record)
[2021-12-28 14:21:29,604] {logging_mixin.py:109} WARNING -   File "/usr/local/lib/python3.6/logging/__init__.py", line 865, in handle
    self.emit(record)
[2021-12-28 14:21:29,656] {logging_mixin.py:109} WARNING -   File "/home/***/.local/lib/python3.6/site-packages/***/utils/log/file_task_handler.py", line 66, in emit
    self.handler.emit(record)
[2021-12-28 14:21:29,727] {logging_mixin.py:109} WARNING -   File "/usr/local/lib/python3.6/logging/__init__.py", line 1072, in emit
    StreamHandler.emit(self, record)
[2021-12-28 14:21:29,742] {logging_mixin.py:109} WARNING -   File "/usr/local/lib/python3.6/logging/__init__.py", line 1000, in emit
    self.handleError(record)
[2021-12-28 14:21:29,838] {logging_mixin.py:109} WARNING -   File "/usr/local/lib/python3.6/logging/__init__.py", line 917, in handleError
    sys.stderr.write('--- Logging error ---\n')
[2021-12-28 14:21:29,889] {logging_mixin.py:109} WARNING -   File "/home/***/.local/lib/python3.6/site-packages/***/utils/log/logging_mixin.py", line 121, in write
    self._propagate_log(self._buffer.rstrip())
[2021-12-28 14:21:29,936] {logging_mixin.py:109} WARNING -   File "/home/***/.local/lib/python3.6/site-packages/***/utils/log/logging_mixin.py", line 109, in _propagate_log
    self.logger.log(self.level, remove_escape_codes(message))
[2021-12-28 14:21:30,009] {logging_mixin.py:109} WARNING -   File "/usr/local/lib/python3.6/logging/__init__.py", line 1374, in log
    self._log(level, msg, args, **kwargs)
[2021-12-28 14:21:30,036] {logging_mixin.py:109} WARNING -   File "/usr/local/lib/python3.6/logging/__init__.py", line 1444, in _log
    self.handle(record)
[2021-12-28 14:21:30,063] {logging_mixin.py:109} WARNING -   File "/usr/local/lib/python3.6/logging/__init__.py", line 1454, in handle
    self.callHandlers(record)
[2021-12-28 14:21:30,102] {logging_mixin.py:109} WARNING -   File "/usr/local/lib/python3.6/logging/__init__.py", line 1516, in callHandlers
    hdlr.handle(record)
[2021-12-28 14:21:30,130] {logging_mixin.py:109} WARNING -   File "/usr/local/lib/python3.6/logging/__init__.py", line 865, in handle
    self.emit(record)
[2021-12-28 14:21:30,137] {logging_mixin.py:109} WARNING -   File "/home/***/.local/lib/python3.6/site-packages/***/utils/log/file_task_handler.py", line 66, in emit
    self.handler.emit(record)
[2021-12-28 14:21:30,151] {logging_mixin.py:109} WARNING -   File "/usr/local/lib/python3.6/logging/__init__.py", line 1072, in emit
    StreamHandler.emit(self, record)
[2021-12-28 14:21:30,186] {logging_mixin.py:109} WARNING -   File "/usr/local/lib/python3.6/logging/__init__.py", line 1000, in emit
    self.handleError(record)
[2021-12-28 14:21:30,206] {logging_mixin.py:109} WARNING -   File "/usr/local/lib/python3.6/logging/__init__.py", line 917, in handleError
    sys.stderr.write('--- Logging error ---\n')
[2021-12-28 14:21:30,217] {logging_mixin.py:109} WARNING -   File "/home/***/.local/lib/python3.6/site-packages/***/utils/log/logging_mixin.py", line 121, in write
    self._propagate_log(self._buffer.rstrip())
[2021-12-28 14:21:30,233] {logging_mixin.py:109} WARNING -   File "/home/***/.local/lib/python3.6/site-packages/***/utils/log/logging_mixin.py", line 109, in _propagate_log
    self.logger.log(self.level, remove_escape_codes(message))
[2021-12-28 14:21:30,935] {logging_mixin.py:109} WARNING -   File "/usr/local/lib/python3.6/logging/__init__.py", line 1374, in log
    self._log(level, msg, args, **kwargs)
[2021-12-28 14:21:31,258] {logging_mixin.py:109} WARNING -   File "/usr/local/lib/python3.6/logging/__init__.py", line 1444, in _log
    self.handle(record)
[2021-12-28 14:21:31,553] {logging_mixin.py:109} WARNING -   File "/usr/local/lib/python3.6/logging/__init__.py", line 1454, in handle
    self.callHandlers(record)
[2021-12-28 14:21:31,625] {logging_mixin.py:109} WARNING -   File "/usr/local/lib/python3.6/logging/__init__.py", line 1516, in callHandlers
    hdlr.handle(record)
[2021-12-28 14:21:31,630] {logging_mixin.py:109} WARNING -   File "/usr/local/lib/python3.6/logging/__init__.py", line 865, in handle
    self.emit(record)
[2021-12-28 14:21:31,636] {logging_mixin.py:109} WARNING -   File "/home/***/.local/lib/python3.6/site-packages/***/utils/log/file_task_handler.py", line 66, in emit
    self.handler.emit(record)
[2021-12-28 14:21:31,649] {logging_mixin.py:109} WARNING -   File "/usr/local/lib/python3.6/logging/__init__.py", line 1072, in emit
    StreamHandler.emit(self, record)
[2021-12-28 14:21:31,665] {logging_mixin.py:109} WARNING -   File "/usr/local/lib/python3.6/logging/__init__.py", line 1000, in emit
    self.handleError(record)
[2021-12-28 14:21:31,684] {logging_mixin.py:109} WARNING -   File "/usr/local/lib/python3.6/logging/__init__.py", line 917, in handleError
    sys.stderr.write('--- Logging error ---\n')
[2021-12-28 14:21:31,693] {logging_mixin.py:109} WARNING -   File "/home/***/.local/lib/python3.6/site-packages/***/utils/log/logging_mixin.py", line 121, in write
    self._propagate_log(self._buffer.rstrip())
[2021-12-28 14:21:31,711] {logging_mixin.py:109} WARNING -   File "/home/***/.local/lib/python3.6/site-packages/***/utils/log/logging_mixin.py", line 109, in _propagate_log
    self.logger.log(self.level, remove_escape_codes(message))
[2021-12-28 14:21:31,732] {logging_mixin.py:109} WARNING -   File "/usr/local/lib/python3.6/logging/__init__.py", line 1374, in log
    self._log(level, msg, args, **kwargs)
[2021-12-28 14:21:31,739] {logging_mixin.py:109} WARNING -   File "/usr/local/lib/python3.6/logging/__init__.py", line 1444, in _log
    self.handle(record)
[2021-12-28 14:21:31,764] {logging_mixin.py:109} WARNING -   File "/usr/local/lib/python3.6/logging/__init__.py", line 1454, in handle
    self.callHandlers(record)
[2021-12-28 14:21:31,773] {logging_mixin.py:109} WARNING -   File "/usr/local/lib/python3.6/logging/__init__.py", line 1516, in callHandlers
    hdlr.handle(record)
[2021-12-28 14:21:31,782] {logging_mixin.py:109} WARNING -   File "/usr/local/lib/python3.6/logging/__init__.py", line 865, in handle
    self.emit(record)
[2021-12-28 14:21:31,795] {logging_mixin.py:109} WARNING -   File "/home/***/.local/lib/python3.6/site-packages/***/utils/log/file_task_handler.py", line 66, in emit
    self.handler.emit(record)
[2021-12-28 14:21:31,811] {logging_mixin.py:109} WARNING -   File "/usr/local/lib/python3.6/logging/__init__.py", line 1072, in emit
    StreamHandler.emit(self, record)
[2021-12-28 14:21:31,823] {logging_mixin.py:109} WARNING -   File "/usr/local/lib/python3.6/logging/__init__.py", line 1000, in emit
    self.handleError(record)
[2021-12-28 14:21:31,859] {logging_mixin.py:109} WARNING -   File "/usr/local/lib/python3.6/logging/__init__.py", line 917, in handleError
    sys.stderr.write('--- Logging error ---\n')
[2021-12-28 14:21:31,874] {logging_mixin.py:109} WARNING -   File "/home/***/.local/lib/python3.6/site-packages/***/utils/log/logging_mixin.py", line 121, in write
    self._propagate_log(self._buffer.rstrip())
[2021-12-28 14:21:31,880] {logging_mixin.py:109} WARNING -   File "/home/***/.local/lib/python3.6/site-packages/***/utils/log/logging_mixin.py", line 109, in _propagate_log
    self.logger.log(self.level, remove_escape_codes(message))
[2021-12-28 14:21:31,886] {logging_mixin.py:109} WARNING -   File "/usr/local/lib/python3.6/logging/__init__.py", line 1374, in log
    self._log(level, msg, args, **kwargs)
[2021-12-28 14:21:31,892] {logging_mixin.py:109} WARNING -   File "/usr/local/lib/python3.6/logging/__init__.py", line 1444, in _log
    self.handle(record)
[2021-12-28 14:21:31,900] {logging_mixin.py:109} WARNING -   File "/usr/local/lib/python3.6/logging/__init__.py", line 1454, in handle
    self.callHandlers(record)
[2021-12-28 14:21:31,922] {logging_mixin.py:109} WARNING -   File "/usr/local/lib/python3.6/logging/__init__.py", line 1516, in callHandlers
    hdlr.handle(record)
[2021-12-28 14:21:31,934] {logging_mixin.py:109} WARNING -   File "/usr/local/lib/python3.6/logging/__init__.py", line 865, in handle
    self.emit(record)
[2021-12-28 14:21:31,946] {logging_mixin.py:109} WARNING -   File "/home/***/.local/lib/python3.6/site-packages/***/utils/log/file_task_handler.py", line 66, in emit
    self.handler.emit(record)
[2021-12-28 14:21:31,977] {logging_mixin.py:109} WARNING -   File "/usr/local/lib/python3.6/logging/__init__.py", line 1072, in emit
    StreamHandler.emit(self, record)
[2021-12-28 14:21:31,993] {logging_mixin.py:109} WARNING -   File "/usr/local/lib/python3.6/logging/__init__.py", line 1000, in emit
    self.handleError(record)
[2021-12-28 14:21:32,017] {logging_mixin.py:109} WARNING -   File "/usr/local/lib/python3.6/logging/__init__.py", line 917, in handleError
    sys.stderr.write('--- Logging error ---\n')
[2021-12-28 14:21:32,030] {logging_mixin.py:109} WARNING -   File "/home/***/.local/lib/python3.6/site-packages/***/utils/log/logging_mixin.py", line 121, in write
    self._propagate_log(self._buffer.rstrip())
[2021-12-28 14:21:32,068] {logging_mixin.py:109} WARNING -   File "/home/***/.local/lib/python3.6/site-packages/***/utils/log/logging_mixin.py", line 109, in _propagate_log
    self.logger.log(self.level, remove_escape_codes(message))
[2021-12-28 14:21:32,124] {logging_mixin.py:109} WARNING -   File "/usr/local/lib/python3.6/logging/__init__.py", line 1374, in log
    self._log(level, msg, args, **kwargs)
[2021-12-28 14:21:32,142] {logging_mixin.py:109} WARNING -   File "/usr/local/lib/python3.6/logging/__init__.py", line 1444, in _log
    self.handle(record)
[2021-12-28 14:21:32,162] {logging_mixin.py:109} WARNING -   File "/usr/local/lib/python3.6/logging/__init__.py", line 1454, in handle
    self.callHandlers(record)
[2021-12-28 14:21:32,175] {logging_mixin.py:109} WARNING -   File "/usr/local/lib/python3.6/logging/__init__.py", line 1516, in callHandlers
    hdlr.handle(record)
[2021-12-28 14:21:32,202] {logging_mixin.py:109} WARNING -   File "/usr/local/lib/python3.6/logging/__init__.py", line 865, in handle
    self.emit(record)
[2021-12-28 14:21:32,284] {logging_mixin.py:109} WARNING -   File "/home/***/.local/lib/python3.6/site-packages/***/utils/log/file_task_handler.py", line 66, in emit
    self.handler.emit(record)
[2021-12-28 14:21:32,384] {logging_mixin.py:109} WARNING -   File "/usr/local/lib/python3.6/logging/__init__.py", line 1072, in emit
    StreamHandler.emit(self, record)
[2021-12-28 14:21:32,531] {logging_mixin.py:109} WARNING -   File "/usr/local/lib/python3.6/logging/__init__.py", line 1000, in emit
    self.handleError(record)
[2021-12-28 14:21:32,575] {logging_mixin.py:109} WARNING -   File "/usr/local/lib/python3.6/logging/__init__.py", line 917, in handleError
    sys.stderr.write('--- Logging error ---\n')
[2021-12-28 14:21:32,598] {logging_mixin.py:109} WARNING -   File "/home/***/.local/lib/python3.6/site-packages/***/utils/log/logging_mixin.py", line 121, in write
    self._propagate_log(self._buffer.rstrip())
[2021-12-28 14:21:32,610] {logging_mixin.py:109} WARNING -   File "/home/***/.local/lib/python3.6/site-packages/***/utils/log/logging_mixin.py", line 109, in _propagate_log
    self.logger.log(self.level, remove_escape_codes(message))
[2021-12-28 14:21:32,628] {logging_mixin.py:109} WARNING -   File "/usr/local/lib/python3.6/logging/__init__.py", line 1374, in log
    self._log(level, msg, args, **kwargs)
[2021-12-28 14:21:32,641] {logging_mixin.py:109} WARNING -   File "/usr/local/lib/python3.6/logging/__init__.py", line 1444, in _log
    self.handle(record)
[2021-12-28 14:21:32,698] {logging_mixin.py:109} WARNING -   File "/usr/local/lib/python3.6/logging/__init__.py", line 1454, in handle
    self.callHandlers(record)
[2021-12-28 14:21:32,708] {logging_mixin.py:109} WARNING -   File "/usr/local/lib/python3.6/logging/__init__.py", line 1516, in callHandlers
    hdlr.handle(record)
[2021-12-28 14:21:33,070] {logging_mixin.py:109} WARNING -   File "/usr/local/lib/python3.6/logging/__init__.py", line 865, in handle
    self.emit(record)
[2021-12-28 14:21:33,119] {logging_mixin.py:109} WARNING -   File "/home/***/.local/lib/python3.6/site-packages/***/utils/log/file_task_handler.py", line 66, in emit
    self.handler.emit(record)
[2021-12-28 14:21:33,151] {logging_mixin.py:109} WARNING -   File "/usr/local/lib/python3.6/logging/__init__.py", line 1072, in emit
    StreamHandler.emit(self, record)
[2021-12-28 14:21:33,220] {logging_mixin.py:109} WARNING -   File "/usr/local/lib/python3.6/logging/__init__.py", line 1000, in emit
    self.handleError(record)
[2021-12-28 14:21:33,304] {logging_mixin.py:109} WARNING -   File "/usr/local/lib/python3.6/logging/__init__.py", line 917, in handleError
    sys.stderr.write('--- Logging error ---\n')
[2021-12-28 14:21:33,399] {logging_mixin.py:109} WARNING -   File "/home/***/.local/lib/python3.6/site-packages/***/utils/log/logging_mixin.py", line 121, in write
    self._propagate_log(self._buffer.rstrip())
[2021-12-28 14:21:33,444] {logging_mixin.py:109} WARNING -   File "/home/***/.local/lib/python3.6/site-packages/***/utils/log/logging_mixin.py", line 109, in _propagate_log
    self.logger.log(self.level, remove_escape_codes(message))
[2021-12-28 14:21:33,517] {logging_mixin.py:109} WARNING -   File "/usr/local/lib/python3.6/logging/__init__.py", line 1374, in log
    self._log(level, msg, args, **kwargs)
[2021-12-28 14:21:33,549] {logging_mixin.py:109} WARNING -   File "/usr/local/lib/python3.6/logging/__init__.py", line 1444, in _log
    self.handle(record)
[2021-12-28 14:21:33,563] {logging_mixin.py:109} WARNING -   File "/usr/local/lib/python3.6/logging/__init__.py", line 1454, in handle
    self.callHandlers(record)
[2021-12-28 14:21:33,594] {logging_mixin.py:109} WARNING -   File "/usr/local/lib/python3.6/logging/__init__.py", line 1516, in callHandlers
    hdlr.handle(record)
[2021-12-28 14:21:33,613] {logging_mixin.py:109} WARNING -   File "/usr/local/lib/python3.6/logging/__init__.py", line 865, in handle
    self.emit(record)
[2021-12-28 14:21:33,624] {logging_mixin.py:109} WARNING -   File "/home/***/.local/lib/python3.6/site-packages/***/utils/log/file_task_handler.py", line 66, in emit
    self.handler.emit(record)
[2021-12-28 14:21:33,786] {logging_mixin.py:109} WARNING -   File "/usr/local/lib/python3.6/logging/__init__.py", line 1072, in emit
    StreamHandler.emit(self, record)
[2021-12-28 14:21:33,888] {logging_mixin.py:109} WARNING -   File "/usr/local/lib/python3.6/logging/__init__.py", line 1000, in emit
    self.handleError(record)
[2021-12-28 14:21:33,903] {logging_mixin.py:109} WARNING -   File "/usr/local/lib/python3.6/logging/__init__.py", line 917, in handleError
    sys.stderr.write('--- Logging error ---\n')
[2021-12-28 14:21:33,950] {logging_mixin.py:109} WARNING -   File "/home/***/.local/lib/python3.6/site-packages/***/utils/log/logging_mixin.py", line 121, in write
    self._propagate_log(self._buffer.rstrip())
[2021-12-28 14:21:33,973] {logging_mixin.py:109} WARNING -   File "/home/***/.local/lib/python3.6/site-packages/***/utils/log/logging_mixin.py", line 109, in _propagate_log
    self.logger.log(self.level, remove_escape_codes(message))
[2021-12-28 14:21:34,058] {logging_mixin.py:109} WARNING -   File "/usr/local/lib/python3.6/logging/__init__.py", line 1374, in log
    self._log(level, msg, args, **kwargs)
[2021-12-28 14:21:34,106] {logging_mixin.py:109} WARNING -   File "/usr/local/lib/python3.6/logging/__init__.py", line 1444, in _log
    self.handle(record)
[2021-12-28 14:21:34,192] {logging_mixin.py:109} WARNING -   File "/usr/local/lib/python3.6/logging/__init__.py", line 1454, in handle
    self.callHandlers(record)
[2021-12-28 14:21:34,225] {logging_mixin.py:109} WARNING -   File "/usr/local/lib/python3.6/logging/__init__.py", line 1516, in callHandlers
    hdlr.handle(record)
[2021-12-28 14:21:34,238] {logging_mixin.py:109} WARNING -   File "/usr/local/lib/python3.6/logging/__init__.py", line 865, in handle
    self.emit(record)
[2021-12-28 14:21:34,250] {logging_mixin.py:109} WARNING -   File "/home/***/.local/lib/python3.6/site-packages/***/utils/log/file_task_handler.py", line 66, in emit
    self.handler.emit(record)
[2021-12-28 14:21:34,257] {logging_mixin.py:109} WARNING -   File "/usr/local/lib/python3.6/logging/__init__.py", line 1072, in emit
    StreamHandler.emit(self, record)
[2021-12-28 14:21:34,305] {logging_mixin.py:109} WARNING -   File "/usr/local/lib/python3.6/logging/__init__.py", line 1000, in emit
    self.handleError(record)
[2021-12-28 14:21:34,456] {logging_mixin.py:109} WARNING -   File "/usr/local/lib/python3.6/logging/__init__.py", line 917, in handleError
    sys.stderr.write('--- Logging error ---\n')
[2021-12-28 14:21:34,536] {logging_mixin.py:109} WARNING -   File "/home/***/.local/lib/python3.6/site-packages/***/utils/log/logging_mixin.py", line 121, in write
    self._propagate_log(self._buffer.rstrip())
[2021-12-28 14:21:34,553] {logging_mixin.py:109} WARNING -   File "/home/***/.local/lib/python3.6/site-packages/***/utils/log/logging_mixin.py", line 109, in _propagate_log
    self.logger.log(self.level, remove_escape_codes(message))
[2021-12-28 14:21:34,661] {logging_mixin.py:109} WARNING -   File "/usr/local/lib/python3.6/logging/__init__.py", line 1374, in log
    self._log(level, msg, args, **kwargs)
[2021-12-28 14:21:34,667] {logging_mixin.py:109} WARNING -   File "/usr/local/lib/python3.6/logging/__init__.py", line 1444, in _log
    self.handle(record)
[2021-12-28 14:21:34,847] {logging_mixin.py:109} WARNING -   File "/usr/local/lib/python3.6/logging/__init__.py", line 1454, in handle
    self.callHandlers(record)
[2021-12-28 14:21:34,861] {logging_mixin.py:109} WARNING -   File "/usr/local/lib/python3.6/logging/__init__.py", line 1516, in callHandlers
    hdlr.handle(record)
[2021-12-28 14:21:34,893] {logging_mixin.py:109} WARNING -   File "/usr/local/lib/python3.6/logging/__init__.py", line 865, in handle
    self.emit(record)
[2021-12-28 14:21:34,910] {logging_mixin.py:109} WARNING -   File "/home/***/.local/lib/python3.6/site-packages/***/utils/log/file_task_handler.py", line 66, in emit
    self.handler.emit(record)
[2021-12-28 14:21:34,937] {logging_mixin.py:109} WARNING -   File "/usr/local/lib/python3.6/logging/__init__.py", line 1072, in emit
    StreamHandler.emit(self, record)
[2021-12-28 14:21:34,955] {logging_mixin.py:109} WARNING -   File "/usr/local/lib/python3.6/logging/__init__.py", line 1000, in emit
    self.handleError(record)
[2021-12-28 14:21:34,962] {logging_mixin.py:109} WARNING -   File "/usr/local/lib/python3.6/logging/__init__.py", line 917, in handleError
    sys.stderr.write('--- Logging error ---\n')
[2021-12-28 14:21:34,973] {logging_mixin.py:109} WARNING -   File "/home/***/.local/lib/python3.6/site-packages/***/utils/log/logging_mixin.py", line 121, in write
    self._propagate_log(self._buffer.rstrip())
[2021-12-28 14:21:34,992] {logging_mixin.py:109} WARNING -   File "/home/***/.local/lib/python3.6/site-packages/***/utils/log/logging_mixin.py", line 109, in _propagate_log
    self.logger.log(self.level, remove_escape_codes(message))
[2021-12-28 14:21:35,002] {logging_mixin.py:109} WARNING -   File "/usr/local/lib/python3.6/logging/__init__.py", line 1374, in log
    self._log(level, msg, args, **kwargs)
[2021-12-28 14:21:35,011] {logging_mixin.py:109} WARNING -   File "/usr/local/lib/python3.6/logging/__init__.py", line 1444, in _log
    self.handle(record)
[2021-12-28 14:21:35,037] {logging_mixin.py:109} WARNING -   File "/usr/local/lib/python3.6/logging/__init__.py", line 1454, in handle
    self.callHandlers(record)
[2021-12-28 14:21:35,049] {logging_mixin.py:109} WARNING -   File "/usr/local/lib/python3.6/logging/__init__.py", line 1516, in callHandlers
    hdlr.handle(record)
[2021-12-28 14:21:35,074] {logging_mixin.py:109} WARNING -   File "/usr/local/lib/python3.6/logging/__init__.py", line 865, in handle
    self.emit(record)
[2021-12-28 14:21:35,086] {logging_mixin.py:109} WARNING -   File "/home/***/.local/lib/python3.6/site-packages/***/utils/log/file_task_handler.py", line 66, in emit
    self.handler.emit(record)
[2021-12-28 14:21:35,114] {logging_mixin.py:109} WARNING -   File "/usr/local/lib/python3.6/logging/__init__.py", line 1072, in emit
    StreamHandler.emit(self, record)
[2021-12-28 14:21:35,131] {logging_mixin.py:109} WARNING -   File "/usr/local/lib/python3.6/logging/__init__.py", line 1000, in emit
    self.handleError(record)
[2021-12-28 14:21:35,142] {logging_mixin.py:109} WARNING -   File "/usr/local/lib/python3.6/logging/__init__.py", line 917, in handleError
    sys.stderr.write('--- Logging error ---\n')
[2021-12-28 14:21:35,158] {logging_mixin.py:109} WARNING -   File "/home/***/.local/lib/python3.6/site-packages/***/utils/log/logging_mixin.py", line 121, in write
    self._propagate_log(self._buffer.rstrip())
[2021-12-28 14:21:35,178] {logging_mixin.py:109} WARNING -   File "/home/***/.local/lib/python3.6/site-packages/***/utils/log/logging_mixin.py", line 109, in _propagate_log
    self.logger.log(self.level, remove_escape_codes(message))
[2021-12-28 14:21:35,288] {logging_mixin.py:109} WARNING -   File "/usr/local/lib/python3.6/logging/__init__.py", line 1374, in log
    self._log(level, msg, args, **kwargs)
[2021-12-28 14:21:35,345] {logging_mixin.py:109} WARNING -   File "/usr/local/lib/python3.6/logging/__init__.py", line 1444, in _log
    self.handle(record)
[2021-12-28 14:21:35,363] {logging_mixin.py:109} WARNING -   File "/usr/local/lib/python3.6/logging/__init__.py", line 1454, in handle
    self.callHandlers(record)
[2021-12-28 14:21:35,431] {logging_mixin.py:109} WARNING -   File "/usr/local/lib/python3.6/logging/__init__.py", line 1516, in callHandlers
    hdlr.handle(record)
[2021-12-28 14:21:35,522] {logging_mixin.py:109} WARNING -   File "/usr/local/lib/python3.6/logging/__init__.py", line 865, in handle
    self.emit(record)
[2021-12-28 14:21:35,589] {logging_mixin.py:109} WARNING -   File "/home/***/.local/lib/python3.6/site-packages/***/utils/log/file_task_handler.py", line 66, in emit
    self.handler.emit(record)
[2021-12-28 14:21:35,606] {logging_mixin.py:109} WARNING -   File "/usr/local/lib/python3.6/logging/__init__.py", line 1072, in emit
    StreamHandler.emit(self, record)
[2021-12-28 14:21:35,628] {logging_mixin.py:109} WARNING -   File "/usr/local/lib/python3.6/logging/__init__.py", line 1000, in emit
    self.handleError(record)
[2021-12-28 14:21:35,649] {logging_mixin.py:109} WARNING -   File "/usr/local/lib/python3.6/logging/__init__.py", line 917, in handleError
    sys.stderr.write('--- Logging error ---\n')
[2021-12-28 14:21:35,662] {logging_mixin.py:109} WARNING -   File "/home/***/.local/lib/python3.6/site-packages/***/utils/log/logging_mixin.py", line 121, in write
    self._propagate_log(self._buffer.rstrip())
[2021-12-28 14:21:35,677] {logging_mixin.py:109} WARNING -   File "/home/***/.local/lib/python3.6/site-packages/***/utils/log/logging_mixin.py", line 109, in _propagate_log
    self.logger.log(self.level, remove_escape_codes(message))
[2021-12-28 14:21:35,686] {logging_mixin.py:109} WARNING -   File "/usr/local/lib/python3.6/logging/__init__.py", line 1374, in log
    self._log(level, msg, args, **kwargs)
[2021-12-28 14:21:35,694] {logging_mixin.py:109} WARNING -   File "/usr/local/lib/python3.6/logging/__init__.py", line 1444, in _log
    self.handle(record)
[2021-12-28 14:21:35,700] {logging_mixin.py:109} WARNING -   File "/usr/local/lib/python3.6/logging/__init__.py", line 1454, in handle
    self.callHandlers(record)
[2021-12-28 14:21:35,706] {logging_mixin.py:109} WARNING -   File "/usr/local/lib/python3.6/logging/__init__.py", line 1516, in callHandlers
    hdlr.handle(record)
[2021-12-28 14:21:35,716] {logging_mixin.py:109} WARNING -   File "/usr/local/lib/python3.6/logging/__init__.py", line 865, in handle
    self.emit(record)
[2021-12-28 14:21:35,725] {logging_mixin.py:109} WARNING -   File "/home/***/.local/lib/python3.6/site-packages/***/utils/log/file_task_handler.py", line 66, in emit
    self.handler.emit(record)
[2021-12-28 14:21:35,744] {logging_mixin.py:109} WARNING -   File "/usr/local/lib/python3.6/logging/__init__.py", line 1072, in emit
    StreamHandler.emit(self, record)
[2021-12-28 14:21:35,750] {logging_mixin.py:109} WARNING -   File "/usr/local/lib/python3.6/logging/__init__.py", line 1000, in emit
    self.handleError(record)
[2021-12-28 14:21:35,756] {logging_mixin.py:109} WARNING -   File "/usr/local/lib/python3.6/logging/__init__.py", line 917, in handleError
    sys.stderr.write('--- Logging error ---\n')
[2021-12-28 14:21:35,765] {logging_mixin.py:109} WARNING -   File "/home/***/.local/lib/python3.6/site-packages/***/utils/log/logging_mixin.py", line 121, in write
    self._propagate_log(self._buffer.rstrip())
[2021-12-28 14:21:35,776] {logging_mixin.py:109} WARNING -   File "/home/***/.local/lib/python3.6/site-packages/***/utils/log/logging_mixin.py", line 109, in _propagate_log
    self.logger.log(self.level, remove_escape_codes(message))
[2021-12-28 14:21:35,792] {logging_mixin.py:109} WARNING -   File "/usr/local/lib/python3.6/logging/__init__.py", line 1374, in log
    self._log(level, msg, args, **kwargs)
[2021-12-28 14:21:35,806] {logging_mixin.py:109} WARNING -   File "/usr/local/lib/python3.6/logging/__init__.py", line 1444, in _log
    self.handle(record)
[2021-12-28 14:21:35,817] {logging_mixin.py:109} WARNING -   File "/usr/local/lib/python3.6/logging/__init__.py", line 1454, in handle
    self.callHandlers(record)
[2021-12-28 14:21:35,842] {logging_mixin.py:109} WARNING -   File "/usr/local/lib/python3.6/logging/__init__.py", line 1516, in callHandlers
    hdlr.handle(record)
[2021-12-28 14:21:35,849] {logging_mixin.py:109} WARNING -   File "/usr/local/lib/python3.6/logging/__init__.py", line 865, in handle
    self.emit(record)
[2021-12-28 14:21:35,855] {logging_mixin.py:109} WARNING -   File "/home/***/.local/lib/python3.6/site-packages/***/utils/log/file_task_handler.py", line 66, in emit
    self.handler.emit(record)
[2021-12-28 14:21:35,875] {logging_mixin.py:109} WARNING -   File "/usr/local/lib/python3.6/logging/__init__.py", line 1072, in emit
    StreamHandler.emit(self, record)
[2021-12-28 14:21:35,891] {logging_mixin.py:109} WARNING -   File "/usr/local/lib/python3.6/logging/__init__.py", line 1000, in emit
    self.handleError(record)
[2021-12-28 14:21:35,903] {logging_mixin.py:109} WARNING -   File "/usr/local/lib/python3.6/logging/__init__.py", line 917, in handleError
    sys.stderr.write('--- Logging error ---\n')
[2021-12-28 14:21:35,910] {logging_mixin.py:109} WARNING -   File "/home/***/.local/lib/python3.6/site-packages/***/utils/log/logging_mixin.py", line 121, in write
    self._propagate_log(self._buffer.rstrip())
[2021-12-28 14:21:35,928] {logging_mixin.py:109} WARNING -   File "/home/***/.local/lib/python3.6/site-packages/***/utils/log/logging_mixin.py", line 109, in _propagate_log
    self.logger.log(self.level, remove_escape_codes(message))
[2021-12-28 14:21:35,947] {logging_mixin.py:109} WARNING -   File "/usr/local/lib/python3.6/logging/__init__.py", line 1374, in log
    self._log(level, msg, args, **kwargs)
[2021-12-28 14:21:35,957] {logging_mixin.py:109} WARNING -   File "/usr/local/lib/python3.6/logging/__init__.py", line 1444, in _log
    self.handle(record)
[2021-12-28 14:21:35,964] {logging_mixin.py:109} WARNING -   File "/usr/local/lib/python3.6/logging/__init__.py", line 1454, in handle
    self.callHandlers(record)
[2021-12-28 14:21:35,975] {logging_mixin.py:109} WARNING -   File "/usr/local/lib/python3.6/logging/__init__.py", line 1516, in callHandlers
    hdlr.handle(record)
[2021-12-28 14:21:35,986] {logging_mixin.py:109} WARNING -   File "/usr/local/lib/python3.6/logging/__init__.py", line 865, in handle
    self.emit(record)
[2021-12-28 14:21:36,009] {logging_mixin.py:109} WARNING -   File "/home/***/.local/lib/python3.6/site-packages/***/utils/log/file_task_handler.py", line 66, in emit
    self.handler.emit(record)
[2021-12-28 14:21:36,017] {logging_mixin.py:109} WARNING -   File "/usr/local/lib/python3.6/logging/__init__.py", line 1072, in emit
    StreamHandler.emit(self, record)
[2021-12-28 14:21:36,031] {logging_mixin.py:109} WARNING -   File "/usr/local/lib/python3.6/logging/__init__.py", line 1000, in emit
    self.handleError(record)
[2021-12-28 14:21:36,041] {logging_mixin.py:109} WARNING -   File "/usr/local/lib/python3.6/logging/__init__.py", line 917, in handleError
    sys.stderr.write('--- Logging error ---\n')
[2021-12-28 14:21:36,055] {logging_mixin.py:109} WARNING -   File "/home/***/.local/lib/python3.6/site-packages/***/utils/log/logging_mixin.py", line 121, in write
    self._propagate_log(self._buffer.rstrip())
[2021-12-28 14:21:36,068] {logging_mixin.py:109} WARNING -   File "/home/***/.local/lib/python3.6/site-packages/***/utils/log/logging_mixin.py", line 109, in _propagate_log
    self.logger.log(self.level, remove_escape_codes(message))
[2021-12-28 14:21:36,077] {logging_mixin.py:109} WARNING -   File "/usr/local/lib/python3.6/logging/__init__.py", line 1374, in log
    self._log(level, msg, args, **kwargs)
[2021-12-28 14:21:36,090] {logging_mixin.py:109} WARNING -   File "/usr/local/lib/python3.6/logging/__init__.py", line 1444, in _log
    self.handle(record)
[2021-12-28 14:21:36,101] {logging_mixin.py:109} WARNING -   File "/usr/local/lib/python3.6/logging/__init__.py", line 1454, in handle
    self.callHandlers(record)
[2021-12-28 14:21:36,106] {logging_mixin.py:109} WARNING -   File "/usr/local/lib/python3.6/logging/__init__.py", line 1516, in callHandlers
    hdlr.handle(record)
[2021-12-28 14:21:36,133] {logging_mixin.py:109} WARNING -   File "/usr/local/lib/python3.6/logging/__init__.py", line 865, in handle
    self.emit(record)
[2021-12-28 14:21:36,196] {logging_mixin.py:109} WARNING -   File "/home/***/.local/lib/python3.6/site-packages/***/utils/log/file_task_handler.py", line 66, in emit
    self.handler.emit(record)
[2021-12-28 14:21:36,254] {logging_mixin.py:109} WARNING -   File "/usr/local/lib/python3.6/logging/__init__.py", line 1072, in emit
    StreamHandler.emit(self, record)
[2021-12-28 14:21:36,277] {logging_mixin.py:109} WARNING -   File "/usr/local/lib/python3.6/logging/__init__.py", line 1000, in emit
    self.handleError(record)
[2021-12-28 14:21:36,311] {logging_mixin.py:109} WARNING -   File "/usr/local/lib/python3.6/logging/__init__.py", line 917, in handleError
    sys.stderr.write('--- Logging error ---\n')
[2021-12-28 14:21:36,321] {logging_mixin.py:109} WARNING -   File "/home/***/.local/lib/python3.6/site-packages/***/utils/log/logging_mixin.py", line 121, in write
    self._propagate_log(self._buffer.rstrip())
[2021-12-28 14:21:36,327] {logging_mixin.py:109} WARNING -   File "/home/***/.local/lib/python3.6/site-packages/***/utils/log/logging_mixin.py", line 109, in _propagate_log
    self.logger.log(self.level, remove_escape_codes(message))
[2021-12-28 14:21:36,352] {logging_mixin.py:109} WARNING -   File "/usr/local/lib/python3.6/logging/__init__.py", line 1374, in log
    self._log(level, msg, args, **kwargs)
[2021-12-28 14:21:36,372] {logging_mixin.py:109} WARNING -   File "/usr/local/lib/python3.6/logging/__init__.py", line 1444, in _log
    self.handle(record)
[2021-12-28 14:21:36,402] {logging_mixin.py:109} WARNING -   File "/usr/local/lib/python3.6/logging/__init__.py", line 1454, in handle
    self.callHandlers(record)
[2021-12-28 14:21:36,415] {logging_mixin.py:109} WARNING -   File "/usr/local/lib/python3.6/logging/__init__.py", line 1516, in callHandlers
    hdlr.handle(record)
[2021-12-28 14:21:36,431] {logging_mixin.py:109} WARNING -   File "/usr/local/lib/python3.6/logging/__init__.py", line 865, in handle
    self.emit(record)
[2021-12-28 14:21:36,444] {logging_mixin.py:109} WARNING -   File "/home/***/.local/lib/python3.6/site-packages/***/utils/log/file_task_handler.py", line 66, in emit
    self.handler.emit(record)
[2021-12-28 14:21:36,463] {logging_mixin.py:109} WARNING -   File "/usr/local/lib/python3.6/logging/__init__.py", line 1072, in emit
    StreamHandler.emit(self, record)
[2021-12-28 14:21:36,472] {logging_mixin.py:109} WARNING -   File "/usr/local/lib/python3.6/logging/__init__.py", line 1000, in emit
    self.handleError(record)
[2021-12-28 14:21:36,483] {logging_mixin.py:109} WARNING -   File "/usr/local/lib/python3.6/logging/__init__.py", line 917, in handleError
    sys.stderr.write('--- Logging error ---\n')
[2021-12-28 14:21:36,512] {logging_mixin.py:109} WARNING -   File "/home/***/.local/lib/python3.6/site-packages/***/utils/log/logging_mixin.py", line 121, in write
    self._propagate_log(self._buffer.rstrip())
[2021-12-28 14:21:36,532] {logging_mixin.py:109} WARNING -   File "/home/***/.local/lib/python3.6/site-packages/***/utils/log/logging_mixin.py", line 109, in _propagate_log
    self.logger.log(self.level, remove_escape_codes(message))
[2021-12-28 14:21:36,552] {logging_mixin.py:109} WARNING -   File "/usr/local/lib/python3.6/logging/__init__.py", line 1374, in log
    self._log(level, msg, args, **kwargs)
[2021-12-28 14:21:36,617] {logging_mixin.py:109} WARNING -   File "/usr/local/lib/python3.6/logging/__init__.py", line 1444, in _log
    self.handle(record)
[2021-12-28 14:21:36,637] {logging_mixin.py:109} WARNING -   File "/usr/local/lib/python3.6/logging/__init__.py", line 1454, in handle
    self.callHandlers(record)
[2021-12-28 14:21:36,653] {logging_mixin.py:109} WARNING -   File "/usr/local/lib/python3.6/logging/__init__.py", line 1516, in callHandlers
    hdlr.handle(record)
[2021-12-28 14:21:36,675] {logging_mixin.py:109} WARNING -   File "/usr/local/lib/python3.6/logging/__init__.py", line 865, in handle
    self.emit(record)
[2021-12-28 14:21:36,722] {logging_mixin.py:109} WARNING -   File "/home/***/.local/lib/python3.6/site-packages/***/utils/log/file_task_handler.py", line 66, in emit
    self.handler.emit(record)
[2021-12-28 14:21:36,737] {logging_mixin.py:109} WARNING -   File "/usr/local/lib/python3.6/logging/__init__.py", line 1072, in emit
    StreamHandler.emit(self, record)
[2021-12-28 14:21:36,812] {logging_mixin.py:109} WARNING -   File "/usr/local/lib/python3.6/logging/__init__.py", line 1000, in emit
    self.handleError(record)
[2021-12-28 14:21:36,836] {logging_mixin.py:109} WARNING -   File "/usr/local/lib/python3.6/logging/__init__.py", line 917, in handleError
    sys.stderr.write('--- Logging error ---\n')
[2021-12-28 14:21:36,851] {logging_mixin.py:109} WARNING -   File "/home/***/.local/lib/python3.6/site-packages/***/utils/log/logging_mixin.py", line 121, in write
    self._propagate_log(self._buffer.rstrip())
[2021-12-28 14:21:36,864] {logging_mixin.py:109} WARNING -   File "/home/***/.local/lib/python3.6/site-packages/***/utils/log/logging_mixin.py", line 109, in _propagate_log
    self.logger.log(self.level, remove_escape_codes(message))
[2021-12-28 14:21:36,879] {logging_mixin.py:109} WARNING -   File "/usr/local/lib/python3.6/logging/__init__.py", line 1374, in log
    self._log(level, msg, args, **kwargs)
[2021-12-28 14:21:36,911] {logging_mixin.py:109} WARNING -   File "/usr/local/lib/python3.6/logging/__init__.py", line 1444, in _log
    self.handle(record)
[2021-12-28 14:21:36,957] {logging_mixin.py:109} WARNING -   File "/usr/local/lib/python3.6/logging/__init__.py", line 1454, in handle
    self.callHandlers(record)
[2021-12-28 14:21:36,992] {logging_mixin.py:109} WARNING -   File "/usr/local/lib/python3.6/logging/__init__.py", line 1516, in callHandlers
    hdlr.handle(record)
[2021-12-28 14:21:37,003] {logging_mixin.py:109} WARNING -   File "/usr/local/lib/python3.6/logging/__init__.py", line 865, in handle
    self.emit(record)
[2021-12-28 14:21:37,040] {logging_mixin.py:109} WARNING -   File "/home/***/.local/lib/python3.6/site-packages/***/utils/log/file_task_handler.py", line 66, in emit
    self.handler.emit(record)
[2021-12-28 14:21:37,080] {logging_mixin.py:109} WARNING -   File "/usr/local/lib/python3.6/logging/__init__.py", line 1072, in emit
    StreamHandler.emit(self, record)
[2021-12-28 14:21:37,117] {logging_mixin.py:109} WARNING -   File "/usr/local/lib/python3.6/logging/__init__.py", line 1000, in emit
    self.handleError(record)
[2021-12-28 14:21:37,129] {logging_mixin.py:109} WARNING -   File "/usr/local/lib/python3.6/logging/__init__.py", line 917, in handleError
    sys.stderr.write('--- Logging error ---\n')
[2021-12-28 14:21:37,160] {logging_mixin.py:109} WARNING -   File "/home/***/.local/lib/python3.6/site-packages/***/utils/log/logging_mixin.py", line 121, in write
    self._propagate_log(self._buffer.rstrip())
[2021-12-28 14:21:37,206] {logging_mixin.py:109} WARNING -   File "/home/***/.local/lib/python3.6/site-packages/***/utils/log/logging_mixin.py", line 109, in _propagate_log
    self.logger.log(self.level, remove_escape_codes(message))
[2021-12-28 14:21:37,313] {logging_mixin.py:109} WARNING -   File "/usr/local/lib/python3.6/logging/__init__.py", line 1374, in log
    self._log(level, msg, args, **kwargs)
[2021-12-28 14:21:37,387] {logging_mixin.py:109} WARNING -   File "/usr/local/lib/python3.6/logging/__init__.py", line 1444, in _log
    self.handle(record)
[2021-12-28 14:21:37,418] {logging_mixin.py:109} WARNING -   File "/usr/local/lib/python3.6/logging/__init__.py", line 1454, in handle
    self.callHandlers(record)
[2021-12-28 14:21:37,463] {logging_mixin.py:109} WARNING -   File "/usr/local/lib/python3.6/logging/__init__.py", line 1516, in callHandlers
    hdlr.handle(record)
[2021-12-28 14:21:37,487] {logging_mixin.py:109} WARNING -   File "/usr/local/lib/python3.6/logging/__init__.py", line 865, in handle
    self.emit(record)
[2021-12-28 14:21:37,557] {logging_mixin.py:109} WARNING -   File "/home/***/.local/lib/python3.6/site-packages/***/utils/log/file_task_handler.py", line 66, in emit
    self.handler.emit(record)
[2021-12-28 14:21:37,612] {logging_mixin.py:109} WARNING -   File "/usr/local/lib/python3.6/logging/__init__.py", line 1072, in emit
    StreamHandler.emit(self, record)
[2021-12-28 14:21:37,628] {logging_mixin.py:109} WARNING -   File "/usr/local/lib/python3.6/logging/__init__.py", line 1000, in emit
    self.handleError(record)
[2021-12-28 14:21:37,650] {logging_mixin.py:109} WARNING -   File "/usr/local/lib/python3.6/logging/__init__.py", line 917, in handleError
    sys.stderr.write('--- Logging error ---\n')
[2021-12-28 14:21:37,664] {logging_mixin.py:109} WARNING -   File "/home/***/.local/lib/python3.6/site-packages/***/utils/log/logging_mixin.py", line 121, in write
    self._propagate_log(self._buffer.rstrip())
[2021-12-28 14:21:37,692] {logging_mixin.py:109} WARNING -   File "/home/***/.local/lib/python3.6/site-packages/***/utils/log/logging_mixin.py", line 109, in _propagate_log
    self.logger.log(self.level, remove_escape_codes(message))
[2021-12-28 14:21:37,706] {logging_mixin.py:109} WARNING -   File "/usr/local/lib/python3.6/logging/__init__.py", line 1374, in log
    self._log(level, msg, args, **kwargs)
[2021-12-28 14:21:37,721] {logging_mixin.py:109} WARNING -   File "/usr/local/lib/python3.6/logging/__init__.py", line 1444, in _log
    self.handle(record)
[2021-12-28 14:21:37,735] {logging_mixin.py:109} WARNING -   File "/usr/local/lib/python3.6/logging/__init__.py", line 1454, in handle
    self.callHandlers(record)
[2021-12-28 14:21:37,805] {logging_mixin.py:109} WARNING -   File "/usr/local/lib/python3.6/logging/__init__.py", line 1516, in callHandlers
    hdlr.handle(record)
[2021-12-28 14:21:37,849] {logging_mixin.py:109} WARNING -   File "/usr/local/lib/python3.6/logging/__init__.py", line 865, in handle
    self.emit(record)
[2021-12-28 14:21:37,863] {logging_mixin.py:109} WARNING -   File "/home/***/.local/lib/python3.6/site-packages/***/utils/log/file_task_handler.py", line 66, in emit
    self.handler.emit(record)
[2021-12-28 14:21:37,880] {logging_mixin.py:109} WARNING -   File "/usr/local/lib/python3.6/logging/__init__.py", line 1072, in emit
    StreamHandler.emit(self, record)
[2021-12-28 14:21:37,888] {logging_mixin.py:109} WARNING -   File "/usr/local/lib/python3.6/logging/__init__.py", line 1000, in emit
    self.handleError(record)
[2021-12-28 14:21:37,897] {logging_mixin.py:109} WARNING -   File "/usr/local/lib/python3.6/logging/__init__.py", line 917, in handleError
    sys.stderr.write('--- Logging error ---\n')
[2021-12-28 14:21:37,912] {logging_mixin.py:109} WARNING -   File "/home/***/.local/lib/python3.6/site-packages/***/utils/log/logging_mixin.py", line 121, in write
    self._propagate_log(self._buffer.rstrip())
[2021-12-28 14:21:37,935] {logging_mixin.py:109} WARNING -   File "/home/***/.local/lib/python3.6/site-packages/***/utils/log/logging_mixin.py", line 109, in _propagate_log
    self.logger.log(self.level, remove_escape_codes(message))
[2021-12-28 14:21:37,977] {logging_mixin.py:109} WARNING -   File "/usr/local/lib/python3.6/logging/__init__.py", line 1374, in log
    self._log(level, msg, args, **kwargs)
[2021-12-28 14:21:37,992] {logging_mixin.py:109} WARNING -   File "/usr/local/lib/python3.6/logging/__init__.py", line 1444, in _log
    self.handle(record)
[2021-12-28 14:21:38,018] {logging_mixin.py:109} WARNING -   File "/usr/local/lib/python3.6/logging/__init__.py", line 1454, in handle
    self.callHandlers(record)
[2021-12-28 14:21:38,039] {logging_mixin.py:109} WARNING -   File "/usr/local/lib/python3.6/logging/__init__.py", line 1516, in callHandlers
    hdlr.handle(record)
[2021-12-28 14:21:38,052] {logging_mixin.py:109} WARNING -   File "/usr/local/lib/python3.6/logging/__init__.py", line 865, in handle
    self.emit(record)
[2021-12-28 14:21:38,064] {logging_mixin.py:109} WARNING -   File "/home/***/.local/lib/python3.6/site-packages/***/utils/log/file_task_handler.py", line 66, in emit
    self.handler.emit(record)
[2021-12-28 14:21:38,113] {logging_mixin.py:109} WARNING -   File "/usr/local/lib/python3.6/logging/__init__.py", line 1072, in emit
    StreamHandler.emit(self, record)
[2021-12-28 14:21:38,137] {logging_mixin.py:109} WARNING -   File "/usr/local/lib/python3.6/logging/__init__.py", line 1000, in emit
    self.handleError(record)
[2021-12-28 14:21:38,148] {logging_mixin.py:109} WARNING -   File "/usr/local/lib/python3.6/logging/__init__.py", line 917, in handleError
    sys.stderr.write('--- Logging error ---\n')
[2021-12-28 14:21:38,154] {logging_mixin.py:109} WARNING -   File "/home/***/.local/lib/python3.6/site-packages/***/utils/log/logging_mixin.py", line 121, in write
    self._propagate_log(self._buffer.rstrip())
[2021-12-28 14:21:38,167] {logging_mixin.py:109} WARNING -   File "/home/***/.local/lib/python3.6/site-packages/***/utils/log/logging_mixin.py", line 109, in _propagate_log
    self.logger.log(self.level, remove_escape_codes(message))
[2021-12-28 14:21:38,195] {logging_mixin.py:109} WARNING -   File "/usr/local/lib/python3.6/logging/__init__.py", line 1374, in log
    self._log(level, msg, args, **kwargs)
[2021-12-28 14:21:38,206] {logging_mixin.py:109} WARNING -   File "/usr/local/lib/python3.6/logging/__init__.py", line 1444, in _log
    self.handle(record)
[2021-12-28 14:21:38,216] {logging_mixin.py:109} WARNING -   File "/usr/local/lib/python3.6/logging/__init__.py", line 1454, in handle
    self.callHandlers(record)
[2021-12-28 14:21:38,230] {logging_mixin.py:109} WARNING -   File "/usr/local/lib/python3.6/logging/__init__.py", line 1516, in callHandlers
    hdlr.handle(record)
[2021-12-28 14:21:38,264] {logging_mixin.py:109} WARNING -   File "/usr/local/lib/python3.6/logging/__init__.py", line 865, in handle
    self.emit(record)
[2021-12-28 14:21:38,295] {logging_mixin.py:109} WARNING -   File "/home/***/.local/lib/python3.6/site-packages/***/utils/log/file_task_handler.py", line 66, in emit
    self.handler.emit(record)
[2021-12-28 14:21:38,343] {logging_mixin.py:109} WARNING -   File "/usr/local/lib/python3.6/logging/__init__.py", line 1072, in emit
    StreamHandler.emit(self, record)
[2021-12-28 14:21:38,356] {logging_mixin.py:109} WARNING -   File "/usr/local/lib/python3.6/logging/__init__.py", line 1000, in emit
    self.handleError(record)
[2021-12-28 14:21:38,371] {logging_mixin.py:109} WARNING -   File "/usr/local/lib/python3.6/logging/__init__.py", line 917, in handleError
    sys.stderr.write('--- Logging error ---\n')
[2021-12-28 14:21:38,415] {logging_mixin.py:109} WARNING -   File "/home/***/.local/lib/python3.6/site-packages/***/utils/log/logging_mixin.py", line 121, in write
    self._propagate_log(self._buffer.rstrip())
[2021-12-28 14:21:38,427] {logging_mixin.py:109} WARNING -   File "/home/***/.local/lib/python3.6/site-packages/***/utils/log/logging_mixin.py", line 109, in _propagate_log
    self.logger.log(self.level, remove_escape_codes(message))
[2021-12-28 14:21:38,480] {logging_mixin.py:109} WARNING -   File "/usr/local/lib/python3.6/logging/__init__.py", line 1374, in log
    self._log(level, msg, args, **kwargs)
[2021-12-28 14:21:38,514] {logging_mixin.py:109} WARNING -   File "/usr/local/lib/python3.6/logging/__init__.py", line 1444, in _log
    self.handle(record)
[2021-12-28 14:21:38,567] {logging_mixin.py:109} WARNING -   File "/usr/local/lib/python3.6/logging/__init__.py", line 1454, in handle
    self.callHandlers(record)
[2021-12-28 14:21:38,586] {logging_mixin.py:109} WARNING -   File "/usr/local/lib/python3.6/logging/__init__.py", line 1516, in callHandlers
    hdlr.handle(record)
[2021-12-28 14:21:38,611] {logging_mixin.py:109} WARNING -   File "/usr/local/lib/python3.6/logging/__init__.py", line 865, in handle
    self.emit(record)
[2021-12-28 14:21:38,684] {logging_mixin.py:109} WARNING -   File "/home/***/.local/lib/python3.6/site-packages/***/utils/log/file_task_handler.py", line 66, in emit
    self.handler.emit(record)
[2021-12-28 14:21:38,767] {logging_mixin.py:109} WARNING -   File "/usr/local/lib/python3.6/logging/__init__.py", line 1072, in emit
    StreamHandler.emit(self, record)
[2021-12-28 14:21:38,789] {logging_mixin.py:109} WARNING -   File "/usr/local/lib/python3.6/logging/__init__.py", line 1000, in emit
    self.handleError(record)
[2021-12-28 14:21:38,810] {logging_mixin.py:109} WARNING -   File "/usr/local/lib/python3.6/logging/__init__.py", line 917, in handleError
    sys.stderr.write('--- Logging error ---\n')
[2021-12-28 14:21:38,821] {logging_mixin.py:109} WARNING -   File "/home/***/.local/lib/python3.6/site-packages/***/utils/log/logging_mixin.py", line 121, in write
    self._propagate_log(self._buffer.rstrip())
[2021-12-28 14:21:38,848] {logging_mixin.py:109} WARNING -   File "/home/***/.local/lib/python3.6/site-packages/***/utils/log/logging_mixin.py", line 109, in _propagate_log
    self.logger.log(self.level, remove_escape_codes(message))
[2021-12-28 14:21:38,869] {logging_mixin.py:109} WARNING -   File "/usr/local/lib/python3.6/logging/__init__.py", line 1374, in log
    self._log(level, msg, args, **kwargs)
[2021-12-28 14:21:38,883] {logging_mixin.py:109} WARNING -   File "/usr/local/lib/python3.6/logging/__init__.py", line 1444, in _log
    self.handle(record)
[2021-12-28 14:21:38,904] {logging_mixin.py:109} WARNING -   File "/usr/local/lib/python3.6/logging/__init__.py", line 1454, in handle
    self.callHandlers(record)
[2021-12-28 14:21:38,937] {logging_mixin.py:109} WARNING -   File "/usr/local/lib/python3.6/logging/__init__.py", line 1516, in callHandlers
    hdlr.handle(record)
[2021-12-28 14:21:38,943] {logging_mixin.py:109} WARNING -   File "/usr/local/lib/python3.6/logging/__init__.py", line 865, in handle
    self.emit(record)
[2021-12-28 14:21:38,962] {logging_mixin.py:109} WARNING -   File "/home/***/.local/lib/python3.6/site-packages/***/utils/log/file_task_handler.py", line 66, in emit
    self.handler.emit(record)
[2021-12-28 14:21:39,041] {logging_mixin.py:109} WARNING -   File "/usr/local/lib/python3.6/logging/__init__.py", line 1072, in emit
    StreamHandler.emit(self, record)
[2021-12-28 14:21:35,922] {process_utils.py:113} WARNING - process psutil.Process(pid=57499, name='java', status='zombie', started='13:49:45') did not respond to SIGTERM. Trying SIGKILL
[2021-12-28 14:21:39,127] {process_utils.py:113} WARNING - process psutil.Process(pid=57445, name='airflow task ru', status='running', started='13:49:44') did not respond to SIGTERM. Trying SIGKILL
[2021-12-28 14:21:41,207] {process_utils.py:66} INFO - Process psutil.Process(pid=57445, name='airflow task ru', status='terminated', exitcode=<Negsignal.SIGKILL: -9>, started='13:49:44') (57445) terminated with exit code Negsignal.SIGKILL
[2021-12-28 14:21:41,236] {process_utils.py:66} INFO - Process psutil.Process(pid=57499, name='java', status='terminated', started='13:49:45') (57499) terminated with exit code None
[2021-12-28 14:21:41,259] {standard_task_runner.py:135} ERROR - Job 5125 was killed before it finished (likely due to running out of memory)
